[2019-06-15 22:34:45,852][Thread-1:22556][task_id:django.request][log.py:228][ERROR][Internal Server Error: /calSensorSimilarity/]
Traceback (most recent call last):
  File "C:\Softwares\Anaconda3\envs\django\lib\site-packages\django\core\handlers\exception.py", line 34, in inner
    response = get_response(request)
  File "C:\Softwares\Anaconda3\envs\django\lib\site-packages\django\core\handlers\base.py", line 115, in _get_response
    response = self.process_exception_by_middleware(e, request)
  File "C:\Softwares\Anaconda3\envs\django\lib\site-packages\django\core\handlers\base.py", line 113, in _get_response
    response = wrapped_callback(request, *callback_args, **callback_kwargs)
  File "D:\Workspace\Projects\vast-challenge-2019-MC2\RadiationVis\backend\views.py", line 54, in calSensorSimilarity
    all = calCorrlelation('2020-04-06 00:00:00', '2020-04-11 00:00:00')
  File "D:\Workspace\Projects\vast-challenge-2019-MC2\RadiationVis\backend\dataprocessing\correlation.py", line 137, in calCorrlelation
    cursor.execute("select concat(DATE_FORMAT(timestamp, '%Y-%m-%d %H'),':00'), sid, avg(value) from mobilesensorreadings where timestamp between '{}' and '{}' GROUP BY concat(DATE_FORMAT(timestamp, '%Y-%m-%d %H'), sid)".format(begintime, endtime))
NameError: name 'endtime' is not defined
[2019-06-15 22:35:08,240][Thread-1:23496][task_id:django.request][log.py:228][ERROR][Internal Server Error: /calSensorSimilarity/]
Traceback (most recent call last):
  File "C:\Softwares\Anaconda3\envs\django\lib\site-packages\django\core\handlers\exception.py", line 34, in inner
    response = get_response(request)
  File "C:\Softwares\Anaconda3\envs\django\lib\site-packages\django\core\handlers\base.py", line 115, in _get_response
    response = self.process_exception_by_middleware(e, request)
  File "C:\Softwares\Anaconda3\envs\django\lib\site-packages\django\core\handlers\base.py", line 113, in _get_response
    response = wrapped_callback(request, *callback_args, **callback_kwargs)
  File "D:\Workspace\Projects\vast-challenge-2019-MC2\RadiationVis\backend\views.py", line 54, in calSensorSimilarity
    all = calCorrlelation('2020-04-06 00:00:00', '2020-04-11 00:00:00')
  File "D:\Workspace\Projects\vast-challenge-2019-MC2\RadiationVis\backend\dataprocessing\correlation.py", line 174, in calCorrlelation
    cursor.execute("select concat(DATE_FORMAT(timestamp, '%Y-%m-%d %H'),':00'), sid, avg(value) from staticsensorreadings where timestamp between '{}' and '{}' GROUP BY concat(DATE_FORMAT(timestamp, '%Y-%m-%d %H'), sid)".format(starttime, endtime))
NameError: name 'starttime' is not defined
[2019-06-16 00:19:59,793][Thread-1:22820][task_id:django.request][log.py:228][ERROR][Internal Server Error: /calSensorSimilarity/]
Traceback (most recent call last):
  File "C:\Softwares\Anaconda3\envs\django\lib\site-packages\django\core\handlers\exception.py", line 34, in inner
    response = get_response(request)
  File "C:\Softwares\Anaconda3\envs\django\lib\site-packages\django\core\handlers\base.py", line 115, in _get_response
    response = self.process_exception_by_middleware(e, request)
  File "C:\Softwares\Anaconda3\envs\django\lib\site-packages\django\core\handlers\base.py", line 113, in _get_response
    response = wrapped_callback(request, *callback_args, **callback_kwargs)
  File "D:\Workspace\Projects\vast-challenge-2019-MC2\RadiationVis\backend\views.py", line 54, in calSensorSimilarity
    all = calCorrlelation('2020-04-06 00:00:00', '2020-04-11 00:00:00')
  File "D:\Workspace\Projects\vast-challenge-2019-MC2\RadiationVis\backend\dataprocessing\correlation.py", line 145, in calCorrlelation
    begin_timestamp = time.mktime(begin.timetuple())
UnboundLocalError: local variable 'begin' referenced before assignment
[2019-06-16 00:22:08,394][Thread-1:8248][task_id:django.request][log.py:228][ERROR][Internal Server Error: /calSensorSimilarity/]
Traceback (most recent call last):
  File "C:\Softwares\Anaconda3\envs\django\lib\site-packages\django\core\handlers\exception.py", line 34, in inner
    response = get_response(request)
  File "C:\Softwares\Anaconda3\envs\django\lib\site-packages\django\core\handlers\base.py", line 115, in _get_response
    response = self.process_exception_by_middleware(e, request)
  File "C:\Softwares\Anaconda3\envs\django\lib\site-packages\django\core\handlers\base.py", line 113, in _get_response
    response = wrapped_callback(request, *callback_args, **callback_kwargs)
  File "D:\Workspace\Projects\vast-challenge-2019-MC2\RadiationVis\backend\views.py", line 54, in calSensorSimilarity
    all = calCorrlelation('2020-04-06 00:00:00', '2020-04-11 00:00:00')
  File "D:\Workspace\Projects\vast-challenge-2019-MC2\RadiationVis\backend\dataprocessing\correlation.py", line 144, in calCorrlelation
    end = datetime.datetime.strptime(end, '%Y-%m-%d %H:%M:%S')
UnboundLocalError: local variable 'end' referenced before assignment
[2019-06-16 00:23:03,910][Thread-1:17144][task_id:django.request][log.py:228][ERROR][Internal Server Error: /calSensorSimilarity/]
Traceback (most recent call last):
  File "C:\Softwares\Anaconda3\envs\django\lib\site-packages\django\core\handlers\exception.py", line 34, in inner
    response = get_response(request)
  File "C:\Softwares\Anaconda3\envs\django\lib\site-packages\django\core\handlers\base.py", line 115, in _get_response
    response = self.process_exception_by_middleware(e, request)
  File "C:\Softwares\Anaconda3\envs\django\lib\site-packages\django\core\handlers\base.py", line 113, in _get_response
    response = wrapped_callback(request, *callback_args, **callback_kwargs)
  File "D:\Workspace\Projects\vast-challenge-2019-MC2\RadiationVis\backend\views.py", line 54, in calSensorSimilarity
    all = calCorrlelation('2020-04-06 00:00:00', '2020-04-11 00:00:00')
  File "D:\Workspace\Projects\vast-challenge-2019-MC2\RadiationVis\backend\dataprocessing\correlation.py", line 145, in calCorrlelation
    begin_timestamp = time.mktime(begin.timetuple())
NameError: name 'begin' is not defined
[2019-06-16 00:25:05,380][Thread-1:17144][task_id:django.request][log.py:228][ERROR][Internal Server Error: /calSensorSimilarity/]
Traceback (most recent call last):
  File "C:\Softwares\Anaconda3\envs\django\lib\site-packages\django\core\handlers\exception.py", line 34, in inner
    response = get_response(request)
  File "C:\Softwares\Anaconda3\envs\django\lib\site-packages\django\core\handlers\base.py", line 115, in _get_response
    response = self.process_exception_by_middleware(e, request)
  File "C:\Softwares\Anaconda3\envs\django\lib\site-packages\django\core\handlers\base.py", line 113, in _get_response
    response = wrapped_callback(request, *callback_args, **callback_kwargs)
  File "D:\Workspace\Projects\vast-challenge-2019-MC2\RadiationVis\backend\views.py", line 54, in calSensorSimilarity
    all = calCorrlelation('2020-04-06 00:00:00', '2020-04-11 00:00:00')
  File "D:\Workspace\Projects\vast-challenge-2019-MC2\RadiationVis\backend\dataprocessing\correlation.py", line 145, in calCorrlelation
    begin_timestamp = time.mktime(begin.timetuple())
NameError: name 'begin' is not defined
[2019-06-16 01:50:13,329][Thread-1:13392][task_id:django.request][log.py:228][ERROR][Internal Server Error: /calSensorSimilarity/]
Traceback (most recent call last):
  File "C:\Softwares\Anaconda3\envs\django\lib\site-packages\django\core\handlers\exception.py", line 34, in inner
    response = get_response(request)
  File "C:\Softwares\Anaconda3\envs\django\lib\site-packages\django\core\handlers\base.py", line 115, in _get_response
    response = self.process_exception_by_middleware(e, request)
  File "C:\Softwares\Anaconda3\envs\django\lib\site-packages\django\core\handlers\base.py", line 113, in _get_response
    response = wrapped_callback(request, *callback_args, **callback_kwargs)
  File "D:\Workspace\Projects\vast-challenge-2019-MC2\RadiationVis\backend\views.py", line 56, in calSensorSimilarity
    data = calCorrlelation(params['begintime'], params['endtime'])
  File "D:\Workspace\Projects\vast-challenge-2019-MC2\RadiationVis\backend\dataprocessing\correlation.py", line 158, in calCorrlelation
    obs1[d['time']][d['sid']] = d['value']
KeyError: '2020-04-07 02:00'
[2019-06-16 01:57:57,825][Thread-1:13416][task_id:django.request][log.py:228][ERROR][Internal Server Error: /calSensorSimilarity/]
Traceback (most recent call last):
  File "C:\Softwares\Anaconda3\envs\django\lib\site-packages\django\core\handlers\exception.py", line 34, in inner
    response = get_response(request)
  File "C:\Softwares\Anaconda3\envs\django\lib\site-packages\django\core\handlers\base.py", line 115, in _get_response
    response = self.process_exception_by_middleware(e, request)
  File "C:\Softwares\Anaconda3\envs\django\lib\site-packages\django\core\handlers\base.py", line 113, in _get_response
    response = wrapped_callback(request, *callback_args, **callback_kwargs)
  File "D:\Workspace\Projects\vast-challenge-2019-MC2\RadiationVis\backend\views.py", line 56, in calSensorSimilarity
    data = calCorrlelation(params['begintime'], params['endtime'])
  File "D:\Workspace\Projects\vast-challenge-2019-MC2\RadiationVis\backend\dataprocessing\correlation.py", line 160, in calCorrlelation
    obs1[d['time']][d['sid']] = d['value']
KeyError: '2020-04-07 02:00'
[2019-06-16 01:58:50,733][Thread-1:25108][task_id:django.request][log.py:228][ERROR][Internal Server Error: /calSensorSimilarity/]
Traceback (most recent call last):
  File "C:\Softwares\Anaconda3\envs\django\lib\site-packages\django\core\handlers\exception.py", line 34, in inner
    response = get_response(request)
  File "C:\Softwares\Anaconda3\envs\django\lib\site-packages\django\core\handlers\base.py", line 115, in _get_response
    response = self.process_exception_by_middleware(e, request)
  File "C:\Softwares\Anaconda3\envs\django\lib\site-packages\django\core\handlers\base.py", line 113, in _get_response
    response = wrapped_callback(request, *callback_args, **callback_kwargs)
  File "D:\Workspace\Projects\vast-challenge-2019-MC2\RadiationVis\backend\views.py", line 56, in calSensorSimilarity
    data = calCorrlelation(params['begintime'], params['endtime'])
  File "D:\Workspace\Projects\vast-challenge-2019-MC2\RadiationVis\backend\dataprocessing\correlation.py", line 161, in calCorrlelation
    obs1[d['time']][d['sid']] = d['value']
KeyError: '2020-04-07 02:00'
[2019-06-16 02:02:40,991][Thread-1:17968][task_id:django.request][log.py:228][ERROR][Internal Server Error: /calSensorSimilarity/]
Traceback (most recent call last):
  File "C:\Softwares\Anaconda3\envs\django\lib\site-packages\django\core\handlers\exception.py", line 34, in inner
    response = get_response(request)
  File "C:\Softwares\Anaconda3\envs\django\lib\site-packages\django\core\handlers\base.py", line 115, in _get_response
    response = self.process_exception_by_middleware(e, request)
  File "C:\Softwares\Anaconda3\envs\django\lib\site-packages\django\core\handlers\base.py", line 113, in _get_response
    response = wrapped_callback(request, *callback_args, **callback_kwargs)
  File "D:\Workspace\Projects\vast-challenge-2019-MC2\RadiationVis\backend\views.py", line 56, in calSensorSimilarity
    data = calCorrlelation(params['begintime'], params['endtime'])
  File "D:\Workspace\Projects\vast-challenge-2019-MC2\RadiationVis\backend\dataprocessing\correlation.py", line 161, in calCorrlelation
    obs1[d['time']][d['sid']] = d['value']
KeyError: '2020-04-07 02:00'
[2019-06-16 02:04:29,400][Thread-1:22372][task_id:django.request][log.py:228][ERROR][Internal Server Error: /calSensorSimilarity/]
Traceback (most recent call last):
  File "C:\Softwares\Anaconda3\envs\django\lib\site-packages\django\core\handlers\exception.py", line 34, in inner
    response = get_response(request)
  File "C:\Softwares\Anaconda3\envs\django\lib\site-packages\django\core\handlers\base.py", line 115, in _get_response
    response = self.process_exception_by_middleware(e, request)
  File "C:\Softwares\Anaconda3\envs\django\lib\site-packages\django\core\handlers\base.py", line 113, in _get_response
    response = wrapped_callback(request, *callback_args, **callback_kwargs)
  File "D:\Workspace\Projects\vast-challenge-2019-MC2\RadiationVis\backend\views.py", line 56, in calSensorSimilarity
    data = calCorrlelation(params['begintime'], params['endtime'])
  File "D:\Workspace\Projects\vast-challenge-2019-MC2\RadiationVis\backend\dataprocessing\correlation.py", line 150, in calCorrlelation
    current = datetime.datetime.strptime(begintime, '%Y-%m-%d %H:%M')
  File "C:\Softwares\Anaconda3\envs\django\lib\_strptime.py", line 565, in _strptime_datetime
    tt, fraction = _strptime(data_string, format)
  File "C:\Softwares\Anaconda3\envs\django\lib\_strptime.py", line 365, in _strptime
    data_string[found.end():])
ValueError: unconverted data remains: :31
[2019-06-16 02:05:52,521][Thread-1:11384][task_id:django.request][log.py:228][ERROR][Internal Server Error: /calSensorSimilarity/]
Traceback (most recent call last):
  File "C:\Softwares\Anaconda3\envs\django\lib\site-packages\django\core\handlers\exception.py", line 34, in inner
    response = get_response(request)
  File "C:\Softwares\Anaconda3\envs\django\lib\site-packages\django\core\handlers\base.py", line 115, in _get_response
    response = self.process_exception_by_middleware(e, request)
  File "C:\Softwares\Anaconda3\envs\django\lib\site-packages\django\core\handlers\base.py", line 113, in _get_response
    response = wrapped_callback(request, *callback_args, **callback_kwargs)
  File "D:\Workspace\Projects\vast-challenge-2019-MC2\RadiationVis\backend\views.py", line 56, in calSensorSimilarity
    data = calCorrlelation(params['begintime'], params['endtime'])
  File "D:\Workspace\Projects\vast-challenge-2019-MC2\RadiationVis\backend\dataprocessing\correlation.py", line 150, in calCorrlelation
    current = time.mktime(datetime.datetime.strptime(begintime, '%Y-%m-%d %H:%M'))
  File "C:\Softwares\Anaconda3\envs\django\lib\_strptime.py", line 565, in _strptime_datetime
    tt, fraction = _strptime(data_string, format)
  File "C:\Softwares\Anaconda3\envs\django\lib\_strptime.py", line 365, in _strptime
    data_string[found.end():])
ValueError: unconverted data remains: :31
[2019-06-16 02:10:23,190][Thread-1:15804][task_id:django.request][log.py:228][ERROR][Internal Server Error: /calSensorSimilarity/]
Traceback (most recent call last):
  File "C:\Softwares\Anaconda3\envs\django\lib\site-packages\django\core\handlers\exception.py", line 34, in inner
    response = get_response(request)
  File "C:\Softwares\Anaconda3\envs\django\lib\site-packages\django\core\handlers\base.py", line 115, in _get_response
    response = self.process_exception_by_middleware(e, request)
  File "C:\Softwares\Anaconda3\envs\django\lib\site-packages\django\core\handlers\base.py", line 113, in _get_response
    response = wrapped_callback(request, *callback_args, **callback_kwargs)
  File "D:\Workspace\Projects\vast-challenge-2019-MC2\RadiationVis\backend\views.py", line 56, in calSensorSimilarity
    data = calCorrlelation(params['begintime'], params['endtime'])
  File "D:\Workspace\Projects\vast-challenge-2019-MC2\RadiationVis\backend\dataprocessing\correlation.py", line 150, in calCorrlelation
    current = time.mktime(datetime.datetime.strptime(begintime, '%Y-%m-%d %H:%M').timetuple())
  File "C:\Softwares\Anaconda3\envs\django\lib\_strptime.py", line 565, in _strptime_datetime
    tt, fraction = _strptime(data_string, format)
  File "C:\Softwares\Anaconda3\envs\django\lib\_strptime.py", line 365, in _strptime
    data_string[found.end():])
ValueError: unconverted data remains: :31
[2019-06-16 02:20:15,338][Thread-3:10148][task_id:django.request][log.py:228][ERROR][Internal Server Error: /calSensorSimilarity/]
Traceback (most recent call last):
  File "C:\Softwares\Anaconda3\envs\django\lib\site-packages\django\core\handlers\exception.py", line 34, in inner
    response = get_response(request)
  File "C:\Softwares\Anaconda3\envs\django\lib\site-packages\django\core\handlers\base.py", line 115, in _get_response
    response = self.process_exception_by_middleware(e, request)
  File "C:\Softwares\Anaconda3\envs\django\lib\site-packages\django\core\handlers\base.py", line 113, in _get_response
    response = wrapped_callback(request, *callback_args, **callback_kwargs)
  File "D:\Workspace\Projects\vast-challenge-2019-MC2\RadiationVis\backend\views.py", line 56, in calSensorSimilarity
    data = calCorrlelation(params['begintime'], params['endtime'])
  File "D:\Workspace\Projects\vast-challenge-2019-MC2\RadiationVis\backend\dataprocessing\correlation.py", line 214, in calCorrlelation
    mn = Matrix_Completion_2(mn)
  File "D:\Workspace\Projects\vast-challenge-2019-MC2\RadiationVis\backend\dataprocessing\correlation.py", line 59, in Matrix_Completion_2
    m[index[i, 0], index[i, 1]] = -200
IndexError: index 1 is out of bounds for axis 1 with size 1
[2019-06-16 02:21:08,795][Thread-1:20284][task_id:django.request][log.py:228][ERROR][Internal Server Error: /calSensorSimilarity/]
Traceback (most recent call last):
  File "C:\Softwares\Anaconda3\envs\django\lib\site-packages\django\core\handlers\exception.py", line 34, in inner
    response = get_response(request)
  File "C:\Softwares\Anaconda3\envs\django\lib\site-packages\django\core\handlers\base.py", line 115, in _get_response
    response = self.process_exception_by_middleware(e, request)
  File "C:\Softwares\Anaconda3\envs\django\lib\site-packages\django\core\handlers\base.py", line 113, in _get_response
    response = wrapped_callback(request, *callback_args, **callback_kwargs)
  File "D:\Workspace\Projects\vast-challenge-2019-MC2\RadiationVis\backend\views.py", line 56, in calSensorSimilarity
    data = calCorrlelation(params['begintime'], params['endtime'])
  File "D:\Workspace\Projects\vast-challenge-2019-MC2\RadiationVis\backend\dataprocessing\correlation.py", line 230, in calCorrlelation
    feature_matrix = Distance_Metric_Cos(mn)
  File "D:\Workspace\Projects\vast-challenge-2019-MC2\RadiationVis\backend\dataprocessing\correlation.py", line 88, in Distance_Metric_Cos
    tmp2 = m[:, j].T.tolist()
IndexError: index 58 is out of bounds for axis 1 with size 58
[2019-06-16 15:23:05,792][Thread-3:20904][task_id:django.request][log.py:228][ERROR][Internal Server Error: /calSensorSimilarity/]
Traceback (most recent call last):
  File "C:\Softwares\Anaconda3\envs\django\lib\site-packages\django\core\handlers\exception.py", line 34, in inner
    response = get_response(request)
  File "C:\Softwares\Anaconda3\envs\django\lib\site-packages\django\core\handlers\base.py", line 115, in _get_response
    response = self.process_exception_by_middleware(e, request)
  File "C:\Softwares\Anaconda3\envs\django\lib\site-packages\django\core\handlers\base.py", line 113, in _get_response
    response = wrapped_callback(request, *callback_args, **callback_kwargs)
  File "D:\Workspace\Projects\vast-challenge-2019-MC2\RadiationVis\backend\views.py", line 56, in calSensorSimilarity
    data = calCorrlelation(params['begintime'], params['endtime'])
  File "D:\Workspace\Projects\vast-challenge-2019-MC2\RadiationVis\backend\dataprocessing\correlation.py", line 248, in calCorrlelation
    feature_matrix = Distance_Metric_Cos(mn)
  File "D:\Workspace\Projects\vast-challenge-2019-MC2\RadiationVis\backend\dataprocessing\correlation.py", line 88, in Distance_Metric_Cos
    tmp2 = m[:, j].T.tolist()
IndexError: index 58 is out of bounds for axis 1 with size 58
[2019-06-16 15:37:37,768][Thread-1:24880][task_id:django.request][log.py:228][ERROR][Internal Server Error: /calSensorSimilarity/]
Traceback (most recent call last):
  File "C:\Softwares\Anaconda3\envs\django\lib\site-packages\django\core\handlers\exception.py", line 34, in inner
    response = get_response(request)
  File "C:\Softwares\Anaconda3\envs\django\lib\site-packages\django\core\handlers\base.py", line 115, in _get_response
    response = self.process_exception_by_middleware(e, request)
  File "C:\Softwares\Anaconda3\envs\django\lib\site-packages\django\core\handlers\base.py", line 113, in _get_response
    response = wrapped_callback(request, *callback_args, **callback_kwargs)
  File "D:\Workspace\Projects\vast-challenge-2019-MC2\RadiationVis\backend\views.py", line 56, in calSensorSimilarity
    data = calCorrlelation(params['begintime'], params['endtime'])
  File "D:\Workspace\Projects\vast-challenge-2019-MC2\RadiationVis\backend\dataprocessing\correlation.py", line 199, in calCorrlelation
    sensor_length = len(sensor_title)
NameError: name 'sensor_title' is not defined
[2019-06-16 17:44:19,458][Thread-2:19504][task_id:django.request][log.py:228][ERROR][Internal Server Error: /calTimeSeries/]
Traceback (most recent call last):
  File "C:\Softwares\Anaconda3\envs\django\lib\site-packages\django\core\handlers\exception.py", line 34, in inner
    response = get_response(request)
  File "C:\Softwares\Anaconda3\envs\django\lib\site-packages\django\core\handlers\base.py", line 115, in _get_response
    response = self.process_exception_by_middleware(e, request)
  File "C:\Softwares\Anaconda3\envs\django\lib\site-packages\django\core\handlers\base.py", line 113, in _get_response
    response = wrapped_callback(request, *callback_args, **callback_kwargs)
  File "D:\Workspace\Projects\vast-challenge-2019-MC2\RadiationVis\backend\views.py", line 88, in calTimeSeries
    cursor.execute("select concat(DATE_FORMAT(timestamp, '%Y-%m-%d %H:%i'),':00') as time, avg(value) as avg, avg(value) - 1.96*(std(value)/sqrt(count(*))) as lower95, avg(value) + 1.96 * (std(value)/ sqrt(count(value))) as upper95 from mobilesensorreadings where timestamp >= '{0}' and timestamp < '{1}' group by DATE_FORMAT(timestamp, '%Y-%m-%d %H:%i')".format(begintime_str, endtime_str))
NameError: name 'cursor' is not defined
[2019-06-16 17:51:31,017][Thread-4:11620][task_id:django.request][log.py:228][ERROR][Internal Server Error: /calSensorSimilarity/]
Traceback (most recent call last):
  File "C:\Softwares\Anaconda3\envs\django\lib\site-packages\django\core\handlers\exception.py", line 34, in inner
    response = get_response(request)
  File "C:\Softwares\Anaconda3\envs\django\lib\site-packages\django\core\handlers\base.py", line 115, in _get_response
    response = self.process_exception_by_middleware(e, request)
  File "C:\Softwares\Anaconda3\envs\django\lib\site-packages\django\core\handlers\base.py", line 113, in _get_response
    response = wrapped_callback(request, *callback_args, **callback_kwargs)
  File "D:\Workspace\Projects\vast-challenge-2019-MC2\RadiationVis\backend\views.py", line 57, in calSensorSimilarity
    data = calCorrlelation(params['begintime'], params['endtime'])
  File "D:\Workspace\Projects\vast-challenge-2019-MC2\RadiationVis\backend\dataprocessing\correlation.py", line 234, in calCorrlelation
    [a, b] = mn.shape
ValueError: not enough values to unpack (expected 2, got 1)
[2019-06-16 18:03:47,914][Thread-3:10420][task_id:django.request][log.py:228][ERROR][Internal Server Error: /calSensorSimilarity/]
Traceback (most recent call last):
  File "C:\Softwares\Anaconda3\envs\django\lib\site-packages\django\core\handlers\exception.py", line 34, in inner
    response = get_response(request)
  File "C:\Softwares\Anaconda3\envs\django\lib\site-packages\django\core\handlers\base.py", line 115, in _get_response
    response = self.process_exception_by_middleware(e, request)
  File "C:\Softwares\Anaconda3\envs\django\lib\site-packages\django\core\handlers\base.py", line 113, in _get_response
    response = wrapped_callback(request, *callback_args, **callback_kwargs)
  File "D:\Workspace\Projects\vast-challenge-2019-MC2\RadiationVis\backend\views.py", line 57, in calSensorSimilarity
    data = calCorrlelation(params['begintime'], params['endtime'])
  File "D:\Workspace\Projects\vast-challenge-2019-MC2\RadiationVis\backend\dataprocessing\correlation.py", line 251, in calCorrlelation
    result = Dimension_Reduction_MDS(feature_matrix)  # 降维
  File "D:\Workspace\Projects\vast-challenge-2019-MC2\RadiationVis\backend\dataprocessing\correlation.py", line 107, in Dimension_Reduction_MDS
    mds = MDS(n_components=2).fit_transform(feature_matrix)
  File "C:\Softwares\Anaconda3\envs\django\lib\site-packages\sklearn\manifold\mds.py", line 419, in fit_transform
    X = check_array(X)
  File "C:\Softwares\Anaconda3\envs\django\lib\site-packages\sklearn\utils\validation.py", line 542, in check_array
    allow_nan=force_all_finite == 'allow-nan')
  File "C:\Softwares\Anaconda3\envs\django\lib\site-packages\sklearn\utils\validation.py", line 56, in _assert_all_finite
    raise ValueError(msg_err.format(type_err, X.dtype))
ValueError: Input contains NaN, infinity or a value too large for dtype('float64').
[2019-06-16 18:08:11,225][Thread-3:10420][task_id:django.request][log.py:228][ERROR][Internal Server Error: /calSensorSimilarity/]
Traceback (most recent call last):
  File "C:\Softwares\Anaconda3\envs\django\lib\site-packages\django\core\handlers\exception.py", line 34, in inner
    response = get_response(request)
  File "C:\Softwares\Anaconda3\envs\django\lib\site-packages\django\core\handlers\base.py", line 115, in _get_response
    response = self.process_exception_by_middleware(e, request)
  File "C:\Softwares\Anaconda3\envs\django\lib\site-packages\django\core\handlers\base.py", line 113, in _get_response
    response = wrapped_callback(request, *callback_args, **callback_kwargs)
  File "D:\Workspace\Projects\vast-challenge-2019-MC2\RadiationVis\backend\views.py", line 57, in calSensorSimilarity
    data = calCorrlelation(params['begintime'], params['endtime'])
  File "D:\Workspace\Projects\vast-challenge-2019-MC2\RadiationVis\backend\dataprocessing\correlation.py", line 234, in calCorrlelation
    [a, b] = mn.shape
ValueError: not enough values to unpack (expected 2, got 1)
[2019-06-16 21:00:54,617][Thread-1:2208][task_id:django.request][log.py:228][ERROR][Internal Server Error: /calSensorClusters/]
Traceback (most recent call last):
  File "C:\Softwares\Anaconda3\envs\django\lib\site-packages\django\core\handlers\exception.py", line 34, in inner
    response = get_response(request)
  File "C:\Softwares\Anaconda3\envs\django\lib\site-packages\django\core\handlers\base.py", line 115, in _get_response
    response = self.process_exception_by_middleware(e, request)
  File "C:\Softwares\Anaconda3\envs\django\lib\site-packages\django\core\handlers\base.py", line 113, in _get_response
    response = wrapped_callback(request, *callback_args, **callback_kwargs)
  File "D:\Workspace\Projects\vast-challenge-2019-MC2\RadiationVis\backend\views.py", line 64, in calSensorClusters
    data = calCluster(params['begintime'], params['endtime'])
KeyError: 'begintime'
[2019-06-16 21:01:06,793][Thread-2:11964][task_id:django.request][log.py:228][ERROR][Internal Server Error: /calSensorClusters/]
Traceback (most recent call last):
  File "C:\Softwares\Anaconda3\envs\django\lib\site-packages\django\core\handlers\exception.py", line 34, in inner
    response = get_response(request)
  File "C:\Softwares\Anaconda3\envs\django\lib\site-packages\django\core\handlers\base.py", line 115, in _get_response
    response = self.process_exception_by_middleware(e, request)
  File "C:\Softwares\Anaconda3\envs\django\lib\site-packages\django\core\handlers\base.py", line 113, in _get_response
    response = wrapped_callback(request, *callback_args, **callback_kwargs)
  File "D:\Workspace\Projects\vast-challenge-2019-MC2\RadiationVis\backend\views.py", line 64, in calSensorClusters
    data = calCluster(params['begintime'], params['endtime'])
KeyError: 'begintime'
[2019-06-16 21:01:10,837][Thread-2:11964][task_id:django.request][log.py:228][ERROR][Internal Server Error: /calSensorClusters/]
Traceback (most recent call last):
  File "C:\Softwares\Anaconda3\envs\django\lib\site-packages\django\core\handlers\exception.py", line 34, in inner
    response = get_response(request)
  File "C:\Softwares\Anaconda3\envs\django\lib\site-packages\django\core\handlers\base.py", line 115, in _get_response
    response = self.process_exception_by_middleware(e, request)
  File "C:\Softwares\Anaconda3\envs\django\lib\site-packages\django\core\handlers\base.py", line 113, in _get_response
    response = wrapped_callback(request, *callback_args, **callback_kwargs)
  File "D:\Workspace\Projects\vast-challenge-2019-MC2\RadiationVis\backend\views.py", line 64, in calSensorClusters
    data = calCluster(params['begintime'], params['endtime'])
KeyError: 'begintime'
[2019-06-17 00:52:38,941][Thread-73:12868][task_id:django.request][log.py:228][ERROR][Internal Server Error: /findAggMrrByTimeRange/]
Traceback (most recent call last):
  File "C:\Softwares\Anaconda3\envs\django\lib\site-packages\django\core\handlers\exception.py", line 34, in inner
    response = get_response(request)
  File "C:\Softwares\Anaconda3\envs\django\lib\site-packages\django\core\handlers\base.py", line 115, in _get_response
    response = self.process_exception_by_middleware(e, request)
  File "C:\Softwares\Anaconda3\envs\django\lib\site-packages\django\core\handlers\base.py", line 113, in _get_response
    response = wrapped_callback(request, *callback_args, **callback_kwargs)
  File "D:\Workspace\Projects\vast-challenge-2019-MC2\RadiationVis\backend\views.py", line 33, in findAggMrrByTimeRange
    params = json.loads(request.body)
  File "C:\Softwares\Anaconda3\envs\django\lib\json\__init__.py", line 354, in loads
    return _default_decoder.decode(s)
  File "C:\Softwares\Anaconda3\envs\django\lib\json\decoder.py", line 339, in decode
    obj, end = self.raw_decode(s, idx=_w(s, 0).end())
  File "C:\Softwares\Anaconda3\envs\django\lib\json\decoder.py", line 357, in raw_decode
    raise JSONDecodeError("Expecting value", s, err.value) from None
json.decoder.JSONDecodeError: Expecting value: line 1 column 1 (char 0)
[2019-06-17 00:52:38,950][Thread-72:24656][task_id:django.request][log.py:228][ERROR][Internal Server Error: /calSensorClusters/]
Traceback (most recent call last):
  File "C:\Softwares\Anaconda3\envs\django\lib\site-packages\django\core\handlers\exception.py", line 34, in inner
    response = get_response(request)
  File "C:\Softwares\Anaconda3\envs\django\lib\site-packages\django\core\handlers\base.py", line 115, in _get_response
    response = self.process_exception_by_middleware(e, request)
  File "C:\Softwares\Anaconda3\envs\django\lib\site-packages\django\core\handlers\base.py", line 113, in _get_response
    response = wrapped_callback(request, *callback_args, **callback_kwargs)
  File "D:\Workspace\Projects\vast-challenge-2019-MC2\RadiationVis\backend\views.py", line 63, in calSensorClusters
    params = json.loads(request.body)
  File "C:\Softwares\Anaconda3\envs\django\lib\json\__init__.py", line 354, in loads
    return _default_decoder.decode(s)
  File "C:\Softwares\Anaconda3\envs\django\lib\json\decoder.py", line 339, in decode
    obj, end = self.raw_decode(s, idx=_w(s, 0).end())
  File "C:\Softwares\Anaconda3\envs\django\lib\json\decoder.py", line 357, in raw_decode
    raise JSONDecodeError("Expecting value", s, err.value) from None
json.decoder.JSONDecodeError: Expecting value: line 1 column 1 (char 0)
[2019-06-17 00:52:38,955][Thread-71:6664][task_id:django.request][log.py:228][ERROR][Internal Server Error: /findAggSrrByTimeRange/]
Traceback (most recent call last):
  File "C:\Softwares\Anaconda3\envs\django\lib\site-packages\django\core\handlers\exception.py", line 34, in inner
    response = get_response(request)
  File "C:\Softwares\Anaconda3\envs\django\lib\site-packages\django\core\handlers\base.py", line 115, in _get_response
    response = self.process_exception_by_middleware(e, request)
  File "C:\Softwares\Anaconda3\envs\django\lib\site-packages\django\core\handlers\base.py", line 113, in _get_response
    response = wrapped_callback(request, *callback_args, **callback_kwargs)
  File "D:\Workspace\Projects\vast-challenge-2019-MC2\RadiationVis\backend\views.py", line 45, in findAggSrrByTimeRange
    params = json.loads(request.body)
  File "C:\Softwares\Anaconda3\envs\django\lib\json\__init__.py", line 354, in loads
    return _default_decoder.decode(s)
  File "C:\Softwares\Anaconda3\envs\django\lib\json\decoder.py", line 339, in decode
    obj, end = self.raw_decode(s, idx=_w(s, 0).end())
  File "C:\Softwares\Anaconda3\envs\django\lib\json\decoder.py", line 357, in raw_decode
    raise JSONDecodeError("Expecting value", s, err.value) from None
json.decoder.JSONDecodeError: Expecting value: line 1 column 1 (char 0)
[2019-06-17 00:52:41,210][Thread-73:12868][task_id:django.request][log.py:228][ERROR][Internal Server Error: /calSensorClusters/]
Traceback (most recent call last):
  File "C:\Softwares\Anaconda3\envs\django\lib\site-packages\django\core\handlers\exception.py", line 34, in inner
    response = get_response(request)
  File "C:\Softwares\Anaconda3\envs\django\lib\site-packages\django\core\handlers\base.py", line 115, in _get_response
    response = self.process_exception_by_middleware(e, request)
  File "C:\Softwares\Anaconda3\envs\django\lib\site-packages\django\core\handlers\base.py", line 113, in _get_response
    response = wrapped_callback(request, *callback_args, **callback_kwargs)
  File "D:\Workspace\Projects\vast-challenge-2019-MC2\RadiationVis\backend\views.py", line 63, in calSensorClusters
    params = json.loads(request.body)
  File "C:\Softwares\Anaconda3\envs\django\lib\json\__init__.py", line 354, in loads
    return _default_decoder.decode(s)
  File "C:\Softwares\Anaconda3\envs\django\lib\json\decoder.py", line 339, in decode
    obj, end = self.raw_decode(s, idx=_w(s, 0).end())
  File "C:\Softwares\Anaconda3\envs\django\lib\json\decoder.py", line 357, in raw_decode
    raise JSONDecodeError("Expecting value", s, err.value) from None
json.decoder.JSONDecodeError: Expecting value: line 1 column 1 (char 0)
[2019-06-17 00:52:41,219][Thread-72:24656][task_id:django.request][log.py:228][ERROR][Internal Server Error: /findAggMrrByTimeRange/]
Traceback (most recent call last):
  File "C:\Softwares\Anaconda3\envs\django\lib\site-packages\django\core\handlers\exception.py", line 34, in inner
    response = get_response(request)
  File "C:\Softwares\Anaconda3\envs\django\lib\site-packages\django\core\handlers\base.py", line 115, in _get_response
    response = self.process_exception_by_middleware(e, request)
  File "C:\Softwares\Anaconda3\envs\django\lib\site-packages\django\core\handlers\base.py", line 113, in _get_response
    response = wrapped_callback(request, *callback_args, **callback_kwargs)
  File "D:\Workspace\Projects\vast-challenge-2019-MC2\RadiationVis\backend\views.py", line 33, in findAggMrrByTimeRange
    params = json.loads(request.body)
  File "C:\Softwares\Anaconda3\envs\django\lib\json\__init__.py", line 354, in loads
    return _default_decoder.decode(s)
  File "C:\Softwares\Anaconda3\envs\django\lib\json\decoder.py", line 339, in decode
    obj, end = self.raw_decode(s, idx=_w(s, 0).end())
  File "C:\Softwares\Anaconda3\envs\django\lib\json\decoder.py", line 357, in raw_decode
    raise JSONDecodeError("Expecting value", s, err.value) from None
json.decoder.JSONDecodeError: Expecting value: line 1 column 1 (char 0)
[2019-06-17 00:52:41,221][Thread-71:6664][task_id:django.request][log.py:228][ERROR][Internal Server Error: /findAggSrrByTimeRange/]
Traceback (most recent call last):
  File "C:\Softwares\Anaconda3\envs\django\lib\site-packages\django\core\handlers\exception.py", line 34, in inner
    response = get_response(request)
  File "C:\Softwares\Anaconda3\envs\django\lib\site-packages\django\core\handlers\base.py", line 115, in _get_response
    response = self.process_exception_by_middleware(e, request)
  File "C:\Softwares\Anaconda3\envs\django\lib\site-packages\django\core\handlers\base.py", line 113, in _get_response
    response = wrapped_callback(request, *callback_args, **callback_kwargs)
  File "D:\Workspace\Projects\vast-challenge-2019-MC2\RadiationVis\backend\views.py", line 45, in findAggSrrByTimeRange
    params = json.loads(request.body)
  File "C:\Softwares\Anaconda3\envs\django\lib\json\__init__.py", line 354, in loads
    return _default_decoder.decode(s)
  File "C:\Softwares\Anaconda3\envs\django\lib\json\decoder.py", line 339, in decode
    obj, end = self.raw_decode(s, idx=_w(s, 0).end())
  File "C:\Softwares\Anaconda3\envs\django\lib\json\decoder.py", line 357, in raw_decode
    raise JSONDecodeError("Expecting value", s, err.value) from None
json.decoder.JSONDecodeError: Expecting value: line 1 column 1 (char 0)
[2019-06-17 00:52:51,548][Thread-71:6664][task_id:django.request][log.py:228][ERROR][Internal Server Error: /findAggSrrByTimeRange/]
Traceback (most recent call last):
  File "C:\Softwares\Anaconda3\envs\django\lib\site-packages\django\core\handlers\exception.py", line 34, in inner
    response = get_response(request)
  File "C:\Softwares\Anaconda3\envs\django\lib\site-packages\django\core\handlers\base.py", line 115, in _get_response
    response = self.process_exception_by_middleware(e, request)
  File "C:\Softwares\Anaconda3\envs\django\lib\site-packages\django\core\handlers\base.py", line 113, in _get_response
    response = wrapped_callback(request, *callback_args, **callback_kwargs)
  File "D:\Workspace\Projects\vast-challenge-2019-MC2\RadiationVis\backend\views.py", line 45, in findAggSrrByTimeRange
    params = json.loads(request.body)
  File "C:\Softwares\Anaconda3\envs\django\lib\json\__init__.py", line 354, in loads
    return _default_decoder.decode(s)
  File "C:\Softwares\Anaconda3\envs\django\lib\json\decoder.py", line 339, in decode
    obj, end = self.raw_decode(s, idx=_w(s, 0).end())
  File "C:\Softwares\Anaconda3\envs\django\lib\json\decoder.py", line 357, in raw_decode
    raise JSONDecodeError("Expecting value", s, err.value) from None
json.decoder.JSONDecodeError: Expecting value: line 1 column 1 (char 0)
[2019-06-17 00:52:51,549][Thread-73:12868][task_id:django.request][log.py:228][ERROR][Internal Server Error: /calSensorClusters/]
Traceback (most recent call last):
  File "C:\Softwares\Anaconda3\envs\django\lib\site-packages\django\core\handlers\exception.py", line 34, in inner
    response = get_response(request)
  File "C:\Softwares\Anaconda3\envs\django\lib\site-packages\django\core\handlers\base.py", line 115, in _get_response
    response = self.process_exception_by_middleware(e, request)
  File "C:\Softwares\Anaconda3\envs\django\lib\site-packages\django\core\handlers\base.py", line 113, in _get_response
    response = wrapped_callback(request, *callback_args, **callback_kwargs)
  File "D:\Workspace\Projects\vast-challenge-2019-MC2\RadiationVis\backend\views.py", line 63, in calSensorClusters
    params = json.loads(request.body)
  File "C:\Softwares\Anaconda3\envs\django\lib\json\__init__.py", line 354, in loads
    return _default_decoder.decode(s)
  File "C:\Softwares\Anaconda3\envs\django\lib\json\decoder.py", line 339, in decode
    obj, end = self.raw_decode(s, idx=_w(s, 0).end())
  File "C:\Softwares\Anaconda3\envs\django\lib\json\decoder.py", line 357, in raw_decode
    raise JSONDecodeError("Expecting value", s, err.value) from None
json.decoder.JSONDecodeError: Expecting value: line 1 column 1 (char 0)
[2019-06-17 00:52:51,551][Thread-72:24656][task_id:django.request][log.py:228][ERROR][Internal Server Error: /findAggMrrByTimeRange/]
Traceback (most recent call last):
  File "C:\Softwares\Anaconda3\envs\django\lib\site-packages\django\core\handlers\exception.py", line 34, in inner
    response = get_response(request)
  File "C:\Softwares\Anaconda3\envs\django\lib\site-packages\django\core\handlers\base.py", line 115, in _get_response
    response = self.process_exception_by_middleware(e, request)
  File "C:\Softwares\Anaconda3\envs\django\lib\site-packages\django\core\handlers\base.py", line 113, in _get_response
    response = wrapped_callback(request, *callback_args, **callback_kwargs)
  File "D:\Workspace\Projects\vast-challenge-2019-MC2\RadiationVis\backend\views.py", line 33, in findAggMrrByTimeRange
    params = json.loads(request.body)
  File "C:\Softwares\Anaconda3\envs\django\lib\json\__init__.py", line 354, in loads
    return _default_decoder.decode(s)
  File "C:\Softwares\Anaconda3\envs\django\lib\json\decoder.py", line 339, in decode
    obj, end = self.raw_decode(s, idx=_w(s, 0).end())
  File "C:\Softwares\Anaconda3\envs\django\lib\json\decoder.py", line 357, in raw_decode
    raise JSONDecodeError("Expecting value", s, err.value) from None
json.decoder.JSONDecodeError: Expecting value: line 1 column 1 (char 0)
[2019-06-17 00:53:46,925][Thread-72:24656][task_id:django.request][log.py:228][ERROR][Internal Server Error: /calSensorClusters/]
Traceback (most recent call last):
  File "C:\Softwares\Anaconda3\envs\django\lib\site-packages\django\core\handlers\exception.py", line 34, in inner
    response = get_response(request)
  File "C:\Softwares\Anaconda3\envs\django\lib\site-packages\django\core\handlers\base.py", line 115, in _get_response
    response = self.process_exception_by_middleware(e, request)
  File "C:\Softwares\Anaconda3\envs\django\lib\site-packages\django\core\handlers\base.py", line 113, in _get_response
    response = wrapped_callback(request, *callback_args, **callback_kwargs)
  File "D:\Workspace\Projects\vast-challenge-2019-MC2\RadiationVis\backend\views.py", line 63, in calSensorClusters
    params = json.loads(request.body)
  File "C:\Softwares\Anaconda3\envs\django\lib\json\__init__.py", line 354, in loads
    return _default_decoder.decode(s)
  File "C:\Softwares\Anaconda3\envs\django\lib\json\decoder.py", line 339, in decode
    obj, end = self.raw_decode(s, idx=_w(s, 0).end())
  File "C:\Softwares\Anaconda3\envs\django\lib\json\decoder.py", line 357, in raw_decode
    raise JSONDecodeError("Expecting value", s, err.value) from None
json.decoder.JSONDecodeError: Expecting value: line 1 column 1 (char 0)
[2019-06-17 00:53:46,941][Thread-73:12868][task_id:django.request][log.py:228][ERROR][Internal Server Error: /findAggMrrByTimeRange/]
Traceback (most recent call last):
  File "C:\Softwares\Anaconda3\envs\django\lib\site-packages\django\core\handlers\exception.py", line 34, in inner
    response = get_response(request)
  File "C:\Softwares\Anaconda3\envs\django\lib\site-packages\django\core\handlers\base.py", line 115, in _get_response
    response = self.process_exception_by_middleware(e, request)
  File "C:\Softwares\Anaconda3\envs\django\lib\site-packages\django\core\handlers\base.py", line 113, in _get_response
    response = wrapped_callback(request, *callback_args, **callback_kwargs)
  File "D:\Workspace\Projects\vast-challenge-2019-MC2\RadiationVis\backend\views.py", line 33, in findAggMrrByTimeRange
    params = json.loads(request.body)
  File "C:\Softwares\Anaconda3\envs\django\lib\json\__init__.py", line 354, in loads
    return _default_decoder.decode(s)
  File "C:\Softwares\Anaconda3\envs\django\lib\json\decoder.py", line 339, in decode
    obj, end = self.raw_decode(s, idx=_w(s, 0).end())
  File "C:\Softwares\Anaconda3\envs\django\lib\json\decoder.py", line 357, in raw_decode
    raise JSONDecodeError("Expecting value", s, err.value) from None
json.decoder.JSONDecodeError: Expecting value: line 1 column 1 (char 0)
[2019-06-17 00:53:46,953][Thread-71:6664][task_id:django.request][log.py:228][ERROR][Internal Server Error: /findAggSrrByTimeRange/]
Traceback (most recent call last):
  File "C:\Softwares\Anaconda3\envs\django\lib\site-packages\django\core\handlers\exception.py", line 34, in inner
    response = get_response(request)
  File "C:\Softwares\Anaconda3\envs\django\lib\site-packages\django\core\handlers\base.py", line 115, in _get_response
    response = self.process_exception_by_middleware(e, request)
  File "C:\Softwares\Anaconda3\envs\django\lib\site-packages\django\core\handlers\base.py", line 113, in _get_response
    response = wrapped_callback(request, *callback_args, **callback_kwargs)
  File "D:\Workspace\Projects\vast-challenge-2019-MC2\RadiationVis\backend\views.py", line 45, in findAggSrrByTimeRange
    params = json.loads(request.body)
  File "C:\Softwares\Anaconda3\envs\django\lib\json\__init__.py", line 354, in loads
    return _default_decoder.decode(s)
  File "C:\Softwares\Anaconda3\envs\django\lib\json\decoder.py", line 339, in decode
    obj, end = self.raw_decode(s, idx=_w(s, 0).end())
  File "C:\Softwares\Anaconda3\envs\django\lib\json\decoder.py", line 357, in raw_decode
    raise JSONDecodeError("Expecting value", s, err.value) from None
json.decoder.JSONDecodeError: Expecting value: line 1 column 1 (char 0)
[2019-06-17 01:22:29,013][Thread-1:14096][task_id:django.request][log.py:228][ERROR][Internal Server Error: /calTimeSeriesBySid/]
Traceback (most recent call last):
  File "C:\Softwares\Anaconda3\envs\django\lib\site-packages\django\core\handlers\exception.py", line 34, in inner
    response = get_response(request)
  File "C:\Softwares\Anaconda3\envs\django\lib\site-packages\django\core\handlers\base.py", line 115, in _get_response
    response = self.process_exception_by_middleware(e, request)
  File "C:\Softwares\Anaconda3\envs\django\lib\site-packages\django\core\handlers\base.py", line 113, in _get_response
    response = wrapped_callback(request, *callback_args, **callback_kwargs)
  File "D:\Workspace\Projects\vast-challenge-2019-MC2\RadiationVis\backend\views.py", line 116, in calTimeSeriesBySid
    begintime_str = params['begintime']
KeyError: 'begintime'
[2019-06-17 01:26:44,096][Thread-9:1160][task_id:django.request][log.py:228][ERROR][Internal Server Error: /calTimeSeriesBySid/]
Traceback (most recent call last):
  File "C:\Softwares\Anaconda3\envs\django\lib\site-packages\django\core\handlers\exception.py", line 34, in inner
    response = get_response(request)
  File "C:\Softwares\Anaconda3\envs\django\lib\site-packages\django\core\handlers\base.py", line 115, in _get_response
    response = self.process_exception_by_middleware(e, request)
  File "C:\Softwares\Anaconda3\envs\django\lib\site-packages\django\core\handlers\base.py", line 113, in _get_response
    response = wrapped_callback(request, *callback_args, **callback_kwargs)
  File "D:\Workspace\Projects\vast-challenge-2019-MC2\RadiationVis\backend\views.py", line 116, in calTimeSeriesBySid
    begintime_str = params['begintime']
KeyError: 'begintime'
