[2019-06-29 13:06:58,407][MainThread:8756][task_id:django.utils.autoreload][autoreload.py:576][INFO][Watching for file changes with StatReloader]
[2019-06-29 13:48:22,681][Thread-56:13688][task_id:django.request][log.py:228][WARNING][Not Found: /findSrrByTimeRange/]
[2019-06-29 13:51:44,536][Thread-60:14404][task_id:django.request][log.py:228][WARNING][Not Found: /getMrrByTimeRange/]
[2019-06-29 14:19:50,825][Thread-87:12328][task_id:django.request][log.py:228][ERROR][Internal Server Error: /calSensorClusters/]
Traceback (most recent call last):
  File "C:\Softwares\Anaconda3\envs\django\lib\site-packages\django\core\handlers\exception.py", line 34, in inner
    response = get_response(request)
  File "C:\Softwares\Anaconda3\envs\django\lib\site-packages\django\core\handlers\base.py", line 115, in _get_response
    response = self.process_exception_by_middleware(e, request)
  File "C:\Softwares\Anaconda3\envs\django\lib\site-packages\django\core\handlers\base.py", line 113, in _get_response
    response = wrapped_callback(request, *callback_args, **callback_kwargs)
  File "D:\Workspace\Projects\vast-challenge-2019-MC2\RadiationVis\backend\views.py", line 76, in calSensorClusters
    data = calCluster(params['begintime'], params['endtime'])
  File "D:\Workspace\Projects\vast-challenge-2019-MC2\RadiationVis\backend\dataprocessing\cluster.py", line 220, in calCluster
    [a, b] = mn.shape
ValueError: not enough values to unpack (expected 2, got 1)
[2019-06-29 14:52:51,137][Thread-93:10156][task_id:django.request][log.py:228][ERROR][Internal Server Error: /findMrrByTimeRange/]
Traceback (most recent call last):
  File "C:\Softwares\Anaconda3\envs\django\lib\site-packages\django\core\handlers\exception.py", line 34, in inner
    response = get_response(request)
  File "C:\Softwares\Anaconda3\envs\django\lib\site-packages\django\core\handlers\base.py", line 115, in _get_response
    response = self.process_exception_by_middleware(e, request)
  File "C:\Softwares\Anaconda3\envs\django\lib\site-packages\django\core\handlers\base.py", line 113, in _get_response
    response = wrapped_callback(request, *callback_args, **callback_kwargs)
  File "D:\Workspace\Projects\vast-challenge-2019-MC2\RadiationVis\backend\views.py", line 45, in findMrrByTimeRange
    params = json.loads(request.body)
  File "C:\Softwares\Anaconda3\envs\django\lib\json\__init__.py", line 354, in loads
    return _default_decoder.decode(s)
  File "C:\Softwares\Anaconda3\envs\django\lib\json\decoder.py", line 339, in decode
    obj, end = self.raw_decode(s, idx=_w(s, 0).end())
  File "C:\Softwares\Anaconda3\envs\django\lib\json\decoder.py", line 357, in raw_decode
    raise JSONDecodeError("Expecting value", s, err.value) from None
json.decoder.JSONDecodeError: Expecting value: line 1 column 1 (char 0)
[2019-06-29 15:24:54,695][Thread-105:2016][task_id:django.request][log.py:228][ERROR][Internal Server Error: /findMrrByTimeRange/]
Traceback (most recent call last):
  File "C:\Softwares\Anaconda3\envs\django\lib\site-packages\django\core\handlers\exception.py", line 34, in inner
    response = get_response(request)
  File "C:\Softwares\Anaconda3\envs\django\lib\site-packages\django\core\handlers\base.py", line 115, in _get_response
    response = self.process_exception_by_middleware(e, request)
  File "C:\Softwares\Anaconda3\envs\django\lib\site-packages\django\core\handlers\base.py", line 113, in _get_response
    response = wrapped_callback(request, *callback_args, **callback_kwargs)
  File "D:\Workspace\Projects\vast-challenge-2019-MC2\RadiationVis\backend\views.py", line 45, in findMrrByTimeRange
    params = json.loads(request.body)
  File "C:\Softwares\Anaconda3\envs\django\lib\json\__init__.py", line 354, in loads
    return _default_decoder.decode(s)
  File "C:\Softwares\Anaconda3\envs\django\lib\json\decoder.py", line 339, in decode
    obj, end = self.raw_decode(s, idx=_w(s, 0).end())
  File "C:\Softwares\Anaconda3\envs\django\lib\json\decoder.py", line 357, in raw_decode
    raise JSONDecodeError("Expecting value", s, err.value) from None
json.decoder.JSONDecodeError: Expecting value: line 1 column 1 (char 0)
[2019-06-29 15:25:33,891][Thread-106:3432][task_id:django.request][log.py:228][ERROR][Internal Server Error: /findMrrByTimeRange/]
Traceback (most recent call last):
  File "C:\Softwares\Anaconda3\envs\django\lib\site-packages\django\core\handlers\exception.py", line 34, in inner
    response = get_response(request)
  File "C:\Softwares\Anaconda3\envs\django\lib\site-packages\django\core\handlers\base.py", line 115, in _get_response
    response = self.process_exception_by_middleware(e, request)
  File "C:\Softwares\Anaconda3\envs\django\lib\site-packages\django\core\handlers\base.py", line 113, in _get_response
    response = wrapped_callback(request, *callback_args, **callback_kwargs)
  File "D:\Workspace\Projects\vast-challenge-2019-MC2\RadiationVis\backend\views.py", line 45, in findMrrByTimeRange
    params = json.loads(request.body)
  File "C:\Softwares\Anaconda3\envs\django\lib\json\__init__.py", line 354, in loads
    return _default_decoder.decode(s)
  File "C:\Softwares\Anaconda3\envs\django\lib\json\decoder.py", line 339, in decode
    obj, end = self.raw_decode(s, idx=_w(s, 0).end())
  File "C:\Softwares\Anaconda3\envs\django\lib\json\decoder.py", line 357, in raw_decode
    raise JSONDecodeError("Expecting value", s, err.value) from None
json.decoder.JSONDecodeError: Expecting value: line 1 column 1 (char 0)
[2019-06-29 16:54:16,616][MainThread:9080][task_id:django.utils.autoreload][autoreload.py:576][INFO][Watching for file changes with StatReloader]
[2019-06-30 10:26:56,649][MainThread:15200][task_id:django.utils.autoreload][autoreload.py:576][INFO][Watching for file changes with StatReloader]
[2019-06-30 11:40:40,329][MainThread:15200][task_id:django.utils.autoreload][autoreload.py:203][INFO][D:\Workspace\Projects\vast-challenge-2019-MC2\RadiationVis\backend\views.py changed, reloading.]
[2019-06-30 11:40:44,536][MainThread:8448][task_id:django.utils.autoreload][autoreload.py:576][INFO][Watching for file changes with StatReloader]
[2019-06-30 11:41:25,990][MainThread:8448][task_id:django.utils.autoreload][autoreload.py:203][INFO][D:\Workspace\Projects\vast-challenge-2019-MC2\RadiationVis\RadiationVis\urls.py changed, reloading.]
[2019-06-30 11:41:27,883][MainThread:1476][task_id:django.utils.autoreload][autoreload.py:576][INFO][Watching for file changes with StatReloader]
[2019-06-30 11:57:06,725][Thread-6:17592][task_id:django.request][log.py:228][ERROR][Internal Server Error: /findMrrByTimeRangeAndSid/]
Traceback (most recent call last):
  File "C:\Softwares\Anaconda3\envs\django\lib\site-packages\django\core\handlers\exception.py", line 34, in inner
    response = get_response(request)
  File "C:\Softwares\Anaconda3\envs\django\lib\site-packages\django\core\handlers\base.py", line 115, in _get_response
    response = self.process_exception_by_middleware(e, request)
  File "C:\Softwares\Anaconda3\envs\django\lib\site-packages\django\core\handlers\base.py", line 113, in _get_response
    response = wrapped_callback(request, *callback_args, **callback_kwargs)
  File "D:\Workspace\Projects\vast-challenge-2019-MC2\RadiationVis\backend\views.py", line 61, in findMrrByTimeRangeAndSid
    cursor.execute("select longitude, latitude, value from mobilesensorreadings where timestamp > '{0}'  and timestamp < '{1}' and sid = {2}".format(params['begintime'], params['endtime']), params['sid'])
IndexError: tuple index out of range
[2019-06-30 11:57:27,331][Thread-4:20700][task_id:django.request][log.py:228][ERROR][Internal Server Error: /findMrrByTimeRangeAndSid/]
Traceback (most recent call last):
  File "C:\Softwares\Anaconda3\envs\django\lib\site-packages\django\core\handlers\exception.py", line 34, in inner
    response = get_response(request)
  File "C:\Softwares\Anaconda3\envs\django\lib\site-packages\django\core\handlers\base.py", line 115, in _get_response
    response = self.process_exception_by_middleware(e, request)
  File "C:\Softwares\Anaconda3\envs\django\lib\site-packages\django\core\handlers\base.py", line 113, in _get_response
    response = wrapped_callback(request, *callback_args, **callback_kwargs)
  File "D:\Workspace\Projects\vast-challenge-2019-MC2\RadiationVis\backend\views.py", line 61, in findMrrByTimeRangeAndSid
    cursor.execute("select longitude, latitude, value from mobilesensorreadings where timestamp > '{0}'  and timestamp < '{1}' and sid = {2}".format(params['begintime'], params['endtime']), params['sid'])
IndexError: tuple index out of range
[2019-06-30 12:11:54,547][Thread-15:6348][task_id:django.request][log.py:228][ERROR][Internal Server Error: /findMrrByTimeRange/]
Traceback (most recent call last):
  File "C:\Softwares\Anaconda3\envs\django\lib\site-packages\django\core\handlers\exception.py", line 34, in inner
    response = get_response(request)
  File "C:\Softwares\Anaconda3\envs\django\lib\site-packages\django\core\handlers\base.py", line 115, in _get_response
    response = self.process_exception_by_middleware(e, request)
  File "C:\Softwares\Anaconda3\envs\django\lib\site-packages\django\core\handlers\base.py", line 113, in _get_response
    response = wrapped_callback(request, *callback_args, **callback_kwargs)
  File "D:\Workspace\Projects\vast-challenge-2019-MC2\RadiationVis\backend\views.py", line 52, in findMrrByTimeRange
    data = [dict(zip([col[0] for col in desc], row)) for row in alldata]
  File "D:\Workspace\Projects\vast-challenge-2019-MC2\RadiationVis\backend\views.py", line 52, in <listcomp>
    data = [dict(zip([col[0] for col in desc], row)) for row in alldata]
MemoryError
[2019-06-30 12:14:18,851][Thread-33:2580][task_id:django.request][log.py:228][ERROR][Internal Server Error: /findMrrByTimeRangeAndSid/]
Traceback (most recent call last):
  File "C:\Softwares\Anaconda3\envs\django\lib\site-packages\django\core\handlers\exception.py", line 34, in inner
    response = get_response(request)
  File "C:\Softwares\Anaconda3\envs\django\lib\site-packages\django\core\handlers\base.py", line 115, in _get_response
    response = self.process_exception_by_middleware(e, request)
  File "C:\Softwares\Anaconda3\envs\django\lib\site-packages\django\core\handlers\base.py", line 113, in _get_response
    response = wrapped_callback(request, *callback_args, **callback_kwargs)
  File "D:\Workspace\Projects\vast-challenge-2019-MC2\RadiationVis\backend\views.py", line 61, in findMrrByTimeRangeAndSid
    cursor.execute("select longitude, latitude, value from mobilesensorreadings where timestamp > '{0}'  and timestamp < '{1}' and sid = {2}".format(params['begintime'], params['endtime']), params['sid'])
IndexError: tuple index out of range
[2019-06-30 12:17:05,213][Thread-37:7316][task_id:django.request][log.py:228][ERROR][Internal Server Error: /findMrrByTimeRangeAndSid/]
Traceback (most recent call last):
  File "C:\Softwares\Anaconda3\envs\django\lib\site-packages\django\core\handlers\exception.py", line 34, in inner
    response = get_response(request)
  File "C:\Softwares\Anaconda3\envs\django\lib\site-packages\django\core\handlers\base.py", line 115, in _get_response
    response = self.process_exception_by_middleware(e, request)
  File "C:\Softwares\Anaconda3\envs\django\lib\site-packages\django\core\handlers\base.py", line 113, in _get_response
    response = wrapped_callback(request, *callback_args, **callback_kwargs)
  File "D:\Workspace\Projects\vast-challenge-2019-MC2\RadiationVis\backend\views.py", line 61, in findMrrByTimeRangeAndSid
    cursor.execute("select longitude, latitude, value from mobilesensorreadings where timestamp > '{0}'  and timestamp < '{1}' and sid = {2}".format(params['begintime'], params['endtime']), params['sid'])
IndexError: tuple index out of range
[2019-06-30 12:20:18,089][Thread-41:9324][task_id:django.request][log.py:228][ERROR][Internal Server Error: /findMrrByTimeRangeAndSid/]
Traceback (most recent call last):
  File "C:\Softwares\Anaconda3\envs\django\lib\site-packages\django\core\handlers\exception.py", line 34, in inner
    response = get_response(request)
  File "C:\Softwares\Anaconda3\envs\django\lib\site-packages\django\core\handlers\base.py", line 115, in _get_response
    response = self.process_exception_by_middleware(e, request)
  File "C:\Softwares\Anaconda3\envs\django\lib\site-packages\django\core\handlers\base.py", line 113, in _get_response
    response = wrapped_callback(request, *callback_args, **callback_kwargs)
  File "D:\Workspace\Projects\vast-challenge-2019-MC2\RadiationVis\backend\views.py", line 61, in findMrrByTimeRangeAndSid
    cursor.execute("select longitude, latitude, value from mobilesensorreadings where timestamp > '{0}'  and timestamp < '{1}' and sid = {2}".format(params['begintime'], params['endtime'], params['sid']))
IndexError: tuple index out of range
[2019-06-30 12:20:39,693][Thread-45:12692][task_id:django.request][log.py:228][ERROR][Internal Server Error: /findMrrByTimeRangeAndSid/]
Traceback (most recent call last):
  File "C:\Softwares\Anaconda3\envs\django\lib\site-packages\django\core\handlers\exception.py", line 34, in inner
    response = get_response(request)
  File "C:\Softwares\Anaconda3\envs\django\lib\site-packages\django\core\handlers\base.py", line 115, in _get_response
    response = self.process_exception_by_middleware(e, request)
  File "C:\Softwares\Anaconda3\envs\django\lib\site-packages\django\core\handlers\base.py", line 113, in _get_response
    response = wrapped_callback(request, *callback_args, **callback_kwargs)
  File "D:\Workspace\Projects\vast-challenge-2019-MC2\RadiationVis\backend\views.py", line 61, in findMrrByTimeRangeAndSid
    cursor.execute("select longitude, latitude, value from mobilesensorreadings where timestamp > '{0}'  and timestamp < '{1}' and sid = {2}".format(params['begintime'], params['endtime'], params['sid']))
IndexError: tuple index out of range
[2019-06-30 12:20:42,072][Thread-42:308][task_id:django.request][log.py:228][ERROR][Internal Server Error: /calSensorClusters/]
Traceback (most recent call last):
  File "C:\Softwares\Anaconda3\envs\django\lib\site-packages\django\core\handlers\exception.py", line 34, in inner
    response = get_response(request)
  File "C:\Softwares\Anaconda3\envs\django\lib\site-packages\django\core\handlers\base.py", line 115, in _get_response
    response = self.process_exception_by_middleware(e, request)
  File "C:\Softwares\Anaconda3\envs\django\lib\site-packages\django\core\handlers\base.py", line 113, in _get_response
    response = wrapped_callback(request, *callback_args, **callback_kwargs)
  File "D:\Workspace\Projects\vast-challenge-2019-MC2\RadiationVis\backend\views.py", line 88, in calSensorClusters
    data = calCluster(params['begintime'], params['endtime'])
  File "D:\Workspace\Projects\vast-challenge-2019-MC2\RadiationVis\backend\dataprocessing\cluster.py", line 233, in calCluster
    cluster = Cluster_DBSCAN(result)
  File "D:\Workspace\Projects\vast-challenge-2019-MC2\RadiationVis\backend\dataprocessing\cluster.py", line 129, in Cluster_DBSCAN
    cluster_res = DBSCAN(eps=0.05, min_samples=3).fit_predict(result)
  File "C:\Softwares\Anaconda3\envs\django\lib\site-packages\sklearn\cluster\dbscan_.py", line 383, in fit_predict
    self.fit(X, sample_weight=sample_weight)
  File "C:\Softwares\Anaconda3\envs\django\lib\site-packages\sklearn\cluster\dbscan_.py", line 349, in fit
    X = check_array(X, accept_sparse='csr')
  File "C:\Softwares\Anaconda3\envs\django\lib\site-packages\sklearn\utils\validation.py", line 542, in check_array
    allow_nan=force_all_finite == 'allow-nan')
  File "C:\Softwares\Anaconda3\envs\django\lib\site-packages\sklearn\utils\validation.py", line 56, in _assert_all_finite
    raise ValueError(msg_err.format(type_err, X.dtype))
ValueError: Input contains NaN, infinity or a value too large for dtype('float64').
[2019-06-30 12:20:52,876][Thread-43:17292][task_id:django.request][log.py:228][ERROR][Internal Server Error: /findMrrByTimeRangeAndSid/]
Traceback (most recent call last):
  File "C:\Softwares\Anaconda3\envs\django\lib\site-packages\django\core\handlers\exception.py", line 34, in inner
    response = get_response(request)
  File "C:\Softwares\Anaconda3\envs\django\lib\site-packages\django\core\handlers\base.py", line 115, in _get_response
    response = self.process_exception_by_middleware(e, request)
  File "C:\Softwares\Anaconda3\envs\django\lib\site-packages\django\core\handlers\base.py", line 113, in _get_response
    response = wrapped_callback(request, *callback_args, **callback_kwargs)
  File "D:\Workspace\Projects\vast-challenge-2019-MC2\RadiationVis\backend\views.py", line 61, in findMrrByTimeRangeAndSid
    cursor.execute("select longitude, latitude, value from mobilesensorreadings where timestamp > '{0}'  and timestamp < '{1}' and sid = {2}".format(params['begintime'], params['endtime'], params['sid']))
IndexError: tuple index out of range
[2019-06-30 12:21:47,979][Thread-49:16600][task_id:django.request][log.py:228][ERROR][Internal Server Error: /findMrrByTimeRangeAndSid/]
Traceback (most recent call last):
  File "C:\Softwares\Anaconda3\envs\django\lib\site-packages\django\core\handlers\exception.py", line 34, in inner
    response = get_response(request)
  File "C:\Softwares\Anaconda3\envs\django\lib\site-packages\django\core\handlers\base.py", line 115, in _get_response
    response = self.process_exception_by_middleware(e, request)
  File "C:\Softwares\Anaconda3\envs\django\lib\site-packages\django\core\handlers\base.py", line 113, in _get_response
    response = wrapped_callback(request, *callback_args, **callback_kwargs)
  File "D:\Workspace\Projects\vast-challenge-2019-MC2\RadiationVis\backend\views.py", line 61, in findMrrByTimeRangeAndSid
    cursor.execute("select longitude, latitude, value from mobilesensorreadings where timestamp > '{0}'  and timestamp < '{1}' and sid = '{2}'".format(params['begintime'], params['endtime'], params['sid']))
IndexError: tuple index out of range
[2019-06-30 12:23:03,982][MainThread:1476][task_id:django.utils.autoreload][autoreload.py:203][INFO][D:\Workspace\Projects\vast-challenge-2019-MC2\RadiationVis\backend\views.py changed, reloading.]
[2019-06-30 12:23:11,846][MainThread:16368][task_id:django.utils.autoreload][autoreload.py:576][INFO][Watching for file changes with StatReloader]
[2019-06-30 12:25:42,704][MainThread:16368][task_id:django.utils.autoreload][autoreload.py:203][INFO][D:\Workspace\Projects\vast-challenge-2019-MC2\RadiationVis\backend\views.py changed, reloading.]
[2019-06-30 12:25:44,745][MainThread:15956][task_id:django.utils.autoreload][autoreload.py:576][INFO][Watching for file changes with StatReloader]
[2019-06-30 12:26:59,108][MainThread:15956][task_id:django.utils.autoreload][autoreload.py:203][INFO][D:\Workspace\Projects\vast-challenge-2019-MC2\RadiationVis\backend\views.py changed, reloading.]
[2019-06-30 12:27:00,452][MainThread:11436][task_id:django.utils.autoreload][autoreload.py:576][INFO][Watching for file changes with StatReloader]
[2019-06-30 12:27:03,899][Thread-5:17396][task_id:backend.views][views.py:60][INFO][<class 'int'>]
[2019-06-30 12:29:05,426][Thread-1:10100][task_id:backend.views][views.py:60][INFO][<class 'int'>]
[2019-06-30 12:38:08,118][Thread-7:18048][task_id:backend.views][views.py:60][INFO][<class 'int'>]
[2019-06-30 12:39:13,140][Thread-6:11888][task_id:backend.views][views.py:60][INFO][<class 'int'>]
[2019-06-30 12:41:29,617][Thread-6:11888][task_id:backend.views][views.py:60][INFO][<class 'int'>]
[2019-06-30 12:41:34,831][Thread-11:15564][task_id:backend.views][views.py:60][INFO][<class 'int'>]
[2019-06-30 12:41:48,942][Thread-10:15924][task_id:django.request][log.py:228][ERROR][Internal Server Error: /calSensorClusters/]
Traceback (most recent call last):
  File "C:\Softwares\Anaconda3\envs\django\lib\site-packages\django\core\handlers\exception.py", line 34, in inner
    response = get_response(request)
  File "C:\Softwares\Anaconda3\envs\django\lib\site-packages\django\core\handlers\base.py", line 115, in _get_response
    response = self.process_exception_by_middleware(e, request)
  File "C:\Softwares\Anaconda3\envs\django\lib\site-packages\django\core\handlers\base.py", line 113, in _get_response
    response = wrapped_callback(request, *callback_args, **callback_kwargs)
  File "D:\Workspace\Projects\vast-challenge-2019-MC2\RadiationVis\backend\views.py", line 89, in calSensorClusters
    params = json.loads(request.body)
  File "C:\Softwares\Anaconda3\envs\django\lib\json\__init__.py", line 354, in loads
    return _default_decoder.decode(s)
  File "C:\Softwares\Anaconda3\envs\django\lib\json\decoder.py", line 339, in decode
    obj, end = self.raw_decode(s, idx=_w(s, 0).end())
  File "C:\Softwares\Anaconda3\envs\django\lib\json\decoder.py", line 357, in raw_decode
    raise JSONDecodeError("Expecting value", s, err.value) from None
json.decoder.JSONDecodeError: Expecting value: line 1 column 1 (char 0)
[2019-06-30 12:43:09,028][Thread-6:11888][task_id:backend.views][views.py:60][INFO][<class 'int'>]
[2019-06-30 12:43:22,907][Thread-7:18048][task_id:backend.views][views.py:60][INFO][<class 'int'>]
[2019-06-30 12:44:09,399][Thread-8:7824][task_id:django.request][log.py:228][ERROR][Internal Server Error: /calSensorClusters/]
Traceback (most recent call last):
  File "C:\Softwares\Anaconda3\envs\django\lib\site-packages\django\core\handlers\exception.py", line 34, in inner
    response = get_response(request)
  File "C:\Softwares\Anaconda3\envs\django\lib\site-packages\django\core\handlers\base.py", line 115, in _get_response
    response = self.process_exception_by_middleware(e, request)
  File "C:\Softwares\Anaconda3\envs\django\lib\site-packages\django\core\handlers\base.py", line 113, in _get_response
    response = wrapped_callback(request, *callback_args, **callback_kwargs)
  File "D:\Workspace\Projects\vast-challenge-2019-MC2\RadiationVis\backend\views.py", line 89, in calSensorClusters
    params = json.loads(request.body)
  File "C:\Softwares\Anaconda3\envs\django\lib\json\__init__.py", line 354, in loads
    return _default_decoder.decode(s)
  File "C:\Softwares\Anaconda3\envs\django\lib\json\decoder.py", line 339, in decode
    obj, end = self.raw_decode(s, idx=_w(s, 0).end())
  File "C:\Softwares\Anaconda3\envs\django\lib\json\decoder.py", line 357, in raw_decode
    raise JSONDecodeError("Expecting value", s, err.value) from None
json.decoder.JSONDecodeError: Expecting value: line 1 column 1 (char 0)
[2019-06-30 12:45:43,492][Thread-8:7824][task_id:backend.views][views.py:60][INFO][<class 'int'>]
[2019-06-30 12:45:47,418][Thread-6:11888][task_id:backend.views][views.py:60][INFO][<class 'int'>]
[2019-06-30 12:45:49,303][Thread-7:18048][task_id:django.request][log.py:228][ERROR][Internal Server Error: /calSensorClusters/]
Traceback (most recent call last):
  File "C:\Softwares\Anaconda3\envs\django\lib\site-packages\django\core\handlers\exception.py", line 34, in inner
    response = get_response(request)
  File "C:\Softwares\Anaconda3\envs\django\lib\site-packages\django\core\handlers\base.py", line 115, in _get_response
    response = self.process_exception_by_middleware(e, request)
  File "C:\Softwares\Anaconda3\envs\django\lib\site-packages\django\core\handlers\base.py", line 113, in _get_response
    response = wrapped_callback(request, *callback_args, **callback_kwargs)
  File "D:\Workspace\Projects\vast-challenge-2019-MC2\RadiationVis\backend\views.py", line 90, in calSensorClusters
    data = calCluster(params['begintime'], params['endtime'])
  File "D:\Workspace\Projects\vast-challenge-2019-MC2\RadiationVis\backend\dataprocessing\cluster.py", line 233, in calCluster
    cluster = Cluster_DBSCAN(result)
  File "D:\Workspace\Projects\vast-challenge-2019-MC2\RadiationVis\backend\dataprocessing\cluster.py", line 129, in Cluster_DBSCAN
    cluster_res = DBSCAN(eps=0.05, min_samples=3).fit_predict(result)
  File "C:\Softwares\Anaconda3\envs\django\lib\site-packages\sklearn\cluster\dbscan_.py", line 383, in fit_predict
    self.fit(X, sample_weight=sample_weight)
  File "C:\Softwares\Anaconda3\envs\django\lib\site-packages\sklearn\cluster\dbscan_.py", line 349, in fit
    X = check_array(X, accept_sparse='csr')
  File "C:\Softwares\Anaconda3\envs\django\lib\site-packages\sklearn\utils\validation.py", line 542, in check_array
    allow_nan=force_all_finite == 'allow-nan')
  File "C:\Softwares\Anaconda3\envs\django\lib\site-packages\sklearn\utils\validation.py", line 56, in _assert_all_finite
    raise ValueError(msg_err.format(type_err, X.dtype))
ValueError: Input contains NaN, infinity or a value too large for dtype('float64').
[2019-06-30 12:45:52,078][Thread-8:7824][task_id:backend.views][views.py:60][INFO][<class 'int'>]
[2019-06-30 12:46:43,694][Thread-8:7824][task_id:backend.views][views.py:60][INFO][<class 'int'>]
[2019-06-30 12:46:46,845][Thread-9:5716][task_id:backend.views][views.py:60][INFO][<class 'int'>]
[2019-06-30 12:46:53,245][Thread-10:15924][task_id:backend.views][views.py:60][INFO][<class 'int'>]
[2019-06-30 12:47:07,179][Thread-9:5716][task_id:backend.views][views.py:60][INFO][<class 'int'>]
[2019-06-30 12:47:10,886][Thread-10:15924][task_id:backend.views][views.py:60][INFO][<class 'int'>]
[2019-06-30 12:47:16,192][Thread-9:5716][task_id:backend.views][views.py:60][INFO][<class 'int'>]
[2019-06-30 12:47:21,394][Thread-11:15564][task_id:backend.views][views.py:60][INFO][<class 'int'>]
[2019-06-30 12:47:26,552][Thread-7:18048][task_id:backend.views][views.py:60][INFO][<class 'int'>]
[2019-06-30 12:47:29,241][Thread-8:7824][task_id:backend.views][views.py:60][INFO][<class 'int'>]
[2019-06-30 12:47:34,670][Thread-9:5716][task_id:backend.views][views.py:60][INFO][<class 'int'>]
[2019-06-30 12:47:37,522][Thread-10:15924][task_id:backend.views][views.py:60][INFO][<class 'int'>]
[2019-06-30 12:47:42,830][Thread-7:18048][task_id:backend.views][views.py:60][INFO][<class 'int'>]
[2019-06-30 12:47:47,733][Thread-9:5716][task_id:backend.views][views.py:60][INFO][<class 'int'>]
[2019-06-30 12:47:52,699][Thread-7:18048][task_id:backend.views][views.py:60][INFO][<class 'int'>]
[2019-06-30 12:47:57,960][Thread-10:15924][task_id:backend.views][views.py:60][INFO][<class 'int'>]
[2019-06-30 12:48:03,174][Thread-11:15564][task_id:backend.views][views.py:60][INFO][<class 'int'>]
