[2019-06-09 16:47:05,397][Thread-1:15628][task_id:django.request][log.py:228][ERROR][Internal Server Error: /testdb/]
Traceback (most recent call last):
  File "C:\Softwares\Anaconda3\envs\django\lib\site-packages\django\core\handlers\exception.py", line 34, in inner
    response = get_response(request)
  File "C:\Softwares\Anaconda3\envs\django\lib\site-packages\django\core\handlers\base.py", line 115, in _get_response
    response = self.process_exception_by_middleware(e, request)
  File "C:\Softwares\Anaconda3\envs\django\lib\site-packages\django\core\handlers\base.py", line 113, in _get_response
    response = wrapped_callback(request, *callback_args, **callback_kwargs)
  File "D:\Workspace\Projects\vast-challenge-2019-MC2\RadiationVis\backend\views.py", line 12, in testdb
    logger.info(request.POST.get())
TypeError: get() missing 1 required positional argument: 'key'
[2019-06-09 16:47:38,339][Thread-1:6528][task_id:django.request][log.py:228][ERROR][Internal Server Error: /testdb/]
Traceback (most recent call last):
  File "C:\Softwares\Anaconda3\envs\django\lib\site-packages\django\core\handlers\exception.py", line 34, in inner
    response = get_response(request)
  File "C:\Softwares\Anaconda3\envs\django\lib\site-packages\django\core\handlers\base.py", line 115, in _get_response
    response = self.process_exception_by_middleware(e, request)
  File "C:\Softwares\Anaconda3\envs\django\lib\site-packages\django\core\handlers\base.py", line 113, in _get_response
    response = wrapped_callback(request, *callback_args, **callback_kwargs)
  File "D:\Workspace\Projects\vast-challenge-2019-MC2\RadiationVis\backend\views.py", line 12, in testdb
    logger.info(request.POST.get())
TypeError: get() missing 1 required positional argument: 'key'
[2019-06-09 17:00:14,306][Thread-1:12636][task_id:django.request][log.py:228][ERROR][Internal Server Error: /testdb/]
Traceback (most recent call last):
  File "C:\Softwares\Anaconda3\envs\django\lib\site-packages\django\core\handlers\exception.py", line 34, in inner
    response = get_response(request)
  File "C:\Softwares\Anaconda3\envs\django\lib\site-packages\django\core\handlers\base.py", line 115, in _get_response
    response = self.process_exception_by_middleware(e, request)
  File "C:\Softwares\Anaconda3\envs\django\lib\site-packages\django\core\handlers\base.py", line 113, in _get_response
    response = wrapped_callback(request, *callback_args, **callback_kwargs)
  File "D:\Workspace\Projects\vast-challenge-2019-MC2\RadiationVis\backend\views.py", line 12, in testdb
    logger.info(json.loads(request.body))
NameError: name 'json' is not defined
[2019-06-09 17:07:09,529][Thread-1:15652][task_id:django.request][log.py:228][ERROR][Internal Server Error: /findSensorReadingsBySid/]
Traceback (most recent call last):
  File "C:\Softwares\Anaconda3\envs\django\lib\site-packages\django\core\handlers\exception.py", line 34, in inner
    response = get_response(request)
  File "C:\Softwares\Anaconda3\envs\django\lib\site-packages\django\core\handlers\base.py", line 115, in _get_response
    response = self.process_exception_by_middleware(e, request)
  File "C:\Softwares\Anaconda3\envs\django\lib\site-packages\django\core\handlers\base.py", line 113, in _get_response
    response = wrapped_callback(request, *callback_args, **callback_kwargs)
  File "D:\Workspace\Projects\vast-challenge-2019-MC2\RadiationVis\backend\views.py", line 19, in findSensorReadingsBySid
    data = StaticSensorLocations.objects.filter(sid=sid)
NameError: name 'sid' is not defined
[2019-06-09 17:10:06,486][Thread-1:1540][task_id:django.request][log.py:228][ERROR][Internal Server Error: /findSensorReadingsBySid/]
Traceback (most recent call last):
  File "C:\Softwares\Anaconda3\envs\django\lib\site-packages\django\core\handlers\exception.py", line 34, in inner
    response = get_response(request)
  File "C:\Softwares\Anaconda3\envs\django\lib\site-packages\django\core\handlers\base.py", line 115, in _get_response
    response = self.process_exception_by_middleware(e, request)
  File "C:\Softwares\Anaconda3\envs\django\lib\site-packages\django\core\handlers\base.py", line 113, in _get_response
    response = wrapped_callback(request, *callback_args, **callback_kwargs)
  File "D:\Workspace\Projects\vast-challenge-2019-MC2\RadiationVis\backend\views.py", line 20, in findSensorReadingsBySid
    logger.info(len(dict(data)))
TypeError: cannot convert dictionary update sequence element #0 to a sequence
[2019-06-09 17:10:09,045][Thread-1:1540][task_id:django.request][log.py:228][ERROR][Internal Server Error: /findSensorReadingsBySid/]
Traceback (most recent call last):
  File "C:\Softwares\Anaconda3\envs\django\lib\site-packages\django\core\handlers\exception.py", line 34, in inner
    response = get_response(request)
  File "C:\Softwares\Anaconda3\envs\django\lib\site-packages\django\core\handlers\base.py", line 115, in _get_response
    response = self.process_exception_by_middleware(e, request)
  File "C:\Softwares\Anaconda3\envs\django\lib\site-packages\django\core\handlers\base.py", line 113, in _get_response
    response = wrapped_callback(request, *callback_args, **callback_kwargs)
  File "D:\Workspace\Projects\vast-challenge-2019-MC2\RadiationVis\backend\views.py", line 20, in findSensorReadingsBySid
    logger.info(len(dict(data)))
TypeError: cannot convert dictionary update sequence element #0 to a sequence
[2019-06-09 17:10:42,429][Thread-1:332][task_id:django.request][log.py:228][ERROR][Internal Server Error: /findSensorReadingsBySid/]
Traceback (most recent call last):
  File "C:\Softwares\Anaconda3\envs\django\lib\site-packages\django\core\handlers\exception.py", line 34, in inner
    response = get_response(request)
  File "C:\Softwares\Anaconda3\envs\django\lib\site-packages\django\core\handlers\base.py", line 115, in _get_response
    response = self.process_exception_by_middleware(e, request)
  File "C:\Softwares\Anaconda3\envs\django\lib\site-packages\django\core\handlers\base.py", line 113, in _get_response
    response = wrapped_callback(request, *callback_args, **callback_kwargs)
  File "D:\Workspace\Projects\vast-challenge-2019-MC2\RadiationVis\backend\views.py", line 20, in findSensorReadingsBySid
    logger.info((dict(data)))
TypeError: cannot convert dictionary update sequence element #0 to a sequence
[2019-06-09 17:17:56,875][Thread-1:16752][task_id:django.request][log.py:228][ERROR][Internal Server Error: /findSensorReadingsBySid/]
Traceback (most recent call last):
  File "C:\Softwares\Anaconda3\envs\django\lib\site-packages\django\db\backends\utils.py", line 84, in _execute
    return self.cursor.execute(sql, params)
  File "C:\Softwares\Anaconda3\envs\django\lib\site-packages\django\db\backends\mysql\base.py", line 71, in execute
    return self.cursor.execute(query, args)
  File "C:\Softwares\Anaconda3\envs\django\lib\site-packages\MySQLdb\cursors.py", line 255, in execute
    self.errorhandler(self, exc, value)
  File "C:\Softwares\Anaconda3\envs\django\lib\site-packages\MySQLdb\connections.py", line 50, in defaulterrorhandler
    raise errorvalue
  File "C:\Softwares\Anaconda3\envs\django\lib\site-packages\MySQLdb\cursors.py", line 252, in execute
    res = self._query(query)
  File "C:\Softwares\Anaconda3\envs\django\lib\site-packages\MySQLdb\cursors.py", line 378, in _query
    db.query(q)
  File "C:\Softwares\Anaconda3\envs\django\lib\site-packages\MySQLdb\connections.py", line 280, in query
    _mysql.connection.query(self, query)
_mysql_exceptions.OperationalError: (1054, "Unknown column 'staticsensorreadings.id' in 'field list'")

The above exception was the direct cause of the following exception:

Traceback (most recent call last):
  File "C:\Softwares\Anaconda3\envs\django\lib\site-packages\django\core\handlers\exception.py", line 34, in inner
    response = get_response(request)
  File "C:\Softwares\Anaconda3\envs\django\lib\site-packages\django\core\handlers\base.py", line 115, in _get_response
    response = self.process_exception_by_middleware(e, request)
  File "C:\Softwares\Anaconda3\envs\django\lib\site-packages\django\core\handlers\base.py", line 113, in _get_response
    response = wrapped_callback(request, *callback_args, **callback_kwargs)
  File "D:\Workspace\Projects\vast-challenge-2019-MC2\RadiationVis\backend\views.py", line 26, in findSensorReadingsBySid
    return HttpResponse(responseData)
  File "C:\Softwares\Anaconda3\envs\django\lib\site-packages\django\http\response.py", line 291, in __init__
    self.content = content
  File "C:\Softwares\Anaconda3\envs\django\lib\site-packages\django\http\response.py", line 314, in content
    content = b''.join(self.make_bytes(chunk) for chunk in value)
  File "C:\Softwares\Anaconda3\envs\django\lib\site-packages\django\db\models\query.py", line 274, in __iter__
    self._fetch_all()
  File "C:\Softwares\Anaconda3\envs\django\lib\site-packages\django\db\models\query.py", line 1242, in _fetch_all
    self._result_cache = list(self._iterable_class(self))
  File "C:\Softwares\Anaconda3\envs\django\lib\site-packages\django\db\models\query.py", line 55, in __iter__
    results = compiler.execute_sql(chunked_fetch=self.chunked_fetch, chunk_size=self.chunk_size)
  File "C:\Softwares\Anaconda3\envs\django\lib\site-packages\django\db\models\sql\compiler.py", line 1100, in execute_sql
    cursor.execute(sql, params)
  File "C:\Softwares\Anaconda3\envs\django\lib\site-packages\django\db\backends\utils.py", line 99, in execute
    return super().execute(sql, params)
  File "C:\Softwares\Anaconda3\envs\django\lib\site-packages\django\db\backends\utils.py", line 67, in execute
    return self._execute_with_wrappers(sql, params, many=False, executor=self._execute)
  File "C:\Softwares\Anaconda3\envs\django\lib\site-packages\django\db\backends\utils.py", line 76, in _execute_with_wrappers
    return executor(sql, params, many, context)
  File "C:\Softwares\Anaconda3\envs\django\lib\site-packages\django\db\backends\utils.py", line 84, in _execute
    return self.cursor.execute(sql, params)
  File "C:\Softwares\Anaconda3\envs\django\lib\site-packages\django\db\utils.py", line 89, in __exit__
    raise dj_exc_value.with_traceback(traceback) from exc_value
  File "C:\Softwares\Anaconda3\envs\django\lib\site-packages\django\db\backends\utils.py", line 84, in _execute
    return self.cursor.execute(sql, params)
  File "C:\Softwares\Anaconda3\envs\django\lib\site-packages\django\db\backends\mysql\base.py", line 71, in execute
    return self.cursor.execute(query, args)
  File "C:\Softwares\Anaconda3\envs\django\lib\site-packages\MySQLdb\cursors.py", line 255, in execute
    self.errorhandler(self, exc, value)
  File "C:\Softwares\Anaconda3\envs\django\lib\site-packages\MySQLdb\connections.py", line 50, in defaulterrorhandler
    raise errorvalue
  File "C:\Softwares\Anaconda3\envs\django\lib\site-packages\MySQLdb\cursors.py", line 252, in execute
    res = self._query(query)
  File "C:\Softwares\Anaconda3\envs\django\lib\site-packages\MySQLdb\cursors.py", line 378, in _query
    db.query(q)
  File "C:\Softwares\Anaconda3\envs\django\lib\site-packages\MySQLdb\connections.py", line 280, in query
    _mysql.connection.query(self, query)
django.db.utils.OperationalError: (1054, "Unknown column 'staticsensorreadings.id' in 'field list'")
[2019-06-09 17:19:06,897][Thread-1:12116][task_id:django.request][log.py:228][ERROR][Internal Server Error: /findSensorReadingsBySid/]
Traceback (most recent call last):
  File "C:\Softwares\Anaconda3\envs\django\lib\site-packages\django\db\backends\utils.py", line 84, in _execute
    return self.cursor.execute(sql, params)
  File "C:\Softwares\Anaconda3\envs\django\lib\site-packages\django\db\backends\mysql\base.py", line 71, in execute
    return self.cursor.execute(query, args)
  File "C:\Softwares\Anaconda3\envs\django\lib\site-packages\MySQLdb\cursors.py", line 255, in execute
    self.errorhandler(self, exc, value)
  File "C:\Softwares\Anaconda3\envs\django\lib\site-packages\MySQLdb\connections.py", line 50, in defaulterrorhandler
    raise errorvalue
  File "C:\Softwares\Anaconda3\envs\django\lib\site-packages\MySQLdb\cursors.py", line 252, in execute
    res = self._query(query)
  File "C:\Softwares\Anaconda3\envs\django\lib\site-packages\MySQLdb\cursors.py", line 378, in _query
    db.query(q)
  File "C:\Softwares\Anaconda3\envs\django\lib\site-packages\MySQLdb\connections.py", line 280, in query
    _mysql.connection.query(self, query)
_mysql_exceptions.OperationalError: (1054, "Unknown column 'staticsensorreadings.id' in 'field list'")

The above exception was the direct cause of the following exception:

Traceback (most recent call last):
  File "C:\Softwares\Anaconda3\envs\django\lib\site-packages\django\core\handlers\exception.py", line 34, in inner
    response = get_response(request)
  File "C:\Softwares\Anaconda3\envs\django\lib\site-packages\django\core\handlers\base.py", line 115, in _get_response
    response = self.process_exception_by_middleware(e, request)
  File "C:\Softwares\Anaconda3\envs\django\lib\site-packages\django\core\handlers\base.py", line 113, in _get_response
    response = wrapped_callback(request, *callback_args, **callback_kwargs)
  File "D:\Workspace\Projects\vast-challenge-2019-MC2\RadiationVis\backend\views.py", line 27, in findSensorReadingsBySid
    return HttpResponse(responseData)
  File "C:\Softwares\Anaconda3\envs\django\lib\site-packages\django\http\response.py", line 291, in __init__
    self.content = content
  File "C:\Softwares\Anaconda3\envs\django\lib\site-packages\django\http\response.py", line 314, in content
    content = b''.join(self.make_bytes(chunk) for chunk in value)
  File "C:\Softwares\Anaconda3\envs\django\lib\site-packages\django\db\models\query.py", line 274, in __iter__
    self._fetch_all()
  File "C:\Softwares\Anaconda3\envs\django\lib\site-packages\django\db\models\query.py", line 1242, in _fetch_all
    self._result_cache = list(self._iterable_class(self))
  File "C:\Softwares\Anaconda3\envs\django\lib\site-packages\django\db\models\query.py", line 55, in __iter__
    results = compiler.execute_sql(chunked_fetch=self.chunked_fetch, chunk_size=self.chunk_size)
  File "C:\Softwares\Anaconda3\envs\django\lib\site-packages\django\db\models\sql\compiler.py", line 1100, in execute_sql
    cursor.execute(sql, params)
  File "C:\Softwares\Anaconda3\envs\django\lib\site-packages\django\db\backends\utils.py", line 99, in execute
    return super().execute(sql, params)
  File "C:\Softwares\Anaconda3\envs\django\lib\site-packages\django\db\backends\utils.py", line 67, in execute
    return self._execute_with_wrappers(sql, params, many=False, executor=self._execute)
  File "C:\Softwares\Anaconda3\envs\django\lib\site-packages\django\db\backends\utils.py", line 76, in _execute_with_wrappers
    return executor(sql, params, many, context)
  File "C:\Softwares\Anaconda3\envs\django\lib\site-packages\django\db\backends\utils.py", line 84, in _execute
    return self.cursor.execute(sql, params)
  File "C:\Softwares\Anaconda3\envs\django\lib\site-packages\django\db\utils.py", line 89, in __exit__
    raise dj_exc_value.with_traceback(traceback) from exc_value
  File "C:\Softwares\Anaconda3\envs\django\lib\site-packages\django\db\backends\utils.py", line 84, in _execute
    return self.cursor.execute(sql, params)
  File "C:\Softwares\Anaconda3\envs\django\lib\site-packages\django\db\backends\mysql\base.py", line 71, in execute
    return self.cursor.execute(query, args)
  File "C:\Softwares\Anaconda3\envs\django\lib\site-packages\MySQLdb\cursors.py", line 255, in execute
    self.errorhandler(self, exc, value)
  File "C:\Softwares\Anaconda3\envs\django\lib\site-packages\MySQLdb\connections.py", line 50, in defaulterrorhandler
    raise errorvalue
  File "C:\Softwares\Anaconda3\envs\django\lib\site-packages\MySQLdb\cursors.py", line 252, in execute
    res = self._query(query)
  File "C:\Softwares\Anaconda3\envs\django\lib\site-packages\MySQLdb\cursors.py", line 378, in _query
    db.query(q)
  File "C:\Softwares\Anaconda3\envs\django\lib\site-packages\MySQLdb\connections.py", line 280, in query
    _mysql.connection.query(self, query)
django.db.utils.OperationalError: (1054, "Unknown column 'staticsensorreadings.id' in 'field list'")
[2019-06-09 17:19:25,742][Thread-2:5552][task_id:django.request][log.py:228][ERROR][Internal Server Error: /testdb/]
Traceback (most recent call last):
  File "C:\Softwares\Anaconda3\envs\django\lib\site-packages\django\core\handlers\exception.py", line 34, in inner
    response = get_response(request)
  File "C:\Softwares\Anaconda3\envs\django\lib\site-packages\django\core\handlers\base.py", line 115, in _get_response
    response = self.process_exception_by_middleware(e, request)
  File "C:\Softwares\Anaconda3\envs\django\lib\site-packages\django\core\handlers\base.py", line 113, in _get_response
    response = wrapped_callback(request, *callback_args, **callback_kwargs)
  File "D:\Workspace\Projects\vast-challenge-2019-MC2\RadiationVis\backend\views.py", line 10, in testdb
    logger.info(json.loads(request.body))
  File "C:\Softwares\Anaconda3\envs\django\lib\json\__init__.py", line 354, in loads
    return _default_decoder.decode(s)
  File "C:\Softwares\Anaconda3\envs\django\lib\json\decoder.py", line 339, in decode
    obj, end = self.raw_decode(s, idx=_w(s, 0).end())
  File "C:\Softwares\Anaconda3\envs\django\lib\json\decoder.py", line 357, in raw_decode
    raise JSONDecodeError("Expecting value", s, err.value) from None
json.decoder.JSONDecodeError: Expecting value: line 1 column 1 (char 0)
[2019-06-09 17:20:37,336][Thread-1:3012][task_id:django.request][log.py:228][ERROR][Internal Server Error: /testdb/]
Traceback (most recent call last):
  File "C:\Softwares\Anaconda3\envs\django\lib\site-packages\django\core\handlers\exception.py", line 34, in inner
    response = get_response(request)
  File "C:\Softwares\Anaconda3\envs\django\lib\site-packages\django\core\handlers\base.py", line 115, in _get_response
    response = self.process_exception_by_middleware(e, request)
  File "C:\Softwares\Anaconda3\envs\django\lib\site-packages\django\core\handlers\base.py", line 113, in _get_response
    response = wrapped_callback(request, *callback_args, **callback_kwargs)
  File "D:\Workspace\Projects\vast-challenge-2019-MC2\RadiationVis\backend\views.py", line 10, in testdb
    logger.info(json.loads(request.body))
  File "C:\Softwares\Anaconda3\envs\django\lib\json\__init__.py", line 354, in loads
    return _default_decoder.decode(s)
  File "C:\Softwares\Anaconda3\envs\django\lib\json\decoder.py", line 339, in decode
    obj, end = self.raw_decode(s, idx=_w(s, 0).end())
  File "C:\Softwares\Anaconda3\envs\django\lib\json\decoder.py", line 357, in raw_decode
    raise JSONDecodeError("Expecting value", s, err.value) from None
json.decoder.JSONDecodeError: Expecting value: line 1 column 1 (char 0)
[2019-06-09 17:21:39,186][Thread-1:13308][task_id:django.request][log.py:228][ERROR][Internal Server Error: /testdb/]
Traceback (most recent call last):
  File "C:\Softwares\Anaconda3\envs\django\lib\site-packages\django\core\handlers\exception.py", line 34, in inner
    response = get_response(request)
  File "C:\Softwares\Anaconda3\envs\django\lib\site-packages\django\core\handlers\base.py", line 115, in _get_response
    response = self.process_exception_by_middleware(e, request)
  File "C:\Softwares\Anaconda3\envs\django\lib\site-packages\django\core\handlers\base.py", line 113, in _get_response
    response = wrapped_callback(request, *callback_args, **callback_kwargs)
  File "D:\Workspace\Projects\vast-challenge-2019-MC2\RadiationVis\backend\views.py", line 10, in testdb
    logger.info(json.loads(request.body))
  File "C:\Softwares\Anaconda3\envs\django\lib\json\__init__.py", line 354, in loads
    return _default_decoder.decode(s)
  File "C:\Softwares\Anaconda3\envs\django\lib\json\decoder.py", line 339, in decode
    obj, end = self.raw_decode(s, idx=_w(s, 0).end())
  File "C:\Softwares\Anaconda3\envs\django\lib\json\decoder.py", line 357, in raw_decode
    raise JSONDecodeError("Expecting value", s, err.value) from None
json.decoder.JSONDecodeError: Expecting value: line 1 column 1 (char 0)
[2019-06-09 17:22:04,390][Thread-1:13660][task_id:django.request][log.py:228][ERROR][Internal Server Error: /testdb/]
Traceback (most recent call last):
  File "C:\Softwares\Anaconda3\envs\django\lib\site-packages\django\core\handlers\exception.py", line 34, in inner
    response = get_response(request)
  File "C:\Softwares\Anaconda3\envs\django\lib\site-packages\django\core\handlers\base.py", line 115, in _get_response
    response = self.process_exception_by_middleware(e, request)
  File "C:\Softwares\Anaconda3\envs\django\lib\site-packages\django\core\handlers\base.py", line 113, in _get_response
    response = wrapped_callback(request, *callback_args, **callback_kwargs)
  File "D:\Workspace\Projects\vast-challenge-2019-MC2\RadiationVis\backend\views.py", line 10, in testdb
    logger.info(json.loads(request.body))
  File "C:\Softwares\Anaconda3\envs\django\lib\json\__init__.py", line 354, in loads
    return _default_decoder.decode(s)
  File "C:\Softwares\Anaconda3\envs\django\lib\json\decoder.py", line 339, in decode
    obj, end = self.raw_decode(s, idx=_w(s, 0).end())
  File "C:\Softwares\Anaconda3\envs\django\lib\json\decoder.py", line 357, in raw_decode
    raise JSONDecodeError("Expecting value", s, err.value) from None
json.decoder.JSONDecodeError: Expecting value: line 1 column 1 (char 0)
[2019-06-09 17:22:07,548][Thread-1:13660][task_id:django.request][log.py:228][ERROR][Internal Server Error: /testdb/]
Traceback (most recent call last):
  File "C:\Softwares\Anaconda3\envs\django\lib\site-packages\django\core\handlers\exception.py", line 34, in inner
    response = get_response(request)
  File "C:\Softwares\Anaconda3\envs\django\lib\site-packages\django\core\handlers\base.py", line 115, in _get_response
    response = self.process_exception_by_middleware(e, request)
  File "C:\Softwares\Anaconda3\envs\django\lib\site-packages\django\core\handlers\base.py", line 113, in _get_response
    response = wrapped_callback(request, *callback_args, **callback_kwargs)
  File "D:\Workspace\Projects\vast-challenge-2019-MC2\RadiationVis\backend\views.py", line 10, in testdb
    logger.info(json.loads(request.body))
  File "C:\Softwares\Anaconda3\envs\django\lib\json\__init__.py", line 354, in loads
    return _default_decoder.decode(s)
  File "C:\Softwares\Anaconda3\envs\django\lib\json\decoder.py", line 339, in decode
    obj, end = self.raw_decode(s, idx=_w(s, 0).end())
  File "C:\Softwares\Anaconda3\envs\django\lib\json\decoder.py", line 357, in raw_decode
    raise JSONDecodeError("Expecting value", s, err.value) from None
json.decoder.JSONDecodeError: Expecting value: line 1 column 1 (char 0)
[2019-06-09 17:24:27,439][Thread-2:21280][task_id:django.request][log.py:228][ERROR][Internal Server Error: /findSensorReadingsBySid/]
Traceback (most recent call last):
  File "C:\Softwares\Anaconda3\envs\django\lib\site-packages\django\db\backends\utils.py", line 84, in _execute
    return self.cursor.execute(sql, params)
  File "C:\Softwares\Anaconda3\envs\django\lib\site-packages\django\db\backends\mysql\base.py", line 71, in execute
    return self.cursor.execute(query, args)
  File "C:\Softwares\Anaconda3\envs\django\lib\site-packages\MySQLdb\cursors.py", line 255, in execute
    self.errorhandler(self, exc, value)
  File "C:\Softwares\Anaconda3\envs\django\lib\site-packages\MySQLdb\connections.py", line 50, in defaulterrorhandler
    raise errorvalue
  File "C:\Softwares\Anaconda3\envs\django\lib\site-packages\MySQLdb\cursors.py", line 252, in execute
    res = self._query(query)
  File "C:\Softwares\Anaconda3\envs\django\lib\site-packages\MySQLdb\cursors.py", line 378, in _query
    db.query(q)
  File "C:\Softwares\Anaconda3\envs\django\lib\site-packages\MySQLdb\connections.py", line 280, in query
    _mysql.connection.query(self, query)
_mysql_exceptions.OperationalError: (1054, "Unknown column 'staticsensorreadings.id' in 'field list'")

The above exception was the direct cause of the following exception:

Traceback (most recent call last):
  File "C:\Softwares\Anaconda3\envs\django\lib\site-packages\django\core\handlers\exception.py", line 34, in inner
    response = get_response(request)
  File "C:\Softwares\Anaconda3\envs\django\lib\site-packages\django\core\handlers\base.py", line 115, in _get_response
    response = self.process_exception_by_middleware(e, request)
  File "C:\Softwares\Anaconda3\envs\django\lib\site-packages\django\core\handlers\base.py", line 113, in _get_response
    response = wrapped_callback(request, *callback_args, **callback_kwargs)
  File "D:\Workspace\Projects\vast-challenge-2019-MC2\RadiationVis\backend\views.py", line 29, in findSensorReadingsBySid
    return HttpResponse(responseData)
  File "C:\Softwares\Anaconda3\envs\django\lib\site-packages\django\http\response.py", line 291, in __init__
    self.content = content
  File "C:\Softwares\Anaconda3\envs\django\lib\site-packages\django\http\response.py", line 314, in content
    content = b''.join(self.make_bytes(chunk) for chunk in value)
  File "C:\Softwares\Anaconda3\envs\django\lib\site-packages\django\db\models\query.py", line 274, in __iter__
    self._fetch_all()
  File "C:\Softwares\Anaconda3\envs\django\lib\site-packages\django\db\models\query.py", line 1242, in _fetch_all
    self._result_cache = list(self._iterable_class(self))
  File "C:\Softwares\Anaconda3\envs\django\lib\site-packages\django\db\models\query.py", line 55, in __iter__
    results = compiler.execute_sql(chunked_fetch=self.chunked_fetch, chunk_size=self.chunk_size)
  File "C:\Softwares\Anaconda3\envs\django\lib\site-packages\django\db\models\sql\compiler.py", line 1100, in execute_sql
    cursor.execute(sql, params)
  File "C:\Softwares\Anaconda3\envs\django\lib\site-packages\django\db\backends\utils.py", line 99, in execute
    return super().execute(sql, params)
  File "C:\Softwares\Anaconda3\envs\django\lib\site-packages\django\db\backends\utils.py", line 67, in execute
    return self._execute_with_wrappers(sql, params, many=False, executor=self._execute)
  File "C:\Softwares\Anaconda3\envs\django\lib\site-packages\django\db\backends\utils.py", line 76, in _execute_with_wrappers
    return executor(sql, params, many, context)
  File "C:\Softwares\Anaconda3\envs\django\lib\site-packages\django\db\backends\utils.py", line 84, in _execute
    return self.cursor.execute(sql, params)
  File "C:\Softwares\Anaconda3\envs\django\lib\site-packages\django\db\utils.py", line 89, in __exit__
    raise dj_exc_value.with_traceback(traceback) from exc_value
  File "C:\Softwares\Anaconda3\envs\django\lib\site-packages\django\db\backends\utils.py", line 84, in _execute
    return self.cursor.execute(sql, params)
  File "C:\Softwares\Anaconda3\envs\django\lib\site-packages\django\db\backends\mysql\base.py", line 71, in execute
    return self.cursor.execute(query, args)
  File "C:\Softwares\Anaconda3\envs\django\lib\site-packages\MySQLdb\cursors.py", line 255, in execute
    self.errorhandler(self, exc, value)
  File "C:\Softwares\Anaconda3\envs\django\lib\site-packages\MySQLdb\connections.py", line 50, in defaulterrorhandler
    raise errorvalue
  File "C:\Softwares\Anaconda3\envs\django\lib\site-packages\MySQLdb\cursors.py", line 252, in execute
    res = self._query(query)
  File "C:\Softwares\Anaconda3\envs\django\lib\site-packages\MySQLdb\cursors.py", line 378, in _query
    db.query(q)
  File "C:\Softwares\Anaconda3\envs\django\lib\site-packages\MySQLdb\connections.py", line 280, in query
    _mysql.connection.query(self, query)
django.db.utils.OperationalError: (1054, "Unknown column 'staticsensorreadings.id' in 'field list'")
[2019-06-09 17:24:39,717][Thread-3:20872][task_id:django.request][log.py:228][ERROR][Internal Server Error: /testdb/]
Traceback (most recent call last):
  File "C:\Softwares\Anaconda3\envs\django\lib\site-packages\django\core\handlers\exception.py", line 34, in inner
    response = get_response(request)
  File "C:\Softwares\Anaconda3\envs\django\lib\site-packages\django\core\handlers\base.py", line 115, in _get_response
    response = self.process_exception_by_middleware(e, request)
  File "C:\Softwares\Anaconda3\envs\django\lib\site-packages\django\core\handlers\base.py", line 113, in _get_response
    response = wrapped_callback(request, *callback_args, **callback_kwargs)
  File "D:\Workspace\Projects\vast-challenge-2019-MC2\RadiationVis\backend\views.py", line 10, in testdb
    logger.info(json.loads(request.body))
  File "C:\Softwares\Anaconda3\envs\django\lib\json\__init__.py", line 354, in loads
    return _default_decoder.decode(s)
  File "C:\Softwares\Anaconda3\envs\django\lib\json\decoder.py", line 339, in decode
    obj, end = self.raw_decode(s, idx=_w(s, 0).end())
  File "C:\Softwares\Anaconda3\envs\django\lib\json\decoder.py", line 357, in raw_decode
    raise JSONDecodeError("Expecting value", s, err.value) from None
json.decoder.JSONDecodeError: Expecting value: line 1 column 1 (char 0)
[2019-06-09 17:24:42,946][Thread-3:20872][task_id:django.request][log.py:228][ERROR][Internal Server Error: /testdb/]
Traceback (most recent call last):
  File "C:\Softwares\Anaconda3\envs\django\lib\site-packages\django\core\handlers\exception.py", line 34, in inner
    response = get_response(request)
  File "C:\Softwares\Anaconda3\envs\django\lib\site-packages\django\core\handlers\base.py", line 115, in _get_response
    response = self.process_exception_by_middleware(e, request)
  File "C:\Softwares\Anaconda3\envs\django\lib\site-packages\django\core\handlers\base.py", line 113, in _get_response
    response = wrapped_callback(request, *callback_args, **callback_kwargs)
  File "D:\Workspace\Projects\vast-challenge-2019-MC2\RadiationVis\backend\views.py", line 10, in testdb
    logger.info(json.loads(request.body))
  File "C:\Softwares\Anaconda3\envs\django\lib\json\__init__.py", line 354, in loads
    return _default_decoder.decode(s)
  File "C:\Softwares\Anaconda3\envs\django\lib\json\decoder.py", line 339, in decode
    obj, end = self.raw_decode(s, idx=_w(s, 0).end())
  File "C:\Softwares\Anaconda3\envs\django\lib\json\decoder.py", line 357, in raw_decode
    raise JSONDecodeError("Expecting value", s, err.value) from None
json.decoder.JSONDecodeError: Expecting value: line 1 column 1 (char 0)
[2019-06-09 17:25:28,445][Thread-1:13620][task_id:django.request][log.py:228][ERROR][Internal Server Error: /testdb/]
Traceback (most recent call last):
  File "C:\Softwares\Anaconda3\envs\django\lib\site-packages\django\core\handlers\exception.py", line 34, in inner
    response = get_response(request)
  File "C:\Softwares\Anaconda3\envs\django\lib\site-packages\django\core\handlers\base.py", line 115, in _get_response
    response = self.process_exception_by_middleware(e, request)
  File "C:\Softwares\Anaconda3\envs\django\lib\site-packages\django\core\handlers\base.py", line 113, in _get_response
    response = wrapped_callback(request, *callback_args, **callback_kwargs)
  File "D:\Workspace\Projects\vast-challenge-2019-MC2\RadiationVis\backend\views.py", line 10, in testdb
    logger.info(json.loads(request.body))
  File "C:\Softwares\Anaconda3\envs\django\lib\json\__init__.py", line 354, in loads
    return _default_decoder.decode(s)
  File "C:\Softwares\Anaconda3\envs\django\lib\json\decoder.py", line 339, in decode
    obj, end = self.raw_decode(s, idx=_w(s, 0).end())
  File "C:\Softwares\Anaconda3\envs\django\lib\json\decoder.py", line 357, in raw_decode
    raise JSONDecodeError("Expecting value", s, err.value) from None
json.decoder.JSONDecodeError: Expecting value: line 1 column 1 (char 0)
[2019-06-09 17:28:27,971][Thread-1:20948][task_id:django.request][log.py:228][ERROR][Internal Server Error: /testdb/]
Traceback (most recent call last):
  File "C:\Softwares\Anaconda3\envs\django\lib\site-packages\django\core\handlers\exception.py", line 34, in inner
    response = get_response(request)
  File "C:\Softwares\Anaconda3\envs\django\lib\site-packages\django\core\handlers\base.py", line 115, in _get_response
    response = self.process_exception_by_middleware(e, request)
  File "C:\Softwares\Anaconda3\envs\django\lib\site-packages\django\core\handlers\base.py", line 113, in _get_response
    response = wrapped_callback(request, *callback_args, **callback_kwargs)
  File "D:\Workspace\Projects\vast-challenge-2019-MC2\RadiationVis\backend\views.py", line 10, in testdb
    logger.info(json.loads(request.body))
  File "C:\Softwares\Anaconda3\envs\django\lib\json\__init__.py", line 354, in loads
    return _default_decoder.decode(s)
  File "C:\Softwares\Anaconda3\envs\django\lib\json\decoder.py", line 339, in decode
    obj, end = self.raw_decode(s, idx=_w(s, 0).end())
  File "C:\Softwares\Anaconda3\envs\django\lib\json\decoder.py", line 357, in raw_decode
    raise JSONDecodeError("Expecting value", s, err.value) from None
json.decoder.JSONDecodeError: Expecting value: line 1 column 1 (char 0)
[2019-06-09 17:28:40,900][Thread-1:21128][task_id:django.request][log.py:228][ERROR][Internal Server Error: /testdb/]
Traceback (most recent call last):
  File "C:\Softwares\Anaconda3\envs\django\lib\site-packages\django\core\handlers\exception.py", line 34, in inner
    response = get_response(request)
  File "C:\Softwares\Anaconda3\envs\django\lib\site-packages\django\core\handlers\base.py", line 115, in _get_response
    response = self.process_exception_by_middleware(e, request)
  File "C:\Softwares\Anaconda3\envs\django\lib\site-packages\django\core\handlers\base.py", line 113, in _get_response
    response = wrapped_callback(request, *callback_args, **callback_kwargs)
  File "D:\Workspace\Projects\vast-challenge-2019-MC2\RadiationVis\backend\views.py", line 10, in testdb
    logger.info(json.loads(request.body))
  File "C:\Softwares\Anaconda3\envs\django\lib\json\__init__.py", line 354, in loads
    return _default_decoder.decode(s)
  File "C:\Softwares\Anaconda3\envs\django\lib\json\decoder.py", line 339, in decode
    obj, end = self.raw_decode(s, idx=_w(s, 0).end())
  File "C:\Softwares\Anaconda3\envs\django\lib\json\decoder.py", line 357, in raw_decode
    raise JSONDecodeError("Expecting value", s, err.value) from None
json.decoder.JSONDecodeError: Expecting value: line 1 column 1 (char 0)
[2019-06-09 17:28:42,937][Thread-1:21128][task_id:django.request][log.py:228][ERROR][Internal Server Error: /testdb/]
Traceback (most recent call last):
  File "C:\Softwares\Anaconda3\envs\django\lib\site-packages\django\core\handlers\exception.py", line 34, in inner
    response = get_response(request)
  File "C:\Softwares\Anaconda3\envs\django\lib\site-packages\django\core\handlers\base.py", line 115, in _get_response
    response = self.process_exception_by_middleware(e, request)
  File "C:\Softwares\Anaconda3\envs\django\lib\site-packages\django\core\handlers\base.py", line 113, in _get_response
    response = wrapped_callback(request, *callback_args, **callback_kwargs)
  File "D:\Workspace\Projects\vast-challenge-2019-MC2\RadiationVis\backend\views.py", line 10, in testdb
    logger.info(json.loads(request.body))
  File "C:\Softwares\Anaconda3\envs\django\lib\json\__init__.py", line 354, in loads
    return _default_decoder.decode(s)
  File "C:\Softwares\Anaconda3\envs\django\lib\json\decoder.py", line 339, in decode
    obj, end = self.raw_decode(s, idx=_w(s, 0).end())
  File "C:\Softwares\Anaconda3\envs\django\lib\json\decoder.py", line 357, in raw_decode
    raise JSONDecodeError("Expecting value", s, err.value) from None
json.decoder.JSONDecodeError: Expecting value: line 1 column 1 (char 0)
[2019-06-09 17:28:43,525][Thread-1:21128][task_id:django.request][log.py:228][ERROR][Internal Server Error: /testdb/]
Traceback (most recent call last):
  File "C:\Softwares\Anaconda3\envs\django\lib\site-packages\django\core\handlers\exception.py", line 34, in inner
    response = get_response(request)
  File "C:\Softwares\Anaconda3\envs\django\lib\site-packages\django\core\handlers\base.py", line 115, in _get_response
    response = self.process_exception_by_middleware(e, request)
  File "C:\Softwares\Anaconda3\envs\django\lib\site-packages\django\core\handlers\base.py", line 113, in _get_response
    response = wrapped_callback(request, *callback_args, **callback_kwargs)
  File "D:\Workspace\Projects\vast-challenge-2019-MC2\RadiationVis\backend\views.py", line 10, in testdb
    logger.info(json.loads(request.body))
  File "C:\Softwares\Anaconda3\envs\django\lib\json\__init__.py", line 354, in loads
    return _default_decoder.decode(s)
  File "C:\Softwares\Anaconda3\envs\django\lib\json\decoder.py", line 339, in decode
    obj, end = self.raw_decode(s, idx=_w(s, 0).end())
  File "C:\Softwares\Anaconda3\envs\django\lib\json\decoder.py", line 357, in raw_decode
    raise JSONDecodeError("Expecting value", s, err.value) from None
json.decoder.JSONDecodeError: Expecting value: line 1 column 1 (char 0)
[2019-06-09 17:29:00,251][Thread-1:21128][task_id:django.request][log.py:228][ERROR][Internal Server Error: /testdb/]
Traceback (most recent call last):
  File "C:\Softwares\Anaconda3\envs\django\lib\site-packages\django\core\handlers\exception.py", line 34, in inner
    response = get_response(request)
  File "C:\Softwares\Anaconda3\envs\django\lib\site-packages\django\core\handlers\base.py", line 115, in _get_response
    response = self.process_exception_by_middleware(e, request)
  File "C:\Softwares\Anaconda3\envs\django\lib\site-packages\django\core\handlers\base.py", line 113, in _get_response
    response = wrapped_callback(request, *callback_args, **callback_kwargs)
  File "D:\Workspace\Projects\vast-challenge-2019-MC2\RadiationVis\backend\views.py", line 10, in testdb
    logger.info(json.loads(request.body))
  File "C:\Softwares\Anaconda3\envs\django\lib\json\__init__.py", line 354, in loads
    return _default_decoder.decode(s)
  File "C:\Softwares\Anaconda3\envs\django\lib\json\decoder.py", line 339, in decode
    obj, end = self.raw_decode(s, idx=_w(s, 0).end())
  File "C:\Softwares\Anaconda3\envs\django\lib\json\decoder.py", line 357, in raw_decode
    raise JSONDecodeError("Expecting value", s, err.value) from None
json.decoder.JSONDecodeError: Expecting value: line 1 column 1 (char 0)
[2019-06-09 17:29:01,137][Thread-1:21128][task_id:django.request][log.py:228][ERROR][Internal Server Error: /testdb/]
Traceback (most recent call last):
  File "C:\Softwares\Anaconda3\envs\django\lib\site-packages\django\core\handlers\exception.py", line 34, in inner
    response = get_response(request)
  File "C:\Softwares\Anaconda3\envs\django\lib\site-packages\django\core\handlers\base.py", line 115, in _get_response
    response = self.process_exception_by_middleware(e, request)
  File "C:\Softwares\Anaconda3\envs\django\lib\site-packages\django\core\handlers\base.py", line 113, in _get_response
    response = wrapped_callback(request, *callback_args, **callback_kwargs)
  File "D:\Workspace\Projects\vast-challenge-2019-MC2\RadiationVis\backend\views.py", line 10, in testdb
    logger.info(json.loads(request.body))
  File "C:\Softwares\Anaconda3\envs\django\lib\json\__init__.py", line 354, in loads
    return _default_decoder.decode(s)
  File "C:\Softwares\Anaconda3\envs\django\lib\json\decoder.py", line 339, in decode
    obj, end = self.raw_decode(s, idx=_w(s, 0).end())
  File "C:\Softwares\Anaconda3\envs\django\lib\json\decoder.py", line 357, in raw_decode
    raise JSONDecodeError("Expecting value", s, err.value) from None
json.decoder.JSONDecodeError: Expecting value: line 1 column 1 (char 0)
[2019-06-09 17:29:37,553][Thread-1:20692][task_id:django.request][log.py:228][ERROR][Internal Server Error: /testdb/]
Traceback (most recent call last):
  File "C:\Softwares\Anaconda3\envs\django\lib\site-packages\django\core\handlers\exception.py", line 34, in inner
    response = get_response(request)
  File "C:\Softwares\Anaconda3\envs\django\lib\site-packages\django\core\handlers\base.py", line 115, in _get_response
    response = self.process_exception_by_middleware(e, request)
  File "C:\Softwares\Anaconda3\envs\django\lib\site-packages\django\core\handlers\base.py", line 113, in _get_response
    response = wrapped_callback(request, *callback_args, **callback_kwargs)
  File "D:\Workspace\Projects\vast-challenge-2019-MC2\RadiationVis\backend\views.py", line 10, in testdb
    logger.info(json.loads(request.body))
  File "C:\Softwares\Anaconda3\envs\django\lib\json\__init__.py", line 354, in loads
    return _default_decoder.decode(s)
  File "C:\Softwares\Anaconda3\envs\django\lib\json\decoder.py", line 339, in decode
    obj, end = self.raw_decode(s, idx=_w(s, 0).end())
  File "C:\Softwares\Anaconda3\envs\django\lib\json\decoder.py", line 357, in raw_decode
    raise JSONDecodeError("Expecting value", s, err.value) from None
json.decoder.JSONDecodeError: Expecting value: line 1 column 1 (char 0)
[2019-06-09 17:29:58,527][Thread-1:20692][task_id:django.request][log.py:228][ERROR][Internal Server Error: /testdb/]
Traceback (most recent call last):
  File "C:\Softwares\Anaconda3\envs\django\lib\site-packages\django\core\handlers\exception.py", line 34, in inner
    response = get_response(request)
  File "C:\Softwares\Anaconda3\envs\django\lib\site-packages\django\core\handlers\base.py", line 115, in _get_response
    response = self.process_exception_by_middleware(e, request)
  File "C:\Softwares\Anaconda3\envs\django\lib\site-packages\django\core\handlers\base.py", line 113, in _get_response
    response = wrapped_callback(request, *callback_args, **callback_kwargs)
  File "D:\Workspace\Projects\vast-challenge-2019-MC2\RadiationVis\backend\views.py", line 10, in testdb
    logger.info(json.loads(request.body))
  File "C:\Softwares\Anaconda3\envs\django\lib\json\__init__.py", line 354, in loads
    return _default_decoder.decode(s)
  File "C:\Softwares\Anaconda3\envs\django\lib\json\decoder.py", line 339, in decode
    obj, end = self.raw_decode(s, idx=_w(s, 0).end())
  File "C:\Softwares\Anaconda3\envs\django\lib\json\decoder.py", line 357, in raw_decode
    raise JSONDecodeError("Expecting value", s, err.value) from None
json.decoder.JSONDecodeError: Expecting value: line 1 column 1 (char 0)
[2019-06-09 17:30:27,901][Thread-3:21184][task_id:django.request][log.py:228][ERROR][Internal Server Error: /testdb/]
Traceback (most recent call last):
  File "C:\Softwares\Anaconda3\envs\django\lib\site-packages\django\core\handlers\exception.py", line 34, in inner
    response = get_response(request)
  File "C:\Softwares\Anaconda3\envs\django\lib\site-packages\django\core\handlers\base.py", line 115, in _get_response
    response = self.process_exception_by_middleware(e, request)
  File "C:\Softwares\Anaconda3\envs\django\lib\site-packages\django\core\handlers\base.py", line 113, in _get_response
    response = wrapped_callback(request, *callback_args, **callback_kwargs)
  File "D:\Workspace\Projects\vast-challenge-2019-MC2\RadiationVis\backend\views.py", line 10, in testdb
    logger.info(json.loads(request.body))
  File "C:\Softwares\Anaconda3\envs\django\lib\json\__init__.py", line 354, in loads
    return _default_decoder.decode(s)
  File "C:\Softwares\Anaconda3\envs\django\lib\json\decoder.py", line 339, in decode
    obj, end = self.raw_decode(s, idx=_w(s, 0).end())
  File "C:\Softwares\Anaconda3\envs\django\lib\json\decoder.py", line 357, in raw_decode
    raise JSONDecodeError("Expecting value", s, err.value) from None
json.decoder.JSONDecodeError: Expecting value: line 1 column 1 (char 0)
[2019-06-09 17:31:28,790][Thread-2:17184][task_id:django.request][log.py:228][ERROR][Internal Server Error: /findSensorReadingsBySid/]
Traceback (most recent call last):
  File "C:\Softwares\Anaconda3\envs\django\lib\site-packages\django\db\backends\utils.py", line 84, in _execute
    return self.cursor.execute(sql, params)
  File "C:\Softwares\Anaconda3\envs\django\lib\site-packages\django\db\backends\mysql\base.py", line 71, in execute
    return self.cursor.execute(query, args)
  File "C:\Softwares\Anaconda3\envs\django\lib\site-packages\MySQLdb\cursors.py", line 255, in execute
    self.errorhandler(self, exc, value)
  File "C:\Softwares\Anaconda3\envs\django\lib\site-packages\MySQLdb\connections.py", line 50, in defaulterrorhandler
    raise errorvalue
  File "C:\Softwares\Anaconda3\envs\django\lib\site-packages\MySQLdb\cursors.py", line 252, in execute
    res = self._query(query)
  File "C:\Softwares\Anaconda3\envs\django\lib\site-packages\MySQLdb\cursors.py", line 378, in _query
    db.query(q)
  File "C:\Softwares\Anaconda3\envs\django\lib\site-packages\MySQLdb\connections.py", line 280, in query
    _mysql.connection.query(self, query)
_mysql_exceptions.OperationalError: (1054, "Unknown column 'staticsensorreadings.id' in 'field list'")

The above exception was the direct cause of the following exception:

Traceback (most recent call last):
  File "C:\Softwares\Anaconda3\envs\django\lib\site-packages\django\core\handlers\exception.py", line 34, in inner
    response = get_response(request)
  File "C:\Softwares\Anaconda3\envs\django\lib\site-packages\django\core\handlers\base.py", line 115, in _get_response
    response = self.process_exception_by_middleware(e, request)
  File "C:\Softwares\Anaconda3\envs\django\lib\site-packages\django\core\handlers\base.py", line 113, in _get_response
    response = wrapped_callback(request, *callback_args, **callback_kwargs)
  File "D:\Workspace\Projects\vast-challenge-2019-MC2\RadiationVis\backend\views.py", line 27, in findSensorReadingsBySid
    return HttpResponse(responseData)
  File "C:\Softwares\Anaconda3\envs\django\lib\site-packages\django\http\response.py", line 291, in __init__
    self.content = content
  File "C:\Softwares\Anaconda3\envs\django\lib\site-packages\django\http\response.py", line 314, in content
    content = b''.join(self.make_bytes(chunk) for chunk in value)
  File "C:\Softwares\Anaconda3\envs\django\lib\site-packages\django\db\models\query.py", line 274, in __iter__
    self._fetch_all()
  File "C:\Softwares\Anaconda3\envs\django\lib\site-packages\django\db\models\query.py", line 1242, in _fetch_all
    self._result_cache = list(self._iterable_class(self))
  File "C:\Softwares\Anaconda3\envs\django\lib\site-packages\django\db\models\query.py", line 55, in __iter__
    results = compiler.execute_sql(chunked_fetch=self.chunked_fetch, chunk_size=self.chunk_size)
  File "C:\Softwares\Anaconda3\envs\django\lib\site-packages\django\db\models\sql\compiler.py", line 1100, in execute_sql
    cursor.execute(sql, params)
  File "C:\Softwares\Anaconda3\envs\django\lib\site-packages\django\db\backends\utils.py", line 99, in execute
    return super().execute(sql, params)
  File "C:\Softwares\Anaconda3\envs\django\lib\site-packages\django\db\backends\utils.py", line 67, in execute
    return self._execute_with_wrappers(sql, params, many=False, executor=self._execute)
  File "C:\Softwares\Anaconda3\envs\django\lib\site-packages\django\db\backends\utils.py", line 76, in _execute_with_wrappers
    return executor(sql, params, many, context)
  File "C:\Softwares\Anaconda3\envs\django\lib\site-packages\django\db\backends\utils.py", line 84, in _execute
    return self.cursor.execute(sql, params)
  File "C:\Softwares\Anaconda3\envs\django\lib\site-packages\django\db\utils.py", line 89, in __exit__
    raise dj_exc_value.with_traceback(traceback) from exc_value
  File "C:\Softwares\Anaconda3\envs\django\lib\site-packages\django\db\backends\utils.py", line 84, in _execute
    return self.cursor.execute(sql, params)
  File "C:\Softwares\Anaconda3\envs\django\lib\site-packages\django\db\backends\mysql\base.py", line 71, in execute
    return self.cursor.execute(query, args)
  File "C:\Softwares\Anaconda3\envs\django\lib\site-packages\MySQLdb\cursors.py", line 255, in execute
    self.errorhandler(self, exc, value)
  File "C:\Softwares\Anaconda3\envs\django\lib\site-packages\MySQLdb\connections.py", line 50, in defaulterrorhandler
    raise errorvalue
  File "C:\Softwares\Anaconda3\envs\django\lib\site-packages\MySQLdb\cursors.py", line 252, in execute
    res = self._query(query)
  File "C:\Softwares\Anaconda3\envs\django\lib\site-packages\MySQLdb\cursors.py", line 378, in _query
    db.query(q)
  File "C:\Softwares\Anaconda3\envs\django\lib\site-packages\MySQLdb\connections.py", line 280, in query
    _mysql.connection.query(self, query)
django.db.utils.OperationalError: (1054, "Unknown column 'staticsensorreadings.id' in 'field list'")
[2019-06-09 17:33:41,820][Thread-2:2672][task_id:django.request][log.py:228][ERROR][Internal Server Error: /findSensorReadingsBySid/]
Traceback (most recent call last):
  File "C:\Softwares\Anaconda3\envs\django\lib\site-packages\django\db\backends\utils.py", line 84, in _execute
    return self.cursor.execute(sql, params)
  File "C:\Softwares\Anaconda3\envs\django\lib\site-packages\django\db\backends\mysql\base.py", line 71, in execute
    return self.cursor.execute(query, args)
  File "C:\Softwares\Anaconda3\envs\django\lib\site-packages\MySQLdb\cursors.py", line 255, in execute
    self.errorhandler(self, exc, value)
  File "C:\Softwares\Anaconda3\envs\django\lib\site-packages\MySQLdb\connections.py", line 50, in defaulterrorhandler
    raise errorvalue
  File "C:\Softwares\Anaconda3\envs\django\lib\site-packages\MySQLdb\cursors.py", line 252, in execute
    res = self._query(query)
  File "C:\Softwares\Anaconda3\envs\django\lib\site-packages\MySQLdb\cursors.py", line 378, in _query
    db.query(q)
  File "C:\Softwares\Anaconda3\envs\django\lib\site-packages\MySQLdb\connections.py", line 280, in query
    _mysql.connection.query(self, query)
_mysql_exceptions.OperationalError: (1054, "Unknown column 'staticsensorreadings.id' in 'field list'")

The above exception was the direct cause of the following exception:

Traceback (most recent call last):
  File "C:\Softwares\Anaconda3\envs\django\lib\site-packages\django\core\handlers\exception.py", line 34, in inner
    response = get_response(request)
  File "C:\Softwares\Anaconda3\envs\django\lib\site-packages\django\core\handlers\base.py", line 115, in _get_response
    response = self.process_exception_by_middleware(e, request)
  File "C:\Softwares\Anaconda3\envs\django\lib\site-packages\django\core\handlers\base.py", line 113, in _get_response
    response = wrapped_callback(request, *callback_args, **callback_kwargs)
  File "D:\Workspace\Projects\vast-challenge-2019-MC2\RadiationVis\backend\views.py", line 27, in findSensorReadingsBySid
    return HttpResponse(responseData)
  File "C:\Softwares\Anaconda3\envs\django\lib\site-packages\django\http\response.py", line 291, in __init__
    self.content = content
  File "C:\Softwares\Anaconda3\envs\django\lib\site-packages\django\http\response.py", line 314, in content
    content = b''.join(self.make_bytes(chunk) for chunk in value)
  File "C:\Softwares\Anaconda3\envs\django\lib\site-packages\django\db\models\query.py", line 274, in __iter__
    self._fetch_all()
  File "C:\Softwares\Anaconda3\envs\django\lib\site-packages\django\db\models\query.py", line 1242, in _fetch_all
    self._result_cache = list(self._iterable_class(self))
  File "C:\Softwares\Anaconda3\envs\django\lib\site-packages\django\db\models\query.py", line 55, in __iter__
    results = compiler.execute_sql(chunked_fetch=self.chunked_fetch, chunk_size=self.chunk_size)
  File "C:\Softwares\Anaconda3\envs\django\lib\site-packages\django\db\models\sql\compiler.py", line 1100, in execute_sql
    cursor.execute(sql, params)
  File "C:\Softwares\Anaconda3\envs\django\lib\site-packages\django\db\backends\utils.py", line 99, in execute
    return super().execute(sql, params)
  File "C:\Softwares\Anaconda3\envs\django\lib\site-packages\django\db\backends\utils.py", line 67, in execute
    return self._execute_with_wrappers(sql, params, many=False, executor=self._execute)
  File "C:\Softwares\Anaconda3\envs\django\lib\site-packages\django\db\backends\utils.py", line 76, in _execute_with_wrappers
    return executor(sql, params, many, context)
  File "C:\Softwares\Anaconda3\envs\django\lib\site-packages\django\db\backends\utils.py", line 84, in _execute
    return self.cursor.execute(sql, params)
  File "C:\Softwares\Anaconda3\envs\django\lib\site-packages\django\db\utils.py", line 89, in __exit__
    raise dj_exc_value.with_traceback(traceback) from exc_value
  File "C:\Softwares\Anaconda3\envs\django\lib\site-packages\django\db\backends\utils.py", line 84, in _execute
    return self.cursor.execute(sql, params)
  File "C:\Softwares\Anaconda3\envs\django\lib\site-packages\django\db\backends\mysql\base.py", line 71, in execute
    return self.cursor.execute(query, args)
  File "C:\Softwares\Anaconda3\envs\django\lib\site-packages\MySQLdb\cursors.py", line 255, in execute
    self.errorhandler(self, exc, value)
  File "C:\Softwares\Anaconda3\envs\django\lib\site-packages\MySQLdb\connections.py", line 50, in defaulterrorhandler
    raise errorvalue
  File "C:\Softwares\Anaconda3\envs\django\lib\site-packages\MySQLdb\cursors.py", line 252, in execute
    res = self._query(query)
  File "C:\Softwares\Anaconda3\envs\django\lib\site-packages\MySQLdb\cursors.py", line 378, in _query
    db.query(q)
  File "C:\Softwares\Anaconda3\envs\django\lib\site-packages\MySQLdb\connections.py", line 280, in query
    _mysql.connection.query(self, query)
django.db.utils.OperationalError: (1054, "Unknown column 'staticsensorreadings.id' in 'field list'")
[2019-06-09 17:33:56,374][Thread-1:10456][task_id:django.request][log.py:228][ERROR][Internal Server Error: /findSensorReadingsBySid/]
Traceback (most recent call last):
  File "C:\Softwares\Anaconda3\envs\django\lib\site-packages\django\db\backends\utils.py", line 84, in _execute
    return self.cursor.execute(sql, params)
  File "C:\Softwares\Anaconda3\envs\django\lib\site-packages\django\db\backends\mysql\base.py", line 71, in execute
    return self.cursor.execute(query, args)
  File "C:\Softwares\Anaconda3\envs\django\lib\site-packages\MySQLdb\cursors.py", line 255, in execute
    self.errorhandler(self, exc, value)
  File "C:\Softwares\Anaconda3\envs\django\lib\site-packages\MySQLdb\connections.py", line 50, in defaulterrorhandler
    raise errorvalue
  File "C:\Softwares\Anaconda3\envs\django\lib\site-packages\MySQLdb\cursors.py", line 252, in execute
    res = self._query(query)
  File "C:\Softwares\Anaconda3\envs\django\lib\site-packages\MySQLdb\cursors.py", line 378, in _query
    db.query(q)
  File "C:\Softwares\Anaconda3\envs\django\lib\site-packages\MySQLdb\connections.py", line 280, in query
    _mysql.connection.query(self, query)
_mysql_exceptions.OperationalError: (1054, "Unknown column 'staticsensorreadings.id' in 'field list'")

The above exception was the direct cause of the following exception:

Traceback (most recent call last):
  File "C:\Softwares\Anaconda3\envs\django\lib\site-packages\django\core\handlers\exception.py", line 34, in inner
    response = get_response(request)
  File "C:\Softwares\Anaconda3\envs\django\lib\site-packages\django\core\handlers\base.py", line 115, in _get_response
    response = self.process_exception_by_middleware(e, request)
  File "C:\Softwares\Anaconda3\envs\django\lib\site-packages\django\core\handlers\base.py", line 113, in _get_response
    response = wrapped_callback(request, *callback_args, **callback_kwargs)
  File "D:\Workspace\Projects\vast-challenge-2019-MC2\RadiationVis\backend\views.py", line 27, in findSensorReadingsBySid
    return HttpResponse(responseData)
  File "C:\Softwares\Anaconda3\envs\django\lib\site-packages\django\http\response.py", line 291, in __init__
    self.content = content
  File "C:\Softwares\Anaconda3\envs\django\lib\site-packages\django\http\response.py", line 314, in content
    content = b''.join(self.make_bytes(chunk) for chunk in value)
  File "C:\Softwares\Anaconda3\envs\django\lib\site-packages\django\db\models\query.py", line 274, in __iter__
    self._fetch_all()
  File "C:\Softwares\Anaconda3\envs\django\lib\site-packages\django\db\models\query.py", line 1242, in _fetch_all
    self._result_cache = list(self._iterable_class(self))
  File "C:\Softwares\Anaconda3\envs\django\lib\site-packages\django\db\models\query.py", line 55, in __iter__
    results = compiler.execute_sql(chunked_fetch=self.chunked_fetch, chunk_size=self.chunk_size)
  File "C:\Softwares\Anaconda3\envs\django\lib\site-packages\django\db\models\sql\compiler.py", line 1100, in execute_sql
    cursor.execute(sql, params)
  File "C:\Softwares\Anaconda3\envs\django\lib\site-packages\django\db\backends\utils.py", line 99, in execute
    return super().execute(sql, params)
  File "C:\Softwares\Anaconda3\envs\django\lib\site-packages\django\db\backends\utils.py", line 67, in execute
    return self._execute_with_wrappers(sql, params, many=False, executor=self._execute)
  File "C:\Softwares\Anaconda3\envs\django\lib\site-packages\django\db\backends\utils.py", line 76, in _execute_with_wrappers
    return executor(sql, params, many, context)
  File "C:\Softwares\Anaconda3\envs\django\lib\site-packages\django\db\backends\utils.py", line 84, in _execute
    return self.cursor.execute(sql, params)
  File "C:\Softwares\Anaconda3\envs\django\lib\site-packages\django\db\utils.py", line 89, in __exit__
    raise dj_exc_value.with_traceback(traceback) from exc_value
  File "C:\Softwares\Anaconda3\envs\django\lib\site-packages\django\db\backends\utils.py", line 84, in _execute
    return self.cursor.execute(sql, params)
  File "C:\Softwares\Anaconda3\envs\django\lib\site-packages\django\db\backends\mysql\base.py", line 71, in execute
    return self.cursor.execute(query, args)
  File "C:\Softwares\Anaconda3\envs\django\lib\site-packages\MySQLdb\cursors.py", line 255, in execute
    self.errorhandler(self, exc, value)
  File "C:\Softwares\Anaconda3\envs\django\lib\site-packages\MySQLdb\connections.py", line 50, in defaulterrorhandler
    raise errorvalue
  File "C:\Softwares\Anaconda3\envs\django\lib\site-packages\MySQLdb\cursors.py", line 252, in execute
    res = self._query(query)
  File "C:\Softwares\Anaconda3\envs\django\lib\site-packages\MySQLdb\cursors.py", line 378, in _query
    db.query(q)
  File "C:\Softwares\Anaconda3\envs\django\lib\site-packages\MySQLdb\connections.py", line 280, in query
    _mysql.connection.query(self, query)
django.db.utils.OperationalError: (1054, "Unknown column 'staticsensorreadings.id' in 'field list'")
[2019-06-09 17:35:28,306][Thread-1:16976][task_id:django.request][log.py:228][ERROR][Internal Server Error: /findSensorReadingsBySid/]
Traceback (most recent call last):
  File "C:\Softwares\Anaconda3\envs\django\lib\site-packages\django\db\backends\utils.py", line 84, in _execute
    return self.cursor.execute(sql, params)
  File "C:\Softwares\Anaconda3\envs\django\lib\site-packages\django\db\backends\mysql\base.py", line 71, in execute
    return self.cursor.execute(query, args)
  File "C:\Softwares\Anaconda3\envs\django\lib\site-packages\MySQLdb\cursors.py", line 255, in execute
    self.errorhandler(self, exc, value)
  File "C:\Softwares\Anaconda3\envs\django\lib\site-packages\MySQLdb\connections.py", line 50, in defaulterrorhandler
    raise errorvalue
  File "C:\Softwares\Anaconda3\envs\django\lib\site-packages\MySQLdb\cursors.py", line 252, in execute
    res = self._query(query)
  File "C:\Softwares\Anaconda3\envs\django\lib\site-packages\MySQLdb\cursors.py", line 378, in _query
    db.query(q)
  File "C:\Softwares\Anaconda3\envs\django\lib\site-packages\MySQLdb\connections.py", line 280, in query
    _mysql.connection.query(self, query)
_mysql_exceptions.OperationalError: (1054, "Unknown column 'staticsensorreadings.id' in 'field list'")

The above exception was the direct cause of the following exception:

Traceback (most recent call last):
  File "C:\Softwares\Anaconda3\envs\django\lib\site-packages\django\core\handlers\exception.py", line 34, in inner
    response = get_response(request)
  File "C:\Softwares\Anaconda3\envs\django\lib\site-packages\django\core\handlers\base.py", line 115, in _get_response
    response = self.process_exception_by_middleware(e, request)
  File "C:\Softwares\Anaconda3\envs\django\lib\site-packages\django\core\handlers\base.py", line 113, in _get_response
    response = wrapped_callback(request, *callback_args, **callback_kwargs)
  File "D:\Workspace\Projects\vast-challenge-2019-MC2\RadiationVis\backend\views.py", line 28, in findSensorReadingsBySid
    return HttpResponse(responseData)
  File "C:\Softwares\Anaconda3\envs\django\lib\site-packages\django\http\response.py", line 291, in __init__
    self.content = content
  File "C:\Softwares\Anaconda3\envs\django\lib\site-packages\django\http\response.py", line 314, in content
    content = b''.join(self.make_bytes(chunk) for chunk in value)
  File "C:\Softwares\Anaconda3\envs\django\lib\site-packages\django\db\models\query.py", line 274, in __iter__
    self._fetch_all()
  File "C:\Softwares\Anaconda3\envs\django\lib\site-packages\django\db\models\query.py", line 1242, in _fetch_all
    self._result_cache = list(self._iterable_class(self))
  File "C:\Softwares\Anaconda3\envs\django\lib\site-packages\django\db\models\query.py", line 55, in __iter__
    results = compiler.execute_sql(chunked_fetch=self.chunked_fetch, chunk_size=self.chunk_size)
  File "C:\Softwares\Anaconda3\envs\django\lib\site-packages\django\db\models\sql\compiler.py", line 1100, in execute_sql
    cursor.execute(sql, params)
  File "C:\Softwares\Anaconda3\envs\django\lib\site-packages\django\db\backends\utils.py", line 99, in execute
    return super().execute(sql, params)
  File "C:\Softwares\Anaconda3\envs\django\lib\site-packages\django\db\backends\utils.py", line 67, in execute
    return self._execute_with_wrappers(sql, params, many=False, executor=self._execute)
  File "C:\Softwares\Anaconda3\envs\django\lib\site-packages\django\db\backends\utils.py", line 76, in _execute_with_wrappers
    return executor(sql, params, many, context)
  File "C:\Softwares\Anaconda3\envs\django\lib\site-packages\django\db\backends\utils.py", line 84, in _execute
    return self.cursor.execute(sql, params)
  File "C:\Softwares\Anaconda3\envs\django\lib\site-packages\django\db\utils.py", line 89, in __exit__
    raise dj_exc_value.with_traceback(traceback) from exc_value
  File "C:\Softwares\Anaconda3\envs\django\lib\site-packages\django\db\backends\utils.py", line 84, in _execute
    return self.cursor.execute(sql, params)
  File "C:\Softwares\Anaconda3\envs\django\lib\site-packages\django\db\backends\mysql\base.py", line 71, in execute
    return self.cursor.execute(query, args)
  File "C:\Softwares\Anaconda3\envs\django\lib\site-packages\MySQLdb\cursors.py", line 255, in execute
    self.errorhandler(self, exc, value)
  File "C:\Softwares\Anaconda3\envs\django\lib\site-packages\MySQLdb\connections.py", line 50, in defaulterrorhandler
    raise errorvalue
  File "C:\Softwares\Anaconda3\envs\django\lib\site-packages\MySQLdb\cursors.py", line 252, in execute
    res = self._query(query)
  File "C:\Softwares\Anaconda3\envs\django\lib\site-packages\MySQLdb\cursors.py", line 378, in _query
    db.query(q)
  File "C:\Softwares\Anaconda3\envs\django\lib\site-packages\MySQLdb\connections.py", line 280, in query
    _mysql.connection.query(self, query)
django.db.utils.OperationalError: (1054, "Unknown column 'staticsensorreadings.id' in 'field list'")
[2019-06-09 17:39:55,158][Thread-1:6644][task_id:django.request][log.py:228][ERROR][Internal Server Error: /findSensorReadingsBySid/]
Traceback (most recent call last):
  File "C:\Softwares\Anaconda3\envs\django\lib\site-packages\django\core\handlers\exception.py", line 34, in inner
    response = get_response(request)
  File "C:\Softwares\Anaconda3\envs\django\lib\site-packages\django\core\handlers\base.py", line 115, in _get_response
    response = self.process_exception_by_middleware(e, request)
  File "C:\Softwares\Anaconda3\envs\django\lib\site-packages\django\core\handlers\base.py", line 113, in _get_response
    response = wrapped_callback(request, *callback_args, **callback_kwargs)
  File "D:\Workspace\Projects\vast-challenge-2019-MC2\RadiationVis\backend\views.py", line 28, in findSensorReadingsBySid
    return HttpResponse(json.loads(responseData))
  File "C:\Softwares\Anaconda3\envs\django\lib\json\__init__.py", line 348, in loads
    'not {!r}'.format(s.__class__.__name__))
TypeError: the JSON object must be str, bytes or bytearray, not 'QuerySet'
[2019-06-09 17:40:06,303][Thread-1:21224][task_id:django.request][log.py:228][ERROR][Internal Server Error: /findSensorReadingsBySid/]
Traceback (most recent call last):
  File "C:\Softwares\Anaconda3\envs\django\lib\site-packages\django\core\handlers\exception.py", line 34, in inner
    response = get_response(request)
  File "C:\Softwares\Anaconda3\envs\django\lib\site-packages\django\core\handlers\base.py", line 115, in _get_response
    response = self.process_exception_by_middleware(e, request)
  File "C:\Softwares\Anaconda3\envs\django\lib\site-packages\django\core\handlers\base.py", line 113, in _get_response
    response = wrapped_callback(request, *callback_args, **callback_kwargs)
  File "D:\Workspace\Projects\vast-challenge-2019-MC2\RadiationVis\backend\views.py", line 28, in findSensorReadingsBySid
    return HttpResponse(json.dumps(responseData))
  File "C:\Softwares\Anaconda3\envs\django\lib\json\__init__.py", line 231, in dumps
    return _default_encoder.encode(obj)
  File "C:\Softwares\Anaconda3\envs\django\lib\json\encoder.py", line 199, in encode
    chunks = self.iterencode(o, _one_shot=True)
  File "C:\Softwares\Anaconda3\envs\django\lib\json\encoder.py", line 257, in iterencode
    return _iterencode(o, 0)
  File "C:\Softwares\Anaconda3\envs\django\lib\json\encoder.py", line 180, in default
    o.__class__.__name__)
TypeError: Object of type 'QuerySet' is not JSON serializable
[2019-06-09 17:43:41,416][Thread-1:16980][task_id:django.request][log.py:228][ERROR][Internal Server Error: /findSensorReadingsBySid/]
Traceback (most recent call last):
  File "C:\Softwares\Anaconda3\envs\django\lib\site-packages\django\core\handlers\exception.py", line 34, in inner
    response = get_response(request)
  File "C:\Softwares\Anaconda3\envs\django\lib\site-packages\django\core\handlers\base.py", line 115, in _get_response
    response = self.process_exception_by_middleware(e, request)
  File "C:\Softwares\Anaconda3\envs\django\lib\site-packages\django\core\handlers\base.py", line 113, in _get_response
    response = wrapped_callback(request, *callback_args, **callback_kwargs)
  File "D:\Workspace\Projects\vast-challenge-2019-MC2\RadiationVis\backend\views.py", line 28, in findSensorReadingsBySid
    return HttpResponse(json.loads(responseData), content_type='application/json')
  File "C:\Softwares\Anaconda3\envs\django\lib\json\__init__.py", line 348, in loads
    'not {!r}'.format(s.__class__.__name__))
TypeError: the JSON object must be str, bytes or bytearray, not 'QuerySet'
[2019-06-09 17:44:52,252][Thread-1:20564][task_id:django.request][log.py:228][ERROR][Internal Server Error: /findSensorReadingsBySid/]
Traceback (most recent call last):
  File "C:\Softwares\Anaconda3\envs\django\lib\site-packages\django\core\handlers\exception.py", line 34, in inner
    response = get_response(request)
  File "C:\Softwares\Anaconda3\envs\django\lib\site-packages\django\core\handlers\base.py", line 115, in _get_response
    response = self.process_exception_by_middleware(e, request)
  File "C:\Softwares\Anaconda3\envs\django\lib\site-packages\django\core\handlers\base.py", line 113, in _get_response
    response = wrapped_callback(request, *callback_args, **callback_kwargs)
  File "D:\Workspace\Projects\vast-challenge-2019-MC2\RadiationVis\backend\views.py", line 28, in findSensorReadingsBySid
    logger.info(json.loads(responseData))
  File "C:\Softwares\Anaconda3\envs\django\lib\json\__init__.py", line 348, in loads
    'not {!r}'.format(s.__class__.__name__))
TypeError: the JSON object must be str, bytes or bytearray, not 'QuerySet'
[2019-06-09 17:46:00,209][Thread-1:1892][task_id:django.request][log.py:228][ERROR][Internal Server Error: /findSensorReadingsBySid/]
Traceback (most recent call last):
  File "C:\Softwares\Anaconda3\envs\django\lib\site-packages\django\core\handlers\exception.py", line 34, in inner
    response = get_response(request)
  File "C:\Softwares\Anaconda3\envs\django\lib\site-packages\django\core\handlers\base.py", line 115, in _get_response
    response = self.process_exception_by_middleware(e, request)
  File "C:\Softwares\Anaconda3\envs\django\lib\site-packages\django\core\handlers\base.py", line 113, in _get_response
    response = wrapped_callback(request, *callback_args, **callback_kwargs)
  File "D:\Workspace\Projects\vast-challenge-2019-MC2\RadiationVis\backend\views.py", line 28, in findSensorReadingsBySid
    logger.info(json.loads(responseData))
  File "C:\Softwares\Anaconda3\envs\django\lib\json\__init__.py", line 348, in loads
    'not {!r}'.format(s.__class__.__name__))
TypeError: the JSON object must be str, bytes or bytearray, not 'QuerySet'
[2019-06-09 17:47:46,670][Thread-1:19464][task_id:django.request][log.py:228][ERROR][Internal Server Error: /findSensorReadingsBySid/]
Traceback (most recent call last):
  File "C:\Softwares\Anaconda3\envs\django\lib\site-packages\django\core\handlers\exception.py", line 34, in inner
    response = get_response(request)
  File "C:\Softwares\Anaconda3\envs\django\lib\site-packages\django\core\handlers\base.py", line 115, in _get_response
    response = self.process_exception_by_middleware(e, request)
  File "C:\Softwares\Anaconda3\envs\django\lib\site-packages\django\core\handlers\base.py", line 113, in _get_response
    response = wrapped_callback(request, *callback_args, **callback_kwargs)
  File "D:\Workspace\Projects\vast-challenge-2019-MC2\RadiationVis\backend\views.py", line 28, in findSensorReadingsBySid
    logger.info(json.loads(responseData))
  File "C:\Softwares\Anaconda3\envs\django\lib\json\__init__.py", line 348, in loads
    'not {!r}'.format(s.__class__.__name__))
TypeError: the JSON object must be str, bytes or bytearray, not 'QuerySet'
[2019-06-09 17:49:01,465][Thread-1:20504][task_id:django.request][log.py:228][ERROR][Internal Server Error: /findSensorReadingsBySid/]
Traceback (most recent call last):
  File "C:\Softwares\Anaconda3\envs\django\lib\site-packages\django\core\handlers\exception.py", line 34, in inner
    response = get_response(request)
  File "C:\Softwares\Anaconda3\envs\django\lib\site-packages\django\core\handlers\base.py", line 115, in _get_response
    response = self.process_exception_by_middleware(e, request)
  File "C:\Softwares\Anaconda3\envs\django\lib\site-packages\django\core\handlers\base.py", line 113, in _get_response
    response = wrapped_callback(request, *callback_args, **callback_kwargs)
  File "D:\Workspace\Projects\vast-challenge-2019-MC2\RadiationVis\backend\views.py", line 28, in findSensorReadingsBySid
    logger.info(json.dumps(list(responseData)))
  File "C:\Softwares\Anaconda3\envs\django\lib\json\__init__.py", line 231, in dumps
    return _default_encoder.encode(obj)
  File "C:\Softwares\Anaconda3\envs\django\lib\json\encoder.py", line 199, in encode
    chunks = self.iterencode(o, _one_shot=True)
  File "C:\Softwares\Anaconda3\envs\django\lib\json\encoder.py", line 257, in iterencode
    return _iterencode(o, 0)
  File "C:\Softwares\Anaconda3\envs\django\lib\json\encoder.py", line 180, in default
    o.__class__.__name__)
TypeError: Object of type 'StaticSensorLocations' is not JSON serializable
[2019-06-09 17:50:34,186][Thread-1:10304][task_id:django.request][log.py:228][ERROR][Internal Server Error: /findSensorReadingsBySid/]
Traceback (most recent call last):
  File "C:\Softwares\Anaconda3\envs\django\lib\site-packages\django\core\handlers\exception.py", line 34, in inner
    response = get_response(request)
  File "C:\Softwares\Anaconda3\envs\django\lib\site-packages\django\core\handlers\base.py", line 115, in _get_response
    response = self.process_exception_by_middleware(e, request)
  File "C:\Softwares\Anaconda3\envs\django\lib\site-packages\django\core\handlers\base.py", line 113, in _get_response
    response = wrapped_callback(request, *callback_args, **callback_kwargs)
  File "D:\Workspace\Projects\vast-challenge-2019-MC2\RadiationVis\backend\views.py", line 28, in findSensorReadingsBySid
    logger.info(json.dumps({'d':list(responseData)}))
  File "C:\Softwares\Anaconda3\envs\django\lib\json\__init__.py", line 231, in dumps
    return _default_encoder.encode(obj)
  File "C:\Softwares\Anaconda3\envs\django\lib\json\encoder.py", line 199, in encode
    chunks = self.iterencode(o, _one_shot=True)
  File "C:\Softwares\Anaconda3\envs\django\lib\json\encoder.py", line 257, in iterencode
    return _iterencode(o, 0)
  File "C:\Softwares\Anaconda3\envs\django\lib\json\encoder.py", line 180, in default
    o.__class__.__name__)
TypeError: Object of type 'StaticSensorLocations' is not JSON serializable
[2019-06-09 18:02:28,850][Thread-1:14120][task_id:django.request][log.py:228][ERROR][Internal Server Error: /findSensorReadingsBySid/]
Traceback (most recent call last):
  File "C:\Softwares\Anaconda3\envs\django\lib\site-packages\django\core\handlers\exception.py", line 34, in inner
    response = get_response(request)
  File "C:\Softwares\Anaconda3\envs\django\lib\site-packages\django\core\handlers\base.py", line 115, in _get_response
    response = self.process_exception_by_middleware(e, request)
  File "C:\Softwares\Anaconda3\envs\django\lib\site-packages\django\core\handlers\base.py", line 113, in _get_response
    response = wrapped_callback(request, *callback_args, **callback_kwargs)
  File "D:\Workspace\Projects\vast-challenge-2019-MC2\RadiationVis\backend\views.py", line 30, in findSensorReadingsBySid
    return HttpResponse(json.dumps({"data" : responseData}), content_type='application/json')
  File "C:\Softwares\Anaconda3\envs\django\lib\json\__init__.py", line 231, in dumps
    return _default_encoder.encode(obj)
  File "C:\Softwares\Anaconda3\envs\django\lib\json\encoder.py", line 199, in encode
    chunks = self.iterencode(o, _one_shot=True)
  File "C:\Softwares\Anaconda3\envs\django\lib\json\encoder.py", line 257, in iterencode
    return _iterencode(o, 0)
  File "C:\Softwares\Anaconda3\envs\django\lib\json\encoder.py", line 180, in default
    o.__class__.__name__)
TypeError: Object of type 'QuerySet' is not JSON serializable
[2019-06-09 18:08:40,767][Thread-1:15036][task_id:django.request][log.py:228][ERROR][Internal Server Error: /findSensorReadingsBySid/]
Traceback (most recent call last):
  File "C:\Softwares\Anaconda3\envs\django\lib\site-packages\django\core\handlers\exception.py", line 34, in inner
    response = get_response(request)
  File "C:\Softwares\Anaconda3\envs\django\lib\site-packages\django\core\handlers\base.py", line 115, in _get_response
    response = self.process_exception_by_middleware(e, request)
  File "C:\Softwares\Anaconda3\envs\django\lib\site-packages\django\core\handlers\base.py", line 113, in _get_response
    response = wrapped_callback(request, *callback_args, **callback_kwargs)
  File "D:\Workspace\Projects\vast-challenge-2019-MC2\RadiationVis\backend\views.py", line 30, in findSensorReadingsBySid
    return HttpResponse(json.dumps({'sensorReadings': list(responseData)}), content_type='application/json')
  File "C:\Softwares\Anaconda3\envs\django\lib\json\__init__.py", line 231, in dumps
    return _default_encoder.encode(obj)
  File "C:\Softwares\Anaconda3\envs\django\lib\json\encoder.py", line 199, in encode
    chunks = self.iterencode(o, _one_shot=True)
  File "C:\Softwares\Anaconda3\envs\django\lib\json\encoder.py", line 257, in iterencode
    return _iterencode(o, 0)
  File "C:\Softwares\Anaconda3\envs\django\lib\json\encoder.py", line 180, in default
    o.__class__.__name__)
TypeError: Object of type 'StaticSensorLocations' is not JSON serializable
[2019-06-09 18:09:10,572][Thread-1:13584][task_id:django.request][log.py:228][ERROR][Internal Server Error: /findSensorReadingsBySid/]
Traceback (most recent call last):
  File "C:\Softwares\Anaconda3\envs\django\lib\site-packages\django\db\backends\utils.py", line 84, in _execute
    return self.cursor.execute(sql, params)
  File "C:\Softwares\Anaconda3\envs\django\lib\site-packages\django\db\backends\mysql\base.py", line 71, in execute
    return self.cursor.execute(query, args)
  File "C:\Softwares\Anaconda3\envs\django\lib\site-packages\MySQLdb\cursors.py", line 255, in execute
    self.errorhandler(self, exc, value)
  File "C:\Softwares\Anaconda3\envs\django\lib\site-packages\MySQLdb\connections.py", line 50, in defaulterrorhandler
    raise errorvalue
  File "C:\Softwares\Anaconda3\envs\django\lib\site-packages\MySQLdb\cursors.py", line 252, in execute
    res = self._query(query)
  File "C:\Softwares\Anaconda3\envs\django\lib\site-packages\MySQLdb\cursors.py", line 378, in _query
    db.query(q)
  File "C:\Softwares\Anaconda3\envs\django\lib\site-packages\MySQLdb\connections.py", line 280, in query
    _mysql.connection.query(self, query)
_mysql_exceptions.OperationalError: (1054, "Unknown column 'staticsensorreadings.id' in 'field list'")

The above exception was the direct cause of the following exception:

Traceback (most recent call last):
  File "C:\Softwares\Anaconda3\envs\django\lib\site-packages\django\core\handlers\exception.py", line 34, in inner
    response = get_response(request)
  File "C:\Softwares\Anaconda3\envs\django\lib\site-packages\django\core\handlers\base.py", line 115, in _get_response
    response = self.process_exception_by_middleware(e, request)
  File "C:\Softwares\Anaconda3\envs\django\lib\site-packages\django\core\handlers\base.py", line 113, in _get_response
    response = wrapped_callback(request, *callback_args, **callback_kwargs)
  File "D:\Workspace\Projects\vast-challenge-2019-MC2\RadiationVis\backend\views.py", line 28, in findSensorReadingsBySid
    logger.info(list(responseData))
  File "C:\Softwares\Anaconda3\envs\django\lib\site-packages\django\db\models\query.py", line 274, in __iter__
    self._fetch_all()
  File "C:\Softwares\Anaconda3\envs\django\lib\site-packages\django\db\models\query.py", line 1242, in _fetch_all
    self._result_cache = list(self._iterable_class(self))
  File "C:\Softwares\Anaconda3\envs\django\lib\site-packages\django\db\models\query.py", line 113, in __iter__
    for row in compiler.results_iter(chunked_fetch=self.chunked_fetch, chunk_size=self.chunk_size):
  File "C:\Softwares\Anaconda3\envs\django\lib\site-packages\django\db\models\sql\compiler.py", line 1052, in results_iter
    results = self.execute_sql(MULTI, chunked_fetch=chunked_fetch, chunk_size=chunk_size)
  File "C:\Softwares\Anaconda3\envs\django\lib\site-packages\django\db\models\sql\compiler.py", line 1100, in execute_sql
    cursor.execute(sql, params)
  File "C:\Softwares\Anaconda3\envs\django\lib\site-packages\django\db\backends\utils.py", line 99, in execute
    return super().execute(sql, params)
  File "C:\Softwares\Anaconda3\envs\django\lib\site-packages\django\db\backends\utils.py", line 67, in execute
    return self._execute_with_wrappers(sql, params, many=False, executor=self._execute)
  File "C:\Softwares\Anaconda3\envs\django\lib\site-packages\django\db\backends\utils.py", line 76, in _execute_with_wrappers
    return executor(sql, params, many, context)
  File "C:\Softwares\Anaconda3\envs\django\lib\site-packages\django\db\backends\utils.py", line 84, in _execute
    return self.cursor.execute(sql, params)
  File "C:\Softwares\Anaconda3\envs\django\lib\site-packages\django\db\utils.py", line 89, in __exit__
    raise dj_exc_value.with_traceback(traceback) from exc_value
  File "C:\Softwares\Anaconda3\envs\django\lib\site-packages\django\db\backends\utils.py", line 84, in _execute
    return self.cursor.execute(sql, params)
  File "C:\Softwares\Anaconda3\envs\django\lib\site-packages\django\db\backends\mysql\base.py", line 71, in execute
    return self.cursor.execute(query, args)
  File "C:\Softwares\Anaconda3\envs\django\lib\site-packages\MySQLdb\cursors.py", line 255, in execute
    self.errorhandler(self, exc, value)
  File "C:\Softwares\Anaconda3\envs\django\lib\site-packages\MySQLdb\connections.py", line 50, in defaulterrorhandler
    raise errorvalue
  File "C:\Softwares\Anaconda3\envs\django\lib\site-packages\MySQLdb\cursors.py", line 252, in execute
    res = self._query(query)
  File "C:\Softwares\Anaconda3\envs\django\lib\site-packages\MySQLdb\cursors.py", line 378, in _query
    db.query(q)
  File "C:\Softwares\Anaconda3\envs\django\lib\site-packages\MySQLdb\connections.py", line 280, in query
    _mysql.connection.query(self, query)
django.db.utils.OperationalError: (1054, "Unknown column 'staticsensorreadings.id' in 'field list'")
[2019-06-09 18:10:51,282][Thread-1:804][task_id:django.request][log.py:228][ERROR][Internal Server Error: /findSensorReadingsBySid/]
Traceback (most recent call last):
  File "C:\Softwares\Anaconda3\envs\django\lib\site-packages\django\db\backends\utils.py", line 84, in _execute
    return self.cursor.execute(sql, params)
  File "C:\Softwares\Anaconda3\envs\django\lib\site-packages\django\db\backends\mysql\base.py", line 71, in execute
    return self.cursor.execute(query, args)
  File "C:\Softwares\Anaconda3\envs\django\lib\site-packages\MySQLdb\cursors.py", line 255, in execute
    self.errorhandler(self, exc, value)
  File "C:\Softwares\Anaconda3\envs\django\lib\site-packages\MySQLdb\connections.py", line 50, in defaulterrorhandler
    raise errorvalue
  File "C:\Softwares\Anaconda3\envs\django\lib\site-packages\MySQLdb\cursors.py", line 252, in execute
    res = self._query(query)
  File "C:\Softwares\Anaconda3\envs\django\lib\site-packages\MySQLdb\cursors.py", line 378, in _query
    db.query(q)
  File "C:\Softwares\Anaconda3\envs\django\lib\site-packages\MySQLdb\connections.py", line 280, in query
    _mysql.connection.query(self, query)
_mysql_exceptions.OperationalError: (1054, "Unknown column 'staticsensorreadings.id' in 'field list'")

The above exception was the direct cause of the following exception:

Traceback (most recent call last):
  File "C:\Softwares\Anaconda3\envs\django\lib\site-packages\django\core\handlers\exception.py", line 34, in inner
    response = get_response(request)
  File "C:\Softwares\Anaconda3\envs\django\lib\site-packages\django\core\handlers\base.py", line 115, in _get_response
    response = self.process_exception_by_middleware(e, request)
  File "C:\Softwares\Anaconda3\envs\django\lib\site-packages\django\core\handlers\base.py", line 113, in _get_response
    response = wrapped_callback(request, *callback_args, **callback_kwargs)
  File "D:\Workspace\Projects\vast-challenge-2019-MC2\RadiationVis\backend\views.py", line 28, in findSensorReadingsBySid
    logger.info(list(responseData))
  File "C:\Softwares\Anaconda3\envs\django\lib\site-packages\django\db\models\query.py", line 274, in __iter__
    self._fetch_all()
  File "C:\Softwares\Anaconda3\envs\django\lib\site-packages\django\db\models\query.py", line 1242, in _fetch_all
    self._result_cache = list(self._iterable_class(self))
  File "C:\Softwares\Anaconda3\envs\django\lib\site-packages\django\db\models\query.py", line 113, in __iter__
    for row in compiler.results_iter(chunked_fetch=self.chunked_fetch, chunk_size=self.chunk_size):
  File "C:\Softwares\Anaconda3\envs\django\lib\site-packages\django\db\models\sql\compiler.py", line 1052, in results_iter
    results = self.execute_sql(MULTI, chunked_fetch=chunked_fetch, chunk_size=chunk_size)
  File "C:\Softwares\Anaconda3\envs\django\lib\site-packages\django\db\models\sql\compiler.py", line 1100, in execute_sql
    cursor.execute(sql, params)
  File "C:\Softwares\Anaconda3\envs\django\lib\site-packages\django\db\backends\utils.py", line 99, in execute
    return super().execute(sql, params)
  File "C:\Softwares\Anaconda3\envs\django\lib\site-packages\django\db\backends\utils.py", line 67, in execute
    return self._execute_with_wrappers(sql, params, many=False, executor=self._execute)
  File "C:\Softwares\Anaconda3\envs\django\lib\site-packages\django\db\backends\utils.py", line 76, in _execute_with_wrappers
    return executor(sql, params, many, context)
  File "C:\Softwares\Anaconda3\envs\django\lib\site-packages\django\db\backends\utils.py", line 84, in _execute
    return self.cursor.execute(sql, params)
  File "C:\Softwares\Anaconda3\envs\django\lib\site-packages\django\db\utils.py", line 89, in __exit__
    raise dj_exc_value.with_traceback(traceback) from exc_value
  File "C:\Softwares\Anaconda3\envs\django\lib\site-packages\django\db\backends\utils.py", line 84, in _execute
    return self.cursor.execute(sql, params)
  File "C:\Softwares\Anaconda3\envs\django\lib\site-packages\django\db\backends\mysql\base.py", line 71, in execute
    return self.cursor.execute(query, args)
  File "C:\Softwares\Anaconda3\envs\django\lib\site-packages\MySQLdb\cursors.py", line 255, in execute
    self.errorhandler(self, exc, value)
  File "C:\Softwares\Anaconda3\envs\django\lib\site-packages\MySQLdb\connections.py", line 50, in defaulterrorhandler
    raise errorvalue
  File "C:\Softwares\Anaconda3\envs\django\lib\site-packages\MySQLdb\cursors.py", line 252, in execute
    res = self._query(query)
  File "C:\Softwares\Anaconda3\envs\django\lib\site-packages\MySQLdb\cursors.py", line 378, in _query
    db.query(q)
  File "C:\Softwares\Anaconda3\envs\django\lib\site-packages\MySQLdb\connections.py", line 280, in query
    _mysql.connection.query(self, query)
django.db.utils.OperationalError: (1054, "Unknown column 'staticsensorreadings.id' in 'field list'")
[2019-06-09 18:13:53,796][Thread-1:21128][task_id:django.request][log.py:228][ERROR][Internal Server Error: /findSensorReadingsBySid/]
Traceback (most recent call last):
  File "C:\Softwares\Anaconda3\envs\django\lib\site-packages\django\db\backends\utils.py", line 84, in _execute
    return self.cursor.execute(sql, params)
  File "C:\Softwares\Anaconda3\envs\django\lib\site-packages\django\db\backends\mysql\base.py", line 71, in execute
    return self.cursor.execute(query, args)
  File "C:\Softwares\Anaconda3\envs\django\lib\site-packages\MySQLdb\cursors.py", line 255, in execute
    self.errorhandler(self, exc, value)
  File "C:\Softwares\Anaconda3\envs\django\lib\site-packages\MySQLdb\connections.py", line 50, in defaulterrorhandler
    raise errorvalue
  File "C:\Softwares\Anaconda3\envs\django\lib\site-packages\MySQLdb\cursors.py", line 252, in execute
    res = self._query(query)
  File "C:\Softwares\Anaconda3\envs\django\lib\site-packages\MySQLdb\cursors.py", line 378, in _query
    db.query(q)
  File "C:\Softwares\Anaconda3\envs\django\lib\site-packages\MySQLdb\connections.py", line 280, in query
    _mysql.connection.query(self, query)
_mysql_exceptions.OperationalError: (1054, "Unknown column 'staticsensorreadings.id' in 'field list'")

The above exception was the direct cause of the following exception:

Traceback (most recent call last):
  File "C:\Softwares\Anaconda3\envs\django\lib\site-packages\django\core\handlers\exception.py", line 34, in inner
    response = get_response(request)
  File "C:\Softwares\Anaconda3\envs\django\lib\site-packages\django\core\handlers\base.py", line 115, in _get_response
    response = self.process_exception_by_middleware(e, request)
  File "C:\Softwares\Anaconda3\envs\django\lib\site-packages\django\core\handlers\base.py", line 113, in _get_response
    response = wrapped_callback(request, *callback_args, **callback_kwargs)
  File "D:\Workspace\Projects\vast-challenge-2019-MC2\RadiationVis\backend\views.py", line 28, in findSensorReadingsBySid
    logger.info(list(responseData))
  File "C:\Softwares\Anaconda3\envs\django\lib\site-packages\django\db\models\query.py", line 274, in __iter__
    self._fetch_all()
  File "C:\Softwares\Anaconda3\envs\django\lib\site-packages\django\db\models\query.py", line 1242, in _fetch_all
    self._result_cache = list(self._iterable_class(self))
  File "C:\Softwares\Anaconda3\envs\django\lib\site-packages\django\db\models\query.py", line 113, in __iter__
    for row in compiler.results_iter(chunked_fetch=self.chunked_fetch, chunk_size=self.chunk_size):
  File "C:\Softwares\Anaconda3\envs\django\lib\site-packages\django\db\models\sql\compiler.py", line 1052, in results_iter
    results = self.execute_sql(MULTI, chunked_fetch=chunked_fetch, chunk_size=chunk_size)
  File "C:\Softwares\Anaconda3\envs\django\lib\site-packages\django\db\models\sql\compiler.py", line 1100, in execute_sql
    cursor.execute(sql, params)
  File "C:\Softwares\Anaconda3\envs\django\lib\site-packages\django\db\backends\utils.py", line 99, in execute
    return super().execute(sql, params)
  File "C:\Softwares\Anaconda3\envs\django\lib\site-packages\django\db\backends\utils.py", line 67, in execute
    return self._execute_with_wrappers(sql, params, many=False, executor=self._execute)
  File "C:\Softwares\Anaconda3\envs\django\lib\site-packages\django\db\backends\utils.py", line 76, in _execute_with_wrappers
    return executor(sql, params, many, context)
  File "C:\Softwares\Anaconda3\envs\django\lib\site-packages\django\db\backends\utils.py", line 84, in _execute
    return self.cursor.execute(sql, params)
  File "C:\Softwares\Anaconda3\envs\django\lib\site-packages\django\db\utils.py", line 89, in __exit__
    raise dj_exc_value.with_traceback(traceback) from exc_value
  File "C:\Softwares\Anaconda3\envs\django\lib\site-packages\django\db\backends\utils.py", line 84, in _execute
    return self.cursor.execute(sql, params)
  File "C:\Softwares\Anaconda3\envs\django\lib\site-packages\django\db\backends\mysql\base.py", line 71, in execute
    return self.cursor.execute(query, args)
  File "C:\Softwares\Anaconda3\envs\django\lib\site-packages\MySQLdb\cursors.py", line 255, in execute
    self.errorhandler(self, exc, value)
  File "C:\Softwares\Anaconda3\envs\django\lib\site-packages\MySQLdb\connections.py", line 50, in defaulterrorhandler
    raise errorvalue
  File "C:\Softwares\Anaconda3\envs\django\lib\site-packages\MySQLdb\cursors.py", line 252, in execute
    res = self._query(query)
  File "C:\Softwares\Anaconda3\envs\django\lib\site-packages\MySQLdb\cursors.py", line 378, in _query
    db.query(q)
  File "C:\Softwares\Anaconda3\envs\django\lib\site-packages\MySQLdb\connections.py", line 280, in query
    _mysql.connection.query(self, query)
django.db.utils.OperationalError: (1054, "Unknown column 'staticsensorreadings.id' in 'field list'")
[2019-06-09 18:18:20,655][Thread-1:5536][task_id:django.request][log.py:228][ERROR][Internal Server Error: /findSensorReadingsBySid/]
Traceback (most recent call last):
  File "C:\Softwares\Anaconda3\envs\django\lib\site-packages\django\db\backends\utils.py", line 84, in _execute
    return self.cursor.execute(sql, params)
  File "C:\Softwares\Anaconda3\envs\django\lib\site-packages\django\db\backends\mysql\base.py", line 71, in execute
    return self.cursor.execute(query, args)
  File "C:\Softwares\Anaconda3\envs\django\lib\site-packages\MySQLdb\cursors.py", line 255, in execute
    self.errorhandler(self, exc, value)
  File "C:\Softwares\Anaconda3\envs\django\lib\site-packages\MySQLdb\connections.py", line 50, in defaulterrorhandler
    raise errorvalue
  File "C:\Softwares\Anaconda3\envs\django\lib\site-packages\MySQLdb\cursors.py", line 252, in execute
    res = self._query(query)
  File "C:\Softwares\Anaconda3\envs\django\lib\site-packages\MySQLdb\cursors.py", line 378, in _query
    db.query(q)
  File "C:\Softwares\Anaconda3\envs\django\lib\site-packages\MySQLdb\connections.py", line 280, in query
    _mysql.connection.query(self, query)
_mysql_exceptions.OperationalError: (1054, "Unknown column 'staticsensorreadings.id' in 'field list'")

The above exception was the direct cause of the following exception:

Traceback (most recent call last):
  File "C:\Softwares\Anaconda3\envs\django\lib\site-packages\django\core\handlers\exception.py", line 34, in inner
    response = get_response(request)
  File "C:\Softwares\Anaconda3\envs\django\lib\site-packages\django\core\handlers\base.py", line 115, in _get_response
    response = self.process_exception_by_middleware(e, request)
  File "C:\Softwares\Anaconda3\envs\django\lib\site-packages\django\core\handlers\base.py", line 113, in _get_response
    response = wrapped_callback(request, *callback_args, **callback_kwargs)
  File "D:\Workspace\Projects\vast-challenge-2019-MC2\RadiationVis\backend\views.py", line 28, in findSensorReadingsBySid
    logger.info(list(responseData))
  File "C:\Softwares\Anaconda3\envs\django\lib\site-packages\django\db\models\query.py", line 274, in __iter__
    self._fetch_all()
  File "C:\Softwares\Anaconda3\envs\django\lib\site-packages\django\db\models\query.py", line 1242, in _fetch_all
    self._result_cache = list(self._iterable_class(self))
  File "C:\Softwares\Anaconda3\envs\django\lib\site-packages\django\db\models\query.py", line 113, in __iter__
    for row in compiler.results_iter(chunked_fetch=self.chunked_fetch, chunk_size=self.chunk_size):
  File "C:\Softwares\Anaconda3\envs\django\lib\site-packages\django\db\models\sql\compiler.py", line 1052, in results_iter
    results = self.execute_sql(MULTI, chunked_fetch=chunked_fetch, chunk_size=chunk_size)
  File "C:\Softwares\Anaconda3\envs\django\lib\site-packages\django\db\models\sql\compiler.py", line 1100, in execute_sql
    cursor.execute(sql, params)
  File "C:\Softwares\Anaconda3\envs\django\lib\site-packages\django\db\backends\utils.py", line 99, in execute
    return super().execute(sql, params)
  File "C:\Softwares\Anaconda3\envs\django\lib\site-packages\django\db\backends\utils.py", line 67, in execute
    return self._execute_with_wrappers(sql, params, many=False, executor=self._execute)
  File "C:\Softwares\Anaconda3\envs\django\lib\site-packages\django\db\backends\utils.py", line 76, in _execute_with_wrappers
    return executor(sql, params, many, context)
  File "C:\Softwares\Anaconda3\envs\django\lib\site-packages\django\db\backends\utils.py", line 84, in _execute
    return self.cursor.execute(sql, params)
  File "C:\Softwares\Anaconda3\envs\django\lib\site-packages\django\db\utils.py", line 89, in __exit__
    raise dj_exc_value.with_traceback(traceback) from exc_value
  File "C:\Softwares\Anaconda3\envs\django\lib\site-packages\django\db\backends\utils.py", line 84, in _execute
    return self.cursor.execute(sql, params)
  File "C:\Softwares\Anaconda3\envs\django\lib\site-packages\django\db\backends\mysql\base.py", line 71, in execute
    return self.cursor.execute(query, args)
  File "C:\Softwares\Anaconda3\envs\django\lib\site-packages\MySQLdb\cursors.py", line 255, in execute
    self.errorhandler(self, exc, value)
  File "C:\Softwares\Anaconda3\envs\django\lib\site-packages\MySQLdb\connections.py", line 50, in defaulterrorhandler
    raise errorvalue
  File "C:\Softwares\Anaconda3\envs\django\lib\site-packages\MySQLdb\cursors.py", line 252, in execute
    res = self._query(query)
  File "C:\Softwares\Anaconda3\envs\django\lib\site-packages\MySQLdb\cursors.py", line 378, in _query
    db.query(q)
  File "C:\Softwares\Anaconda3\envs\django\lib\site-packages\MySQLdb\connections.py", line 280, in query
    _mysql.connection.query(self, query)
django.db.utils.OperationalError: (1054, "Unknown column 'staticsensorreadings.id' in 'field list'")
[2019-06-09 18:26:17,353][Thread-1:22240][task_id:django.request][log.py:228][ERROR][Internal Server Error: /testdb/]
Traceback (most recent call last):
  File "C:\Softwares\Anaconda3\envs\django\lib\site-packages\django\core\handlers\exception.py", line 34, in inner
    response = get_response(request)
  File "C:\Softwares\Anaconda3\envs\django\lib\site-packages\django\core\handlers\base.py", line 115, in _get_response
    response = self.process_exception_by_middleware(e, request)
  File "C:\Softwares\Anaconda3\envs\django\lib\site-packages\django\core\handlers\base.py", line 113, in _get_response
    response = wrapped_callback(request, *callback_args, **callback_kwargs)
  File "D:\Workspace\Projects\vast-challenge-2019-MC2\RadiationVis\backend\views.py", line 14, in testdb
    return HttpResponse(json.dumps({'data': list(all)}), content_type='application/json')
  File "C:\Softwares\Anaconda3\envs\django\lib\json\__init__.py", line 231, in dumps
    return _default_encoder.encode(obj)
  File "C:\Softwares\Anaconda3\envs\django\lib\json\encoder.py", line 199, in encode
    chunks = self.iterencode(o, _one_shot=True)
  File "C:\Softwares\Anaconda3\envs\django\lib\json\encoder.py", line 257, in iterencode
    return _iterencode(o, 0)
  File "C:\Softwares\Anaconda3\envs\django\lib\json\encoder.py", line 180, in default
    o.__class__.__name__)
TypeError: Object of type 'StaticSensorLocations' is not JSON serializable
[2019-06-09 18:26:42,420][Thread-4:8216][task_id:django.request][log.py:228][ERROR][Internal Server Error: /findSensorReadingsBySid/]
Traceback (most recent call last):
  File "C:\Softwares\Anaconda3\envs\django\lib\site-packages\django\db\backends\utils.py", line 84, in _execute
    return self.cursor.execute(sql, params)
  File "C:\Softwares\Anaconda3\envs\django\lib\site-packages\django\db\backends\mysql\base.py", line 71, in execute
    return self.cursor.execute(query, args)
  File "C:\Softwares\Anaconda3\envs\django\lib\site-packages\MySQLdb\cursors.py", line 255, in execute
    self.errorhandler(self, exc, value)
  File "C:\Softwares\Anaconda3\envs\django\lib\site-packages\MySQLdb\connections.py", line 50, in defaulterrorhandler
    raise errorvalue
  File "C:\Softwares\Anaconda3\envs\django\lib\site-packages\MySQLdb\cursors.py", line 252, in execute
    res = self._query(query)
  File "C:\Softwares\Anaconda3\envs\django\lib\site-packages\MySQLdb\cursors.py", line 378, in _query
    db.query(q)
  File "C:\Softwares\Anaconda3\envs\django\lib\site-packages\MySQLdb\connections.py", line 280, in query
    _mysql.connection.query(self, query)
_mysql_exceptions.OperationalError: (1054, "Unknown column 'staticsensorreadings.id' in 'field list'")

The above exception was the direct cause of the following exception:

Traceback (most recent call last):
  File "C:\Softwares\Anaconda3\envs\django\lib\site-packages\django\core\handlers\exception.py", line 34, in inner
    response = get_response(request)
  File "C:\Softwares\Anaconda3\envs\django\lib\site-packages\django\core\handlers\base.py", line 115, in _get_response
    response = self.process_exception_by_middleware(e, request)
  File "C:\Softwares\Anaconda3\envs\django\lib\site-packages\django\core\handlers\base.py", line 113, in _get_response
    response = wrapped_callback(request, *callback_args, **callback_kwargs)
  File "D:\Workspace\Projects\vast-challenge-2019-MC2\RadiationVis\backend\views.py", line 28, in findSensorReadingsBySid
    logger.info(list(responseData))
  File "C:\Softwares\Anaconda3\envs\django\lib\site-packages\django\db\models\query.py", line 274, in __iter__
    self._fetch_all()
  File "C:\Softwares\Anaconda3\envs\django\lib\site-packages\django\db\models\query.py", line 1242, in _fetch_all
    self._result_cache = list(self._iterable_class(self))
  File "C:\Softwares\Anaconda3\envs\django\lib\site-packages\django\db\models\query.py", line 113, in __iter__
    for row in compiler.results_iter(chunked_fetch=self.chunked_fetch, chunk_size=self.chunk_size):
  File "C:\Softwares\Anaconda3\envs\django\lib\site-packages\django\db\models\sql\compiler.py", line 1052, in results_iter
    results = self.execute_sql(MULTI, chunked_fetch=chunked_fetch, chunk_size=chunk_size)
  File "C:\Softwares\Anaconda3\envs\django\lib\site-packages\django\db\models\sql\compiler.py", line 1100, in execute_sql
    cursor.execute(sql, params)
  File "C:\Softwares\Anaconda3\envs\django\lib\site-packages\django\db\backends\utils.py", line 99, in execute
    return super().execute(sql, params)
  File "C:\Softwares\Anaconda3\envs\django\lib\site-packages\django\db\backends\utils.py", line 67, in execute
    return self._execute_with_wrappers(sql, params, many=False, executor=self._execute)
  File "C:\Softwares\Anaconda3\envs\django\lib\site-packages\django\db\backends\utils.py", line 76, in _execute_with_wrappers
    return executor(sql, params, many, context)
  File "C:\Softwares\Anaconda3\envs\django\lib\site-packages\django\db\backends\utils.py", line 84, in _execute
    return self.cursor.execute(sql, params)
  File "C:\Softwares\Anaconda3\envs\django\lib\site-packages\django\db\utils.py", line 89, in __exit__
    raise dj_exc_value.with_traceback(traceback) from exc_value
  File "C:\Softwares\Anaconda3\envs\django\lib\site-packages\django\db\backends\utils.py", line 84, in _execute
    return self.cursor.execute(sql, params)
  File "C:\Softwares\Anaconda3\envs\django\lib\site-packages\django\db\backends\mysql\base.py", line 71, in execute
    return self.cursor.execute(query, args)
  File "C:\Softwares\Anaconda3\envs\django\lib\site-packages\MySQLdb\cursors.py", line 255, in execute
    self.errorhandler(self, exc, value)
  File "C:\Softwares\Anaconda3\envs\django\lib\site-packages\MySQLdb\connections.py", line 50, in defaulterrorhandler
    raise errorvalue
  File "C:\Softwares\Anaconda3\envs\django\lib\site-packages\MySQLdb\cursors.py", line 252, in execute
    res = self._query(query)
  File "C:\Softwares\Anaconda3\envs\django\lib\site-packages\MySQLdb\cursors.py", line 378, in _query
    db.query(q)
  File "C:\Softwares\Anaconda3\envs\django\lib\site-packages\MySQLdb\connections.py", line 280, in query
    _mysql.connection.query(self, query)
django.db.utils.OperationalError: (1054, "Unknown column 'staticsensorreadings.id' in 'field list'")
[2019-06-09 18:34:50,163][Thread-2:21888][task_id:django.request][log.py:228][ERROR][Internal Server Error: /findSensorReadingsBySid/]
Traceback (most recent call last):
  File "C:\Softwares\Anaconda3\envs\django\lib\site-packages\django\db\backends\utils.py", line 84, in _execute
    return self.cursor.execute(sql, params)
  File "C:\Softwares\Anaconda3\envs\django\lib\site-packages\django\db\backends\mysql\base.py", line 71, in execute
    return self.cursor.execute(query, args)
  File "C:\Softwares\Anaconda3\envs\django\lib\site-packages\MySQLdb\cursors.py", line 255, in execute
    self.errorhandler(self, exc, value)
  File "C:\Softwares\Anaconda3\envs\django\lib\site-packages\MySQLdb\connections.py", line 50, in defaulterrorhandler
    raise errorvalue
  File "C:\Softwares\Anaconda3\envs\django\lib\site-packages\MySQLdb\cursors.py", line 252, in execute
    res = self._query(query)
  File "C:\Softwares\Anaconda3\envs\django\lib\site-packages\MySQLdb\cursors.py", line 378, in _query
    db.query(q)
  File "C:\Softwares\Anaconda3\envs\django\lib\site-packages\MySQLdb\connections.py", line 280, in query
    _mysql.connection.query(self, query)
_mysql_exceptions.OperationalError: (1054, "Unknown column 'staticsensorreadings.id' in 'field list'")

The above exception was the direct cause of the following exception:

Traceback (most recent call last):
  File "C:\Softwares\Anaconda3\envs\django\lib\site-packages\django\core\handlers\exception.py", line 34, in inner
    response = get_response(request)
  File "C:\Softwares\Anaconda3\envs\django\lib\site-packages\django\core\handlers\base.py", line 115, in _get_response
    response = self.process_exception_by_middleware(e, request)
  File "C:\Softwares\Anaconda3\envs\django\lib\site-packages\django\core\handlers\base.py", line 113, in _get_response
    response = wrapped_callback(request, *callback_args, **callback_kwargs)
  File "D:\Workspace\Projects\vast-challenge-2019-MC2\RadiationVis\backend\views.py", line 28, in findSensorReadingsBySid
    logger.info(list(responseData))
  File "C:\Softwares\Anaconda3\envs\django\lib\site-packages\django\db\models\query.py", line 274, in __iter__
    self._fetch_all()
  File "C:\Softwares\Anaconda3\envs\django\lib\site-packages\django\db\models\query.py", line 1242, in _fetch_all
    self._result_cache = list(self._iterable_class(self))
  File "C:\Softwares\Anaconda3\envs\django\lib\site-packages\django\db\models\query.py", line 113, in __iter__
    for row in compiler.results_iter(chunked_fetch=self.chunked_fetch, chunk_size=self.chunk_size):
  File "C:\Softwares\Anaconda3\envs\django\lib\site-packages\django\db\models\sql\compiler.py", line 1052, in results_iter
    results = self.execute_sql(MULTI, chunked_fetch=chunked_fetch, chunk_size=chunk_size)
  File "C:\Softwares\Anaconda3\envs\django\lib\site-packages\django\db\models\sql\compiler.py", line 1100, in execute_sql
    cursor.execute(sql, params)
  File "C:\Softwares\Anaconda3\envs\django\lib\site-packages\django\db\backends\utils.py", line 99, in execute
    return super().execute(sql, params)
  File "C:\Softwares\Anaconda3\envs\django\lib\site-packages\django\db\backends\utils.py", line 67, in execute
    return self._execute_with_wrappers(sql, params, many=False, executor=self._execute)
  File "C:\Softwares\Anaconda3\envs\django\lib\site-packages\django\db\backends\utils.py", line 76, in _execute_with_wrappers
    return executor(sql, params, many, context)
  File "C:\Softwares\Anaconda3\envs\django\lib\site-packages\django\db\backends\utils.py", line 84, in _execute
    return self.cursor.execute(sql, params)
  File "C:\Softwares\Anaconda3\envs\django\lib\site-packages\django\db\utils.py", line 89, in __exit__
    raise dj_exc_value.with_traceback(traceback) from exc_value
  File "C:\Softwares\Anaconda3\envs\django\lib\site-packages\django\db\backends\utils.py", line 84, in _execute
    return self.cursor.execute(sql, params)
  File "C:\Softwares\Anaconda3\envs\django\lib\site-packages\django\db\backends\mysql\base.py", line 71, in execute
    return self.cursor.execute(query, args)
  File "C:\Softwares\Anaconda3\envs\django\lib\site-packages\MySQLdb\cursors.py", line 255, in execute
    self.errorhandler(self, exc, value)
  File "C:\Softwares\Anaconda3\envs\django\lib\site-packages\MySQLdb\connections.py", line 50, in defaulterrorhandler
    raise errorvalue
  File "C:\Softwares\Anaconda3\envs\django\lib\site-packages\MySQLdb\cursors.py", line 252, in execute
    res = self._query(query)
  File "C:\Softwares\Anaconda3\envs\django\lib\site-packages\MySQLdb\cursors.py", line 378, in _query
    db.query(q)
  File "C:\Softwares\Anaconda3\envs\django\lib\site-packages\MySQLdb\connections.py", line 280, in query
    _mysql.connection.query(self, query)
django.db.utils.OperationalError: (1054, "Unknown column 'staticsensorreadings.id' in 'field list'")
[2019-06-09 18:34:55,847][Thread-2:21888][task_id:django.request][log.py:228][ERROR][Internal Server Error: /findSensorReadingsBySid/]
Traceback (most recent call last):
  File "C:\Softwares\Anaconda3\envs\django\lib\site-packages\django\db\backends\utils.py", line 84, in _execute
    return self.cursor.execute(sql, params)
  File "C:\Softwares\Anaconda3\envs\django\lib\site-packages\django\db\backends\mysql\base.py", line 71, in execute
    return self.cursor.execute(query, args)
  File "C:\Softwares\Anaconda3\envs\django\lib\site-packages\MySQLdb\cursors.py", line 255, in execute
    self.errorhandler(self, exc, value)
  File "C:\Softwares\Anaconda3\envs\django\lib\site-packages\MySQLdb\connections.py", line 50, in defaulterrorhandler
    raise errorvalue
  File "C:\Softwares\Anaconda3\envs\django\lib\site-packages\MySQLdb\cursors.py", line 252, in execute
    res = self._query(query)
  File "C:\Softwares\Anaconda3\envs\django\lib\site-packages\MySQLdb\cursors.py", line 378, in _query
    db.query(q)
  File "C:\Softwares\Anaconda3\envs\django\lib\site-packages\MySQLdb\connections.py", line 280, in query
    _mysql.connection.query(self, query)
_mysql_exceptions.OperationalError: (1054, "Unknown column 'staticsensorreadings.id' in 'field list'")

The above exception was the direct cause of the following exception:

Traceback (most recent call last):
  File "C:\Softwares\Anaconda3\envs\django\lib\site-packages\django\core\handlers\exception.py", line 34, in inner
    response = get_response(request)
  File "C:\Softwares\Anaconda3\envs\django\lib\site-packages\django\core\handlers\base.py", line 115, in _get_response
    response = self.process_exception_by_middleware(e, request)
  File "C:\Softwares\Anaconda3\envs\django\lib\site-packages\django\core\handlers\base.py", line 113, in _get_response
    response = wrapped_callback(request, *callback_args, **callback_kwargs)
  File "D:\Workspace\Projects\vast-challenge-2019-MC2\RadiationVis\backend\views.py", line 28, in findSensorReadingsBySid
    logger.info(list(responseData))
  File "C:\Softwares\Anaconda3\envs\django\lib\site-packages\django\db\models\query.py", line 274, in __iter__
    self._fetch_all()
  File "C:\Softwares\Anaconda3\envs\django\lib\site-packages\django\db\models\query.py", line 1242, in _fetch_all
    self._result_cache = list(self._iterable_class(self))
  File "C:\Softwares\Anaconda3\envs\django\lib\site-packages\django\db\models\query.py", line 113, in __iter__
    for row in compiler.results_iter(chunked_fetch=self.chunked_fetch, chunk_size=self.chunk_size):
  File "C:\Softwares\Anaconda3\envs\django\lib\site-packages\django\db\models\sql\compiler.py", line 1052, in results_iter
    results = self.execute_sql(MULTI, chunked_fetch=chunked_fetch, chunk_size=chunk_size)
  File "C:\Softwares\Anaconda3\envs\django\lib\site-packages\django\db\models\sql\compiler.py", line 1100, in execute_sql
    cursor.execute(sql, params)
  File "C:\Softwares\Anaconda3\envs\django\lib\site-packages\django\db\backends\utils.py", line 99, in execute
    return super().execute(sql, params)
  File "C:\Softwares\Anaconda3\envs\django\lib\site-packages\django\db\backends\utils.py", line 67, in execute
    return self._execute_with_wrappers(sql, params, many=False, executor=self._execute)
  File "C:\Softwares\Anaconda3\envs\django\lib\site-packages\django\db\backends\utils.py", line 76, in _execute_with_wrappers
    return executor(sql, params, many, context)
  File "C:\Softwares\Anaconda3\envs\django\lib\site-packages\django\db\backends\utils.py", line 84, in _execute
    return self.cursor.execute(sql, params)
  File "C:\Softwares\Anaconda3\envs\django\lib\site-packages\django\db\utils.py", line 89, in __exit__
    raise dj_exc_value.with_traceback(traceback) from exc_value
  File "C:\Softwares\Anaconda3\envs\django\lib\site-packages\django\db\backends\utils.py", line 84, in _execute
    return self.cursor.execute(sql, params)
  File "C:\Softwares\Anaconda3\envs\django\lib\site-packages\django\db\backends\mysql\base.py", line 71, in execute
    return self.cursor.execute(query, args)
  File "C:\Softwares\Anaconda3\envs\django\lib\site-packages\MySQLdb\cursors.py", line 255, in execute
    self.errorhandler(self, exc, value)
  File "C:\Softwares\Anaconda3\envs\django\lib\site-packages\MySQLdb\connections.py", line 50, in defaulterrorhandler
    raise errorvalue
  File "C:\Softwares\Anaconda3\envs\django\lib\site-packages\MySQLdb\cursors.py", line 252, in execute
    res = self._query(query)
  File "C:\Softwares\Anaconda3\envs\django\lib\site-packages\MySQLdb\cursors.py", line 378, in _query
    db.query(q)
  File "C:\Softwares\Anaconda3\envs\django\lib\site-packages\MySQLdb\connections.py", line 280, in query
    _mysql.connection.query(self, query)
django.db.utils.OperationalError: (1054, "Unknown column 'staticsensorreadings.id' in 'field list'")
[2019-06-09 18:43:12,151][Thread-1:21576][task_id:django.request][log.py:228][ERROR][Internal Server Error: /findSensorReadingsBySid/]
Traceback (most recent call last):
  File "C:\Softwares\Anaconda3\envs\django\lib\site-packages\django\core\handlers\exception.py", line 34, in inner
    response = get_response(request)
  File "C:\Softwares\Anaconda3\envs\django\lib\site-packages\django\core\handlers\base.py", line 115, in _get_response
    response = self.process_exception_by_middleware(e, request)
  File "C:\Softwares\Anaconda3\envs\django\lib\site-packages\django\core\handlers\base.py", line 113, in _get_response
    response = wrapped_callback(request, *callback_args, **callback_kwargs)
  File "D:\Workspace\Projects\vast-challenge-2019-MC2\RadiationVis\backend\views.py", line 30, in findSensorReadingsBySid
    return HttpResponse(json.dumps({'sensorReadings': list(responseData)}), content_type='application/json')
  File "C:\Softwares\Anaconda3\envs\django\lib\json\__init__.py", line 231, in dumps
    return _default_encoder.encode(obj)
  File "C:\Softwares\Anaconda3\envs\django\lib\json\encoder.py", line 199, in encode
    chunks = self.iterencode(o, _one_shot=True)
  File "C:\Softwares\Anaconda3\envs\django\lib\json\encoder.py", line 257, in iterencode
    return _iterencode(o, 0)
  File "C:\Softwares\Anaconda3\envs\django\lib\json\encoder.py", line 180, in default
    o.__class__.__name__)
TypeError: Object of type 'datetime' is not JSON serializable
[2019-06-09 18:45:12,715][Thread-1:21448][task_id:django.request][log.py:228][ERROR][Internal Server Error: /findSensorReadingsBySid/]
Traceback (most recent call last):
  File "C:\Softwares\Anaconda3\envs\django\lib\site-packages\django\core\handlers\exception.py", line 34, in inner
    response = get_response(request)
  File "C:\Softwares\Anaconda3\envs\django\lib\site-packages\django\core\handlers\base.py", line 115, in _get_response
    response = self.process_exception_by_middleware(e, request)
  File "C:\Softwares\Anaconda3\envs\django\lib\site-packages\django\core\handlers\base.py", line 113, in _get_response
    response = wrapped_callback(request, *callback_args, **callback_kwargs)
  File "D:\Workspace\Projects\vast-challenge-2019-MC2\RadiationVis\backend\views.py", line 30, in findSensorReadingsBySid
    return HttpResponse(json.dumps({'sensorReadings': list(responseData)[0]}), content_type='application/json')
  File "C:\Softwares\Anaconda3\envs\django\lib\json\__init__.py", line 231, in dumps
    return _default_encoder.encode(obj)
  File "C:\Softwares\Anaconda3\envs\django\lib\json\encoder.py", line 199, in encode
    chunks = self.iterencode(o, _one_shot=True)
  File "C:\Softwares\Anaconda3\envs\django\lib\json\encoder.py", line 257, in iterencode
    return _iterencode(o, 0)
  File "C:\Softwares\Anaconda3\envs\django\lib\json\encoder.py", line 180, in default
    o.__class__.__name__)
TypeError: Object of type 'datetime' is not JSON serializable
[2019-06-09 18:46:45,531][Thread-1:18196][task_id:django.request][log.py:228][ERROR][Internal Server Error: /findSensorReadingsBySid/]
Traceback (most recent call last):
  File "C:\Softwares\Anaconda3\envs\django\lib\site-packages\django\core\handlers\exception.py", line 34, in inner
    response = get_response(request)
  File "C:\Softwares\Anaconda3\envs\django\lib\site-packages\django\core\handlers\base.py", line 115, in _get_response
    response = self.process_exception_by_middleware(e, request)
  File "C:\Softwares\Anaconda3\envs\django\lib\site-packages\django\core\handlers\base.py", line 113, in _get_response
    response = wrapped_callback(request, *callback_args, **callback_kwargs)
  File "D:\Workspace\Projects\vast-challenge-2019-MC2\RadiationVis\backend\views.py", line 30, in findSensorReadingsBySid
    return HttpResponse(json.dumps({'sensorReadings': list(responseData)[0]}), content_type='application/json')
  File "C:\Softwares\Anaconda3\envs\django\lib\json\__init__.py", line 231, in dumps
    return _default_encoder.encode(obj)
  File "C:\Softwares\Anaconda3\envs\django\lib\json\encoder.py", line 199, in encode
    chunks = self.iterencode(o, _one_shot=True)
  File "C:\Softwares\Anaconda3\envs\django\lib\json\encoder.py", line 257, in iterencode
    return _iterencode(o, 0)
  File "C:\Softwares\Anaconda3\envs\django\lib\json\encoder.py", line 180, in default
    o.__class__.__name__)
TypeError: Object of type 'datetime' is not JSON serializable
[2019-06-09 19:28:08,723][Thread-1:22524][task_id:django.request][log.py:228][ERROR][Internal Server Error: /findSensorReadingsBySid/]
Traceback (most recent call last):
  File "C:\Softwares\Anaconda3\envs\django\lib\site-packages\django\core\handlers\exception.py", line 34, in inner
    response = get_response(request)
  File "C:\Softwares\Anaconda3\envs\django\lib\site-packages\django\core\handlers\base.py", line 115, in _get_response
    response = self.process_exception_by_middleware(e, request)
  File "C:\Softwares\Anaconda3\envs\django\lib\site-packages\django\core\handlers\base.py", line 113, in _get_response
    response = wrapped_callback(request, *callback_args, **callback_kwargs)
  File "D:\Workspace\Projects\vast-challenge-2019-MC2\RadiationVis\backend\views.py", line 32, in findSensorReadingsBySid
    return HttpResponse(json.dumps({list(responseData)}, cls=DateEncoder), content_type='application/json')
TypeError: unhashable type: 'list'
[2019-06-09 19:39:51,088][Thread-3:1720][task_id:django.request][log.py:228][ERROR][Internal Server Error: /findSensorReadingsBySid/]
Traceback (most recent call last):
  File "C:\Softwares\Anaconda3\envs\django\lib\site-packages\django\core\handlers\exception.py", line 34, in inner
    response = get_response(request)
  File "C:\Softwares\Anaconda3\envs\django\lib\site-packages\django\core\handlers\base.py", line 126, in _get_response
    "returned None instead." % (callback.__module__, view_name)
ValueError: The view backend.views.findSensorReadingsBySid didn't return an HttpResponse object. It returned None instead.
[2019-06-09 19:40:04,933][Thread-3:1720][task_id:django.request][log.py:228][ERROR][Internal Server Error: /findSensorReadingsBySid/]
Traceback (most recent call last):
  File "C:\Softwares\Anaconda3\envs\django\lib\site-packages\django\core\handlers\exception.py", line 34, in inner
    response = get_response(request)
  File "C:\Softwares\Anaconda3\envs\django\lib\site-packages\django\core\handlers\base.py", line 126, in _get_response
    "returned None instead." % (callback.__module__, view_name)
ValueError: The view backend.views.findSensorReadingsBySid didn't return an HttpResponse object. It returned None instead.
[2019-06-09 19:40:12,914][Thread-3:1720][task_id:django.request][log.py:228][ERROR][Internal Server Error: /findSensorReadingsBySid/]
Traceback (most recent call last):
  File "C:\Softwares\Anaconda3\envs\django\lib\site-packages\django\core\handlers\exception.py", line 34, in inner
    response = get_response(request)
  File "C:\Softwares\Anaconda3\envs\django\lib\site-packages\django\core\handlers\base.py", line 126, in _get_response
    "returned None instead." % (callback.__module__, view_name)
ValueError: The view backend.views.findSensorReadingsBySid didn't return an HttpResponse object. It returned None instead.
